Workbook

Sheet 1.응답스펙트럼예제
A1: Hs | B1: 15.5
A2: Tz | B2: 1
A3: w0 | B3: Wave spetrum | C3: RAO^2 | D3: Respone spectrum | E3: Mo
A4: 0.05 | B4: =$B$1^2*(2*PI())^4*A4^-5/4/PI()/$B$2^4*EXP((-1/PI())*(2*PI()/$B$2)^4*A4^-4) -> 0 | C4: ='2.VBM_RAO'!D6^2 -> 0 | D4: =B4*C4 -> 0 | E4: =D4*(A5-A4) -> 0
A5: 0.07875 | B5: =$B$1^2*(2*PI())^4*A5^-5/4/PI()/$B$2^4*EXP((-1/PI())*(2*PI()/$B$2)^4*A5^-4) -> 0 | C5: ='2.VBM_RAO'!D7^2 -> 1.6e-09 | D5: =B5*C5 -> 0 | E5: =D5*(A6-A5) -> 0
A6: 0.1075 | B6: =$B$1^2*(2*PI())^4*A6^-5/4/PI()/$B$2^4*EXP((-1/PI())*(2*PI()/$B$2)^4*A6^-4) -> 0 | C6: ='2.VBM_RAO'!D8^2 -> 3.24e-08 | D6: =B6*C6 -> 0 | E6: =D6*(A7-A6) -> 0
A7: 0.13625 | B7: =$B$1^2*(2*PI())^4*A7^-5/4/PI()/$B$2^4*EXP((-1/PI())*(2*PI()/$B$2)^4*A7^-4) -> 0 | C7: ='2.VBM_RAO'!D9^2 -> 2.304e-07 | D7: =B7*C7 -> 0 | E7: =D7*(A8-A7) -> 0
A8: 0.165 | B8: =$B$1^2*(2*PI())^4*A8^-5/4/PI()/$B$2^4*EXP((-1/PI())*(2*PI()/$B$2)^4*A8^-4) -> 0 | C8: ='2.VBM_RAO'!D10^2 -> 1.1025e-06 | D8: =B8*C8 -> 0 | E8: =D8*(A9-A8) -> 0
A9: 0.19375 | B9: =$B$1^2*(2*PI())^4*A9^-5/4/PI()/$B$2^4*EXP((-1/PI())*(2*PI()/$B$2)^4*A9^-4) -> 0 | C9: ='2.VBM_RAO'!D11^2 -> 3.7636e-06 | D9: =B9*C9 -> 0 | E9: =D9*(A10-A9) -> 0
A10: 0.2225 | B10: =$B$1^2*(2*PI())^4*A10^-5/4/PI()/$B$2^4*EXP((-1/PI())*(2*PI()/$B$2)^4*A10^-4) -> 0 | C10: ='2.VBM_RAO'!D12^2 -> 1.05625e-05 | D10: =B10*C10 -> 0 | E10: =D10*(A11-A10) -> 0
A11: 0.25125 | B11: =$B$1^2*(2*PI())^4*A11^-5/4/PI()/$B$2^4*EXP((-1/PI())*(2*PI()/$B$2)^4*A11^-4) -> 0 | C11: ='2.VBM_RAO'!D13^2 -> 2.47009e-05 | D11: =B11*C11 -> 0 | E11: =D11*(A12-A11) -> 0
A12: 0.28 | B12: =$B$1^2*(2*PI())^4*A12^-5/4/PI()/$B$2^4*EXP((-1/PI())*(2*PI()/$B$2)^4*A12^-4) -> 0 | C12: ='2.VBM_RAO'!D14^2 -> 5.01264e-05 | D12: =B12*C12 -> 0 | E12: =D12*(A13-A12) -> 0
A13: 0.30875 | B13: =$B$1^2*(2*PI())^4*A13^-5/4/PI()/$B$2^4*EXP((-1/PI())*(2*PI()/$B$2)^4*A13^-4) -> 0 | C13: ='2.VBM_RAO'!D15^2 -> 8.85481e-05 | D13: =B13*C13 -> 0 | E13: =D13*(A14-A13) -> 0
A14: 0.3375 | B14: =$B$1^2*(2*PI())^4*A14^-5/4/PI()/$B$2^4*EXP((-1/PI())*(2*PI()/$B$2)^4*A14^-4) -> 0 | C14: ='2.VBM_RAO'!D16^2 -> 0.0001378276 | D14: =B14*C14 -> 0 | E14: =D14*(A15-A14) -> 0
A15: 0.36625 | B15: =$B$1^2*(2*PI())^4*A15^-5/4/PI()/$B$2^4*EXP((-1/PI())*(2*PI()/$B$2)^4*A15^-4) -> 0 | C15: ='2.VBM_RAO'!D17^2 -> 0.0001882384 | D15: =B15*C15 -> 0 | E15: =D15*(A16-A15) -> 0
... A278: 7.9275 | B278: =$B$1^2*(2*PI())^4*A278^-5/4/PI()/$B$2^4*EXP((-1/PI())*(2*PI()/$B$2)^4*A278^-4) -> 0.83934397 | C278: ='2.VBM_RAO'!D280^2 -> 0 | D278: =B278*C278 -> 0 | E278: =D278*(A279-A278) -> 0
B279: =$B$1^2*(2*PI())^4*A279^-5/4/PI()/$B$2^4*EXP((-1/PI())*(2*PI()/$B$2)^4*A279^-4) -> #DIV/0!

Sheet 2.VBM_RAO
A1: 9 | B1: Vertical | C1: Bending | D1: Moment(14 | E1: Station)
A3: A. | B3: Non | C3: Dimensional | D3: Amplitude | E3: per | F3: Unit | G3: Wave | H3: Amplitude(/rho*g*L**2*B | I3: /a) | M3: 차원화(=RAO*rho*g*L^2*B)
B4: ****************************************************************************************************
B5: NO | C5: Wo(rad/sec) | D5: 0 | E5: 30 | F5: 60 | G5: 90 | H5: 120 | I5: 150 | J5: 180 | M5: 0 | N5: 30 | O5: 60 | P5: 90 | Q5: 120 | R5: 150 | S5: 180
B6: 1 | C6: 0.05 | D6: 0 | E6: 0 | F6: 0 | G6: 0 | H6: 0 | I6: 0 | J6: 0 | L6: 0.05 | M6: =D6*1.04*9.81*334^2*58.6 -> 0 | N6: =E6*1.04*9.81*334^2*58.6 -> 0 | O6: =F6*1.04*9.81*334^2*58.6 -> 0 | P6: =G6*1.04*9.81*334^2*58.6 -> 0 | Q6: =H6*1.04*9.81*334^2*58.6 -> 0 | R6: =I6*1.04*9.81*334^2*58.6 -> 0 | S6: =J6*1.04*9.81*334^2*58.6 -> 0
B7: 2 | C7: 0.07875 | D7: 4e-05 | E7: 3e-05 | F7: 0 | G7: 2e-05 | H7: 0 | I7: 3e-05 | J7: 5e-05 | L7: 0.07875 | M7: =D7*1.04*9.81*334^2*58.6 -> 2667.7977 | N7: =E7*1.04*9.81*334^2*58.6 -> 2000.8482 | O7: =F7*1.04*9.81*334^2*58.6 -> 0 | P7: =G7*1.04*9.81*334^2*58.6 -> 1333.8988 | Q7: =H7*1.04*9.81*334^2*58.6 -> 0 | R7: =I7*1.04*9.81*334^2*58.6 -> 2000.8482 | S7: =J7*1.04*9.81*334^2*58.6 -> 3334.7471
B8: 3 | C8: 0.1075 | D8: 0.00018 | E8: 0.00013 | F8: 2e-05 | G8: 3e-05 | H8: 2e-05 | I8: 0.00013 | J8: 0.00018 | L8: 0.1075 | M8: =D8*1.04*9.81*334^2*58.6 -> 12005.089 | N8: =E8*1.04*9.81*334^2*58.6 -> 8670.3424 | O8: =F8*1.04*9.81*334^2*58.6 -> 1333.8988 | P8: =G8*1.04*9.81*334^2*58.6 -> 2000.8482 | Q8: =H8*1.04*9.81*334^2*58.6 -> 1333.8988 | R8: =I8*1.04*9.81*334^2*58.6 -> 8670.3424 | S8: =J8*1.04*9.81*334^2*58.6 -> 12005.089
B9: 4 | C9: 0.13625 | D9: 0.00048 | E9: 0.00035 | F9: 9e-05 | G9: 5e-05 | H9: 9e-05 | I9: 0.00036 | J9: 0.00049 | L9: 0.13625 | M9: =D9*1.04*9.81*334^2*58.6 -> 32013.572 | N9: =E9*1.04*9.81*334^2*58.6 -> 23343.23 | O9: =F9*1.04*9.81*334^2*58.6 -> 6002.5447 | P9: =G9*1.04*9.81*334^2*58.6 -> 3334.7471 | Q9: =H9*1.04*9.81*334^2*58.6 -> 6002.5447 | R9: =I9*1.04*9.81*334^2*58.6 -> 24010.179 | S9: =J9*1.04*9.81*334^2*58.6 -> 32680.521
B10: 5 | C10: 0.165 | D10: 0.00105 | E10: 0.00077 | F10: 0.00021 | G10: 7e-05 | H10: 0.00022 | I10: 0.00078 | J10: 0.00105 | L10: 0.165 | M10: =D10*1.04*9.81*334^2*58.6 -> 70029.689 | N10: =E10*1.04*9.81*334^2*58.6 -> 51355.105 | O10: =F10*1.04*9.81*334^2*58.6 -> 14005.938 | P10: =G10*1.04*9.81*334^2*58.6 -> 4668.6459 | Q10: =H10*1.04*9.81*334^2*58.6 -> 14672.887 | R10: =I10*1.04*9.81*334^2*58.6 -> 52022.054 | S10: =J10*1.04*9.81*334^2*58.6 -> 70029.689
B11: 6 | C11: 0.19375 | D11: 0.00194 | E11: 0.00144 | F11: 0.00043 | G11: 9e-05 | H11: 0.00044 | I11: 0.00145 | J11: 0.00195 | L11: 0.19375 | M11: =D11*1.04*9.81*334^2*58.6 -> 129388.19 | N11: =E11*1.04*9.81*334^2*58.6 -> 96040.716 | O11: =F11*1.04*9.81*334^2*58.6 -> 28678.825 | P11: =G11*1.04*9.81*334^2*58.6 -> 6002.5447 | Q11: =H11*1.04*9.81*334^2*58.6 -> 29345.774 | R11: =I11*1.04*9.81*334^2*58.6 -> 96707.665 | S11: =J11*1.04*9.81*334^2*58.6 -> 130055.14
B12: 7 | C12: 0.2225 | D12: 0.00325 | E12: 0.00243 | F12: 0.00075 | G12: 0.0001 | H12: 0.00076 | I12: 0.00243 | J12: 0.00324 | L12: 0.2225 | M12: =D12*1.04*9.81*334^2*58.6 -> 216758.56 | N12: =E12*1.04*9.81*334^2*58.6 -> 162068.71 | O12: =F12*1.04*9.81*334^2*58.6 -> 50021.206 | P12: =G12*1.04*9.81*334^2*58.6 -> 6669.4942 | Q12: =H12*1.04*9.81*334^2*58.6 -> 50688.156 | R12: =I12*1.04*9.81*334^2*58.6 -> 162068.71 | S12: =J12*1.04*9.81*334^2*58.6 -> 216091.61
B13: 8 | C13: 0.25125 | D13: 0.00497 | E13: 0.00375 | F13: 0.0012 | G13: 0.00012 | H13: 0.00122 | I13: 0.00373 | J13: 0.00493 | L13: 0.25125 | M13: =D13*1.04*9.81*334^2*58.6 -> 331473.86 | N13: =E13*1.04*9.81*334^2*58.6 -> 250106.03 | O13: =F13*1.04*9.81*334^2*58.6 -> 80033.93 | P13: =G13*1.04*9.81*334^2*58.6 -> 8003.393 | Q13: =H13*1.04*9.81*334^2*58.6 -> 81367.829 | R13: =I13*1.04*9.81*334^2*58.6 -> 248772.13 | S13: =J13*1.04*9.81*334^2*58.6 -> 328806.06
B14: 9 | C14: 0.28 | D14: 0.00708 | E14: 0.00538 | F14: 0.00178 | G14: 0.00012 | H14: 0.00179 | I14: 0.00531 | J14: 0.00695 | L14: 0.28 | M14: =D14*1.04*9.81*334^2*58.6 -> 472200.19 | N14: =E14*1.04*9.81*334^2*58.6 -> 358818.79 | O14: =F14*1.04*9.81*334^2*58.6 -> 118717 | P14: =G14*1.04*9.81*334^2*58.6 -> 8003.393 | Q14: =H14*1.04*9.81*334^2*58.6 -> 119383.95 | R14: =I14*1.04*9.81*334^2*58.6 -> 354150.14 | S14: =J14*1.04*9.81*334^2*58.6 -> 463529.84
B15: 10 | C15: 0.30875 | D15: 0.00941 | E15: 0.00724 | F15: 0.00247 | G15: 0.00011 | H15: 0.00248 | I15: 0.00707 | J15: 0.00913 | L15: 0.30875 | M15: =D15*1.04*9.81*334^2*58.6 -> 627599.4 | N15: =E15*1.04*9.81*334^2*58.6 -> 482871.38 | O15: =F15*1.04*9.81*334^2*58.6 -> 164736.51 | P15: =G15*1.04*9.81*334^2*58.6 -> 7336.4436 | Q15: =H15*1.04*9.81*334^2*58.6 -> 165403.46 | R15: =I15*1.04*9.81*334^2*58.6 -> 471533.24 | S15: =J15*1.04*9.81*334^2*58.6 -> 608924.82
B16: 11 | C16: 0.3375 | D16: 0.01174 | E16: 0.00916 | F16: 0.00325 | G16: 8e-05 | H16: 0.00323 | I16: 0.00887 | J16: 0.01128 | L16: 0.3375 | M16: =D16*1.04*9.81*334^2*58.6 -> 782998.61 | N16: =E16*1.04*9.81*334^2*58.6 -> 610925.66 | O16: =F16*1.04*9.81*334^2*58.6 -> 216758.56 | P16: =G16*1.04*9.81*334^2*58.6 -> 5335.5953 | Q16: =H16*1.04*9.81*334^2*58.6 -> 215424.66 | R16: =I16*1.04*9.81*334^2*58.6 -> 591584.13 | S16: =J16*1.04*9.81*334^2*58.6 -> 752318.94
B17: 12 | C17: 0.36625 | D17: 0.01372 | E17: 0.01092 | F17: 0.00405 | G17: 4e-05 | H17: 0.00404 | I17: 0.01064 | J17: 0.01329 | L17: 0.36625 | M17: =D17*1.04*9.81*334^2*58.6 -> 915054.6 | N17: =E17*1.04*9.81*334^2*58.6 -> 728308.76 | O17: =F17*1.04*9.81*334^2*58.6 -> 270114.51 | P17: =G17*1.04*9.81*334^2*58.6 -> 2667.7977 | Q17: =H17*1.04*9.81*334^2*58.6 -> 269447.56 | R17: =I17*1.04*9.81*334^2*58.6 -> 709634.18 | S17: =J17*1.04*9.81*334^2*58.6 -> 886375.77
... B46: 41 | C46: 1.2 | D46: 0.00084 | E46: 0.00082 | F46: 0.00155 | G46: 0.00247 | H46: 0.00223 | I46: 0.00154 | J46: 0.00094 | L46: 1.2 | M46: =D46*1.04*9.81*334^2*58.6 -> 56023.751 | N46: =E46*1.04*9.81*334^2*58.6 -> 54689.852 | O46: =F46*1.04*9.81*334^2*58.6 -> 103377.16 | P46: =G46*1.04*9.81*334^2*58.6 -> 164736.51 | Q46: =H46*1.04*9.81*334^2*58.6 -> 148729.72 | R46: =I46*1.04*9.81*334^2*58.6 -> 102710.21 | S46: =J46*1.04*9.81*334^2*58.6 -> 62693.245
E60: NO | F60: Wo(rad/sec) | G60: 0 | H60: Deg | I60: 30 | J60: Deg | K60: 60 | L60: Deg | M60: 90 | N60: Deg | O60: 120 | P60: Deg | Q60: 150 | R60: Deg | S60: 180 | T60: Deg
E61: ****************************************************************************************************
E62: 1 | F62: 0.05 | G62: 5e-05 | H62: 5e-05 | I62: 6e-05 | J62: 6e-05 | K62: 6e-05 | L62: 5e-05 | M62: 5e-05
E63: 2 | F63: 0.07875 | G63: 3e-05 | H63: 5e-05 | I63: 9e-05 | J63: 0.00011 | K63: 9e-05 | L63: 5e-05 | M63: 3e-05
E64: 3 | F64: 0.1075 | G64: 9e-05 | H64: 3e-05 | I64: 0.00011 | J64: 0.00017 | K64: 0.00011 | L64: 3e-05 | M64: 9e-05
E65: 4 | F65: 0.13625 | G65: 0.00042 | H65: 0.00025 | I65: 9e-05 | J65: 0.00026 | K65: 9e-05 | L65: 0.00025 | M65: 0.00042
E66: 5 | F66: 0.165 | G66: 0.00104 | H66: 0.0007 | I66: 1e-05 | J66: 0.00035 | K66: 1e-05 | L66: 0.0007 | M66: 0.00104
E67: 6 | F67: 0.19375 | G67: 0.00208 | H67: 0.00145 | I67: 0.00018 | J67: 0.00047 | K67: 0.00018 | L67: 0.00145 | M67: 0.00208
E68: 7 | F68: 0.2225 | G68: 0.00359 | H68: 0.00258 | I68: 0.00049 | J68: 0.00059 | K68: 0.00049 | L68: 0.00258 | M68: 0.00359
E69: 8 | F69: 0.25125 | G69: 0.00556 | H69: 0.00408 | I69: 0.00094 | J69: 0.00072 | K69: 0.00094 | L69: 0.00408 | M69: 0.00557
E70: 9 | F70: 0.28 | G70: 0.00791 | H70: 0.00591 | I70: 0.00154 | J70: 0.00085 | K70: 0.00154 | L70: 0.00592 | M70: 0.00791
E71: 10 | F71: 0.30875 | G71: 0.01037 | H71: 0.00791 | I71: 0.00225 | J71: 0.00098 | K71: 0.00226 | L71: 0.00793 | M71: 0.0104
E72: 11 | F72: 0.3375 | G72: 0.01262 | H72: 0.00986 | I72: 0.00303 | J72: 0.0011 | K72: 0.00305 | L72: 0.0099 | M72: 0.01268
E73: 12 | F73: 0.36625 | G73: 0.0143 | H73: 0.0115 | I73: 0.00382 | J73: 0.00122 | K73: 0.00386 | L73: 0.01159 | M73: 0.01442
... E102: 41 | F102: 1.2 | G102: 0.00087 | H102: 0.00135 | I102: 0.00372 | J102: 0.00398 | K102: 0.00179 | L102: 0.00056 | M102: 0.00012

Sheet 3.M0_VBM_0
B2: VBM_RAO
A3: dw | B3: =B4/2 -> 0.014375
A4: w0 | B4: =A7-A6 -> 0.02875 | C4: Hs | D4: 0.5
A5: w | B5: RAO(0) | C5: Tz | D5: 3.5 | E5: 4.5 | F5: 5.5 | G5: 6.5 | H5: 7.5 | I5: 8.5 | J5: 9.5 | K5: 10.5 | L5: 11.5 | M5: 12.5 | N5: 13.5 | O5: 14.5 | P5: 15.5 | Q5: 16.5 | R5: 17.5 | S5: 18.5
A6: 0.05 | B6: ='2.VBM_RAO'!M6 -> 0 | D6: =$B$4*(B6^2)*($D$4^2*(2*PI())^4*A6^-5/4/PI()/$D$5^4*EXP((-1/PI())*(2*PI()/$D$5)^4*A6^-4)) -> 0 | E6: =$B$4*(B6^2)*($D$4^2*(2*PI())^4*A6^-5/4/PI()/$E$5^4*EXP((-1/PI())*(2*PI()/$E$5)^4*A6^-4)) -> 0 | F6: =$B$4*(B6^2)*($D$4^2*(2*PI())^4*A6^-5/4/PI()/$F$5^4*EXP((-1/PI())*(2*PI()/$F$5)^4*A6^-4)) -> 0 | G6: =$B$4*(B6^2)*($D$4^2*(2*PI())^4*A6^-5/4/PI()/$G$5^4*EXP((-1/PI())*(2*PI()/$G$5)^4*A6^-4)) -> 0 | H6: =$B$4*(B6^2)*($D$4^2*(2*PI())^4*A6^-5/4/PI()/$H$5^4*EXP((-1/PI())*(2*PI()/$H$5)^4*A6^-4)) -> 0 | I6: =$B$4*(B6^2)*($D$4^2*(2*PI())^4*A6^-5/4/PI()/$I$5^4*EXP((-1/PI())*(2*PI()/$I$5)^4*A6^-4)) -> 0 | J6: =$B$4*(B6^2)*($D$4^2*(2*PI())^4*A6^-5/4/PI()/$J$5^4*EXP((-1/PI())*(2*PI()/$J$5)^4*A6^-4)) -> 0 | K6: =$B$4*(B6^2)*($D$4^2*(2*PI())^4*A6^-5/4/PI()/$K$5^4*EXP((-1/PI())*(2*PI()/$K$5)^4*A6^-4)) -> 0 | L6: =$B$4*(B6^2)*($D$4^2*(2*PI())^4*A6^-5/4/PI()/$L$5^4*EXP((-1/PI())*(2*PI()/$L$5)^4*A6^-4)) -> 0 | M6: =$B$4*(B6^2)*($D$4^2*(2*PI())^4*A6^-5/4/PI()/$M$5^4*EXP((-1/PI())*(2*PI()/$M$5)^4*A6^-4)) -> 0 | N6: =$B$4*(B6^2)*($D$4^2*(2*PI())^4*A6^-5/4/PI()/$N$5^4*EXP((-1/PI())*(2*PI()/$N$5)^4*A6^-4)) -> 0 | O6: =$B$4*(B6^2)*($D$4^2*(2*PI())^4*A6^-5/4/PI()/$O$5^4*EXP((-1/PI())*(2*PI()/$O$5)^4*A6^-4)) -> 0 | P6: =$B$4*(B6^2)*($D$4^2*(2*PI())^4*A6^-5/4/PI()/$P$5^4*EXP((-1/PI())*(2*PI()/$P$5)^4*A6^-4)) -> 0 | Q6: =$B$4*(B6^2)*($D$4^2*(2*PI())^4*A6^-5/4/PI()/$Q$5^4*EXP((-1/PI())*(2*PI()/$Q$5)^4*A6^-4)) -> 0 | R6: =$B$4*(B6^2)*($D$4^2*(2*PI())^4*A6^-5/4/PI()/$R$5^4*EXP((-1/PI())*(2*PI()/$R$5)^4*A6^-4)) -> 0 | S6: =$B$4*(B6^2)*($D$4^2*(2*PI())^4*A6^-5/4/PI()/$S$5^4*EXP((-1/PI())*(2*PI()/$S$5)^4*A6^-4)) -> 0
A7: 0.07875 | B7: ='2.VBM_RAO'!M7 -> 2667.7977 | D7: =$B$4*(B7^2)*($D$4^2*(2*PI())^4*A7^-5/4/PI()/$D$5^4*EXP((-1/PI())*(2*PI()/$D$5)^4*A7^-4)) -> 0 | E7: =$B$4*(B7^2)*($D$4^2*(2*PI())^4*A7^-5/4/PI()/$E$5^4*EXP((-1/PI())*(2*PI()/$E$5)^4*A7^-4)) -> 0 | F7: =$B$4*(B7^2)*($D$4^2*(2*PI())^4*A7^-5/4/PI()/$F$5^4*EXP((-1/PI())*(2*PI()/$F$5)^4*A7^-4)) -> 0 | G7: =$B$4*(B7^2)*($D$4^2*(2*PI())^4*A7^-5/4/PI()/$G$5^4*EXP((-1/PI())*(2*PI()/$G$5)^4*A7^-4)) -> 0 | H7: =$B$4*(B7^2)*($D$4^2*(2*PI())^4*A7^-5/4/PI()/$H$5^4*EXP((-1/PI())*(2*PI()/$H$5)^4*A7^-4)) -> 0 | I7: =$B$4*(B7^2)*($D$4^2*(2*PI())^4*A7^-5/4/PI()/$I$5^4*EXP((-1/PI())*(2*PI()/$I$5)^4*A7^-4)) -> 0 | J7: =$B$4*(B7^2)*($D$4^2*(2*PI())^4*A7^-5/4/PI()/$J$5^4*EXP((-1/PI())*(2*PI()/$J$5)^4*A7^-4)) -> 0 | K7: =$B$4*(B7^2)*($D$4^2*(2*PI())^4*A7^-5/4/PI()/$K$5^4*EXP((-1/PI())*(2*PI()/$K$5)^4*A7^-4)) -> 0 | L7: =$B$4*(B7^2)*($D$4^2*(2*PI())^4*A7^-5/4/PI()/$L$5^4*EXP((-1/PI())*(2*PI()/$L$5)^4*A7^-4)) -> 0 | M7: =$B$4*(B7^2)*($D$4^2*(2*PI())^4*A7^-5/4/PI()/$M$5^4*EXP((-1/PI())*(2*PI()/$M$5)^4*A7^-4)) -> 2.9584137e-222 | N7: =$B$4*(B7^2)*($D$4^2*(2*PI())^4*A7^-5/4/PI()/$N$5^4*EXP((-1/PI())*(2*PI()/$N$5)^4*A7^-4)) -> 1.3742343e-161 | O7: =$B$4*(B7^2)*($D$4^2*(2*PI())^4*A7^-5/4/PI()/$O$5^4*EXP((-1/PI())*(2*PI()/$O$5)^4*A7^-4)) -> 8.8227647e-120 | P7: =$B$4*(B7^2)*($D$4^2*(2*PI())^4*A7^-5/4/PI()/$P$5^4*EXP((-1/PI())*(2*PI()/$P$5)^4*A7^-4)) -> 3.1860986e-90 | Q7: =$B$4*(B7^2)*($D$4^2*(2*PI())^4*A7^-5/4/PI()/$Q$5^4*EXP((-1/PI())*(2*PI()/$Q$5)^4*A7^-4)) -> 7.4069389e-69 | R7: =$B$4*(B7^2)*($D$4^2*(2*PI())^4*A7^-5/4/PI()/$R$5^4*EXP((-1/PI())*(2*PI()/$R$5)^4*A7^-4)) -> 4.1498462e-53 | S7: =$B$4*(B7^2)*($D$4^2*(2*PI())^4*A7^-5/4/PI()/$S$5^4*EXP((-1/PI())*(2*PI()/$S$5)^4*A7^-4)) -> 2.6691786e-41
A8: 0.1075 | B8: ='2.VBM_RAO'!M8 -> 12005.089 | D8: =$B$4*(B8^2)*($D$4^2*(2*PI())^4*A8^-5/4/PI()/$D$5^4*EXP((-1/PI())*(2*PI()/$D$5)^4*A8^-4)) -> 0 | E8: =$B$4*(B8^2)*($D$4^2*(2*PI())^4*A8^-5/4/PI()/$E$5^4*EXP((-1/PI())*(2*PI()/$E$5)^4*A8^-4)) -> 0 | F8: =$B$4*(B8^2)*($D$4^2*(2*PI())^4*A8^-5/4/PI()/$F$5^4*EXP((-1/PI())*(2*PI()/$F$5)^4*A8^-4)) -> 0 | G8: =$B$4*(B8^2)*($D$4^2*(2*PI())^4*A8^-5/4/PI()/$G$5^4*EXP((-1/PI())*(2*PI()/$G$5)^4*A8^-4)) -> 0 | H8: =$B$4*(B8^2)*($D$4^2*(2*PI())^4*A8^-5/4/PI()/$H$5^4*EXP((-1/PI())*(2*PI()/$H$5)^4*A8^-4)) -> 0 | I8: =$B$4*(B8^2)*($D$4^2*(2*PI())^4*A8^-5/4/PI()/$I$5^4*EXP((-1/PI())*(2*PI()/$I$5)^4*A8^-4)) -> 1.4893468e-300 | J8: =$B$4*(B8^2)*($D$4^2*(2*PI())^4*A8^-5/4/PI()/$J$5^4*EXP((-1/PI())*(2*PI()/$J$5)^4*A8^-4)) -> 9.2836737e-190 | K8: =$B$4*(B8^2)*($D$4^2*(2*PI())^4*A8^-5/4/PI()/$K$5^4*EXP((-1/PI())*(2*PI()/$K$5)^4*A8^-4)) -> 1.37697e-124 | L8: =$B$4*(B8^2)*($D$4^2*(2*PI())^4*A8^-5/4/PI()/$L$5^4*EXP((-1/PI())*(2*PI()/$L$5)^4*A8^-4)) -> 2.9308139e-84 | M8: =$B$4*(B8^2)*($D$4^2*(2*PI())^4*A8^-5/4/PI()/$M$5^4*EXP((-1/PI())*(2*PI()/$M$5)^4*A8^-4)) -> 3.0382191e-58 | N8: =$B$4*(B8^2)*($D$4^2*(2*PI())^4*A8^-5/4/PI()/$N$5^4*EXP((-1/PI())*(2*PI()/$N$5)^4*A8^-4)) -> 7.2202678e-41 | O8: =$B$4*(B8^2)*($D$4^2*(2*PI())^4*A8^-5/4/PI()/$O$5^4*EXP((-1/PI())*(2*PI()/$O$5)^4*A8^-4)) -> 6.4575901e-29 | P8: =$B$4*(B8^2)*($D$4^2*(2*PI())^4*A8^-5/4/PI()/$P$5^4*EXP((-1/PI())*(2*PI()/$P$5)^4*A8^-4)) -> 1.7366498e-20 | Q8: =$B$4*(B8^2)*($D$4^2*(2*PI())^4*A8^-5/4/PI()/$Q$5^4*EXP((-1/PI())*(2*PI()/$Q$5)^4*A8^-4)) -> 2.06803e-14 | R8: =$B$4*(B8^2)*($D$4^2*(2*PI())^4*A8^-5/4/PI()/$R$5^4*EXP((-1/PI())*(2*PI()/$R$5)^4*A8^-4)) -> 5.9987773e-10 | S8: =$B$4*(B8^2)*($D$4^2*(2*PI())^4*A8^-5/4/PI()/$S$5^4*EXP((-1/PI())*(2*PI()/$S$5)^4*A8^-4)) -> 1.2880815e-06
A9: 0.13625 | B9: ='2.VBM_RAO'!M9 -> 32013.572 | D9: =$B$4*(B9^2)*($D$4^2*(2*PI())^4*A9^-5/4/PI()/$D$5^4*EXP((-1/PI())*(2*PI()/$D$5)^4*A9^-4)) -> 0 | E9: =$B$4*(B9^2)*($D$4^2*(2*PI())^4*A9^-5/4/PI()/$E$5^4*EXP((-1/PI())*(2*PI()/$E$5)^4*A9^-4)) -> 0 | F9: =$B$4*(B9^2)*($D$4^2*(2*PI())^4*A9^-5/4/PI()/$F$5^4*EXP((-1/PI())*(2*PI()/$F$5)^4*A9^-4)) -> 0 | G9: =$B$4*(B9^2)*($D$4^2*(2*PI())^4*A9^-5/4/PI()/$G$5^4*EXP((-1/PI())*(2*PI()/$G$5)^4*A9^-4)) -> 0 | H9: =$B$4*(B9^2)*($D$4^2*(2*PI())^4*A9^-5/4/PI()/$H$5^4*EXP((-1/PI())*(2*PI()/$H$5)^4*A9^-4)) -> 1.5841808e-188 | I9: =$B$4*(B9^2)*($D$4^2*(2*PI())^4*A9^-5/4/PI()/$I$5^4*EXP((-1/PI())*(2*PI()/$I$5)^4*A9^-4)) -> 6.3940782e-111 | J9: =$B$4*(B9^2)*($D$4^2*(2*PI())^4*A9^-5/4/PI()/$J$5^4*EXP((-1/PI())*(2*PI()/$J$5)^4*A9^-4)) -> 4.1877627e-68 | K9: =$B$4*(B9^2)*($D$4^2*(2*PI())^4*A9^-5/4/PI()/$K$5^4*EXP((-1/PI())*(2*PI()/$K$5)^4*A9^-4)) -> 5.8921256e-43 | L9: =$B$4*(B9^2)*($D$4^2*(2*PI())^4*A9^-5/4/PI()/$L$5^4*EXP((-1/PI())*(2*PI()/$L$5)^4*A9^-4)) -> 2.0007029e-27 | M9: =$B$4*(B9^2)*($D$4^2*(2*PI())^4*A9^-5/4/PI()/$M$5^4*EXP((-1/PI())*(2*PI()/$M$5)^4*A9^-4)) -> 1.9674137e-17 | N9: =$B$4*(B9^2)*($D$4^2*(2*PI())^4*A9^-5/4/PI()/$N$5^4*EXP((-1/PI())*(2*PI()/$N$5)^4*A9^-4)) -> 8.8192903e-11 | O9: =$B$4*(B9^2)*($D$4^2*(2*PI())^4*A9^-5/4/PI()/$O$5^4*EXP((-1/PI())*(2*PI()/$O$5)^4*A9^-4)) -> 3.1680076e-06 | P9: =$B$4*(B9^2)*($D$4^2*(2*PI())^4*A9^-5/4/PI()/$P$5^4*EXP((-1/PI())*(2*PI()/$P$5)^4*A9^-4)) -> 0.00497089 | Q9: =$B$4*(B9^2)*($D$4^2*(2*PI())^4*A9^-5/4/PI()/$Q$5^4*EXP((-1/PI())*(2*PI()/$Q$5)^4*A9^-4)) -> 0.9646945 | R9: =$B$4*(B9^2)*($D$4^2*(2*PI())^4*A9^-5/4/PI()/$R$5^4*EXP((-1/PI())*(2*PI()/$R$5)^4*A9^-4)) -> 44.778432 | S9: =$B$4*(B9^2)*($D$4^2*(2*PI())^4*A9^-5/4/PI()/$S$5^4*EXP((-1/PI())*(2*PI()/$S$5)^4*A9^-4)) -> 764.00179
A10: 0.165 | B10: ='2.VBM_RAO'!M10 -> 70029.689 | D10: =$B$4*(B10^2)*($D$4^2*(2*PI())^4*A10^-5/4/PI()/$D$5^4*EXP((-1/PI())*(2*PI()/$D$5)^4*A10^-4)) -> 0 | E10: =$B$4*(B10^2)*($D$4^2*(2*PI())^4*A10^-5/4/PI()/$E$5^4*EXP((-1/PI())*(2*PI()/$E$5)^4*A10^-4)) -> 0 | F10: =$B$4*(B10^2)*($D$4^2*(2*PI())^4*A10^-5/4/PI()/$F$5^4*EXP((-1/PI())*(2*PI()/$F$5)^4*A10^-4)) -> 0 | G10: =$B$4*(B10^2)*($D$4^2*(2*PI())^4*A10^-5/4/PI()/$G$5^4*EXP((-1/PI())*(2*PI()/$G$5)^4*A10^-4)) -> 2.8855147e-153 | H10: =$B$4*(B10^2)*($D$4^2*(2*PI())^4*A10^-5/4/PI()/$H$5^4*EXP((-1/PI())*(2*PI()/$H$5)^4*A10^-4)) -> 1.5244787e-82 | I10: =$B$4*(B10^2)*($D$4^2*(2*PI())^4*A10^-5/4/PI()/$I$5^4*EXP((-1/PI())*(2*PI()/$I$5)^4*A10^-4)) -> 1.4125923e-46 | J10: =$B$4*(B10^2)*($D$4^2*(2*PI())^4*A10^-5/4/PI()/$J$5^4*EXP((-1/PI())*(2*PI()/$J$5)^4*A10^-4)) -> 8.9994121e-27 | K10: =$B$4*(B10^2)*($D$4^2*(2*PI())^4*A10^-5/4/PI()/$K$5^4*EXP((-1/PI())*(2*PI()/$K$5)^4*A10^-4)) -> 3.580924e-15 | L10: =$B$4*(B10^2)*($D$4^2*(2*PI())^4*A10^-5/4/PI()/$L$5^4*EXP((-1/PI())*(2*PI()/$L$5)^4*A10^-4)) -> 4.9045961e-08 | M10: =$B$4*(B10^2)*($D$4^2*(2*PI())^4*A10^-5/4/PI()/$M$5^4*EXP((-1/PI())*(2*PI()/$M$5)^4*A10^-4)) -> 0.0018165924 | N10: =$B$4*(B10^2)*($D$4^2*(2*PI())^4*A10^-5/4/PI()/$N$5^4*EXP((-1/PI())*(2*PI()/$N$5)^4*A10^-4)) -> 1.9071537 | O10: =$B$4*(B10^2)*($D$4^2*(2*PI())^4*A10^-5/4/PI()/$O$5^4*EXP((-1/PI())*(2*PI()/$O$5)^4*A10^-4)) -> 214.78182 | P10: =$B$4*(B10^2)*($D$4^2*(2*PI())^4*A10^-5/4/PI()/$P$5^4*EXP((-1/PI())*(2*PI()/$P$5)^4*A10^-4)) -> 5699.5447 | Q10: =$B$4*(B10^2)*($D$4^2*(2*PI())^4*A10^-5/4/PI()/$Q$5^4*EXP((-1/PI())*(2*PI()/$Q$5)^4*A10^-4)) -> 57746.306 | R10: =$B$4*(B10^2)*($D$4^2*(2*PI())^4*A10^-5/4/PI()/$R$5^4*EXP((-1/PI())*(2*PI()/$R$5)^4*A10^-4)) -> 303223.85 | S10: =$B$4*(B10^2)*($D$4^2*(2*PI())^4*A10^-5/4/PI()/$S$5^4*EXP((-1/PI())*(2*PI()/$S$5)^4*A10^-4)) -> 1006812.1
A11: 0.19375 | B11: ='2.VBM_RAO'!M11 -> 129388.19 | D11: =$B$4*(B11^2)*($D$4^2*(2*PI())^4*A11^-5/4/PI()/$D$5^4*EXP((-1/PI())*(2*PI()/$D$5)^4*A11^-4)) -> 0 | E11: =$B$4*(B11^2)*($D$4^2*(2*PI())^4*A11^-5/4/PI()/$E$5^4*EXP((-1/PI())*(2*PI()/$E$5)^4*A11^-4)) -> 0 | F11: =$B$4*(B11^2)*($D$4^2*(2*PI())^4*A11^-5/4/PI()/$F$5^4*EXP((-1/PI())*(2*PI()/$F$5)^4*A11^-4)) -> 4.9165589e-157 | G11: =$B$4*(B11^2)*($D$4^2*(2*PI())^4*A11^-5/4/PI()/$G$5^4*EXP((-1/PI())*(2*PI()/$G$5)^4*A11^-4)) -> 6.8356135e-76 | H11: =$B$4*(B11^2)*($D$4^2*(2*PI())^4*A11^-5/4/PI()/$H$5^4*EXP((-1/PI())*(2*PI()/$H$5)^4*A11^-4)) -> 8.2365314e-39 | I11: =$B$4*(B11^2)*($D$4^2*(2*PI())^4*A11^-5/4/PI()/$I$5^4*EXP((-1/PI())*(2*PI()/$I$5)^4*A11^-4)) -> 5.3769065e-20 | J11: =$B$4*(B11^2)*($D$4^2*(2*PI())^4*A11^-5/4/PI()/$J$5^4*EXP((-1/PI())*(2*PI()/$J$5)^4*A11^-4)) -> 1.1364424e-09 | K11: =$B$4*(B11^2)*($D$4^2*(2*PI())^4*A11^-5/4/PI()/$K$5^4*EXP((-1/PI())*(2*PI()/$K$5)^4*A11^-4)) -> 0.0011868109 | L11: =$B$4*(B11^2)*($D$4^2*(2*PI())^4*A11^-5/4/PI()/$L$5^4*EXP((-1/PI())*(2*PI()/$L$5)^4*A11^-4)) -> 5.664749 | M11: =$B$4*(B11^2)*($D$4^2*(2*PI())^4*A11^-5/4/PI()/$M$5^4*EXP((-1/PI())*(2*PI()/$M$5)^4*A11^-4)) -> 1223.3157 | N11: =$B$4*(B11^2)*($D$4^2*(2*PI())^4*A11^-5/4/PI()/$N$5^4*EXP((-1/PI())*(2*PI()/$N$5)^4*A11^-4)) -> 41040.846 | O11: =$B$4*(B11^2)*($D$4^2*(2*PI())^4*A11^-5/4/PI()/$O$5^4*EXP((-1/PI())*(2*PI()/$O$5)^4*A11^-4)) -> 430010.36 | P11: =$B$4*(B11^2)*($D$4^2*(2*PI())^4*A11^-5/4/PI()/$P$5^4*EXP((-1/PI())*(2*PI()/$P$5)^4*A11^-4)) -> 2125561.3 | Q11: =$B$4*(B11^2)*($D$4^2*(2*PI())^4*A11^-5/4/PI()/$Q$5^4*EXP((-1/PI())*(2*PI()/$Q$5)^4*A11^-4)) -> 6382048.3 | R11: =$B$4*(B11^2)*($D$4^2*(2*PI())^4*A11^-5/4/PI()/$R$5^4*EXP((-1/PI())*(2*PI()/$R$5)^4*A11^-4)) -> 13656473 | S11: =$B$4*(B11^2)*($D$4^2*(2*PI())^4*A11^-5/4/PI()/$S$5^4*EXP((-1/PI())*(2*PI()/$S$5)^4*A11^-4)) -> 23105313
A12: 0.2225 | B12: ='2.VBM_RAO'!M12 -> 216758.56 | D12: =$B$4*(B12^2)*($D$4^2*(2*PI())^4*A12^-5/4/PI()/$D$5^4*EXP((-1/PI())*(2*PI()/$D$5)^4*A12^-4)) -> 0 | E12: =$B$4*(B12^2)*($D$4^2*(2*PI())^4*A12^-5/4/PI()/$E$5^4*EXP((-1/PI())*(2*PI()/$E$5)^4*A12^-4)) -> 7.8121812e-204 | F12: =$B$4*(B12^2)*($D$4^2*(2*PI())^4*A12^-5/4/PI()/$F$5^4*EXP((-1/PI())*(2*PI()/$F$5)^4*A12^-4)) -> 7.1610773e-86 | G12: =$B$4*(B12^2)*($D$4^2*(2*PI())^4*A12^-5/4/PI()/$G$5^4*EXP((-1/PI())*(2*PI()/$G$5)^4*A12^-4)) -> 2.435922e-39 | H12: =$B$4*(B12^2)*($D$4^2*(2*PI())^4*A12^-5/4/PI()/$H$5^4*EXP((-1/PI())*(2*PI()/$H$5)^4*A12^-4)) -> 3.9950938e-18 | I12: =$B$4*(B12^2)*($D$4^2*(2*PI())^4*A12^-5/4/PI()/$I$5^4*EXP((-1/PI())*(2*PI()/$I$5)^4*A12^-4)) -> 2.1236915e-07 | J12: =$B$4*(B12^2)*($D$4^2*(2*PI())^4*A12^-5/4/PI()/$J$5^4*EXP((-1/PI())*(2*PI()/$J$5)^4*A12^-4)) -> 0.15190209 | K12: =$B$4*(B12^2)*($D$4^2*(2*PI())^4*A12^-5/4/PI()/$K$5^4*EXP((-1/PI())*(2*PI()/$K$5)^4*A12^-4)) -> 370.10846 | L12: =$B$4*(B12^2)*($D$4^2*(2*PI())^4*A12^-5/4/PI()/$L$5^4*EXP((-1/PI())*(2*PI()/$L$5)^4*A12^-4)) -> 41339.672 | M12: =$B$4*(B12^2)*($D$4^2*(2*PI())^4*A12^-5/4/PI()/$M$5^4*EXP((-1/PI())*(2*PI()/$M$5)^4*A12^-4)) -> 788847.36 | N12: =$B$4*(B12^2)*($D$4^2*(2*PI())^4*A12^-5/4/PI()/$N$5^4*EXP((-1/PI())*(2*PI()/$N$5)^4*A12^-4)) -> 5216642 | O12: =$B$4*(B12^2)*($D$4^2*(2*PI())^4*A12^-5/4/PI()/$O$5^4*EXP((-1/PI())*(2*PI()/$O$5)^4*A12^-4)) -> 17834130 | P12: =$B$4*(B12^2)*($D$4^2*(2*PI())^4*A12^-5/4/PI()/$P$5^4*EXP((-1/PI())*(2*PI()/$P$5)^4*A12^-4)) -> 39905984 | Q12: =$B$4*(B12^2)*($D$4^2*(2*PI())^4*A12^-5/4/PI()/$Q$5^4*EXP((-1/PI())*(2*PI()/$Q$5)^4*A12^-4)) -> 67517690 | R12: =$B$4*(B12^2)*($D$4^2*(2*PI())^4*A12^-5/4/PI()/$R$5^4*EXP((-1/PI())*(2*PI()/$R$5)^4*A12^-4)) -> 94608717 | S12: =$B$4*(B12^2)*($D$4^2*(2*PI())^4*A12^-5/4/PI()/$S$5^4*EXP((-1/PI())*(2*PI()/$S$5)^4*A12^-4)) -> 1.1646877e+08
A13: 0.25125 | B13: ='2.VBM_RAO'!M13 -> 331473.86 | D13: =$B$4*(B13^2)*($D$4^2*(2*PI())^4*A13^-5/4/PI()/$D$5^4*EXP((-1/PI())*(2*PI()/$D$5)^4*A13^-4)) -> 0 | E13: =$B$4*(B13^2)*($D$4^2*(2*PI())^4*A13^-5/4/PI()/$E$5^4*EXP((-1/PI())*(2*PI()/$E$5)^4*A13^-4)) -> 3.3711285e-121 | F13: =$B$4*(B13^2)*($D$4^2*(2*PI())^4*A13^-5/4/PI()/$F$5^4*EXP((-1/PI())*(2*PI()/$F$5)^4*A13^-4)) -> 8.7858307e-49 | G13: =$B$4*(B13^2)*($D$4^2*(2*PI())^4*A13^-5/4/PI()/$G$5^4*EXP((-1/PI())*(2*PI()/$G$5)^4*A13^-4)) -> 2.8210528e-20 | H13: =$B$4*(B13^2)*($D$4^2*(2*PI())^4*A13^-5/4/PI()/$H$5^4*EXP((-1/PI())*(2*PI()/$H$5)^4*A13^-4)) -> 2.5262285e-07 | I13: =$B$4*(B13^2)*($D$4^2*(2*PI())^4*A13^-5/4/PI()/$I$5^4*EXP((-1/PI())*(2*PI()/$I$5)^4*A13^-4)) -> 0.82281875 | J13: =$B$4*(B13^2)*($D$4^2*(2*PI())^4*A13^-5/4/PI()/$J$5^4*EXP((-1/PI())*(2*PI()/$J$5)^4*A13^-4)) -> 2764.3462 | K13: =$B$4*(B13^2)*($D$4^2*(2*PI())^4*A13^-5/4/PI()/$K$5^4*EXP((-1/PI())*(2*PI()/$K$5)^4*A13^-4)) -> 286827.03 | L13: =$B$4*(B13^2)*($D$4^2*(2*PI())^4*A13^-5/4/PI()/$L$5^4*EXP((-1/PI())*(2*PI()/$L$5)^4*A13^-4)) -> 4532991 | M13: =$B$4*(B13^2)*($D$4^2*(2*PI())^4*A13^-5/4/PI()/$M$5^4*EXP((-1/PI())*(2*PI()/$M$5)^4*A13^-4)) -> 24448082 | N13: =$B$4*(B13^2)*($D$4^2*(2*PI())^4*A13^-5/4/PI()/$N$5^4*EXP((-1/PI())*(2*PI()/$N$5)^4*A13^-4)) -> 69397676 | O13: =$B$4*(B13^2)*($D$4^2*(2*PI())^4*A13^-5/4/PI()/$O$5^4*EXP((-1/PI())*(2*PI()/$O$5)^4*A13^-4)) -> 1.3240242e+08 | P13: =$B$4*(B13^2)*($D$4^2*(2*PI())^4*A13^-5/4/PI()/$P$5^4*EXP((-1/PI())*(2*PI()/$P$5)^4*A13^-4)) -> 1.9607575e+08 | Q13: =$B$4*(B13^2)*($D$4^2*(2*PI())^4*A13^-5/4/PI()/$Q$5^4*EXP((-1/PI())*(2*PI()/$Q$5)^4*A13^-4)) -> 2.4607796e+08 | R13: =$B$4*(B13^2)*($D$4^2*(2*PI())^4*A13^-5/4/PI()/$R$5^4*EXP((-1/PI())*(2*PI()/$R$5)^4*A13^-4)) -> 2.7658749e+08 | S13: =$B$4*(B13^2)*($D$4^2*(2*PI())^4*A13^-5/4/PI()/$S$5^4*EXP((-1/PI())*(2*PI()/$S$5)^4*A13^-4)) -> 2.8853155e+08
A14: 0.28 | B14: ='2.VBM_RAO'!M14 -> 472200.19 | D14: =$B$4*(B14^2)*($D$4^2*(2*PI())^4*A14^-5/4/PI()/$D$5^4*EXP((-1/PI())*(2*PI()/$D$5)^4*A14^-4)) -> 1.9896272e-222 | E14: =$B$4*(B14^2)*($D$4^2*(2*PI())^4*A14^-5/4/PI()/$E$5^4*EXP((-1/PI())*(2*PI()/$E$5)^4*A14^-4)) -> 9.2956305e-75 | F14: =$B$4*(B14^2)*($D$4^2*(2*PI())^4*A14^-5/4/PI()/$F$5^4*EXP((-1/PI())*(2*PI()/$F$5)^4*A14^-4)) -> 6.2334181e-28 | G14: =$B$4*(B14^2)*($D$4^2*(2*PI())^4*A14^-5/4/PI()/$G$5^4*EXP((-1/PI())*(2*PI()/$G$5)^4*A14^-4)) -> 1.4934915e-09 | H14: =$B$4*(B14^2)*($D$4^2*(2*PI())^4*A14^-5/4/PI()/$H$5^4*EXP((-1/PI())*(2*PI()/$H$5)^4*A14^-4)) -> 0.30472806 | I14: =$B$4*(B14^2)*($D$4^2*(2*PI())^4*A14^-5/4/PI()/$I$5^4*EXP((-1/PI())*(2*PI()/$I$5)^4*A14^-4)) -> 4264.5468 | J14: =$B$4*(B14^2)*($D$4^2*(2*PI())^4*A14^-5/4/PI()/$J$5^4*EXP((-1/PI())*(2*PI()/$J$5)^4*A14^-4)) -> 704855.54 | K14: =$B$4*(B14^2)*($D$4^2*(2*PI())^4*A14^-5/4/PI()/$K$5^4*EXP((-1/PI())*(2*PI()/$K$5)^4*A14^-4)) -> 12416410 | L14: =$B$4*(B14^2)*($D$4^2*(2*PI())^4*A14^-5/4/PI()/$L$5^4*EXP((-1/PI())*(2*PI()/$L$5)^4*A14^-4)) -> 65404454 | M14: =$B$4*(B14^2)*($D$4^2*(2*PI())^4*A14^-5/4/PI()/$M$5^4*EXP((-1/PI())*(2*PI()/$M$5)^4*A14^-4)) -> 1.7344027e+08 | N14: =$B$4*(B14^2)*($D$4^2*(2*PI())^4*A14^-5/4/PI()/$N$5^4*EXP((-1/PI())*(2*PI()/$N$5)^4*A14^-4)) -> 3.0611764e+08 | O14: =$B$4*(B14^2)*($D$4^2*(2*PI())^4*A14^-5/4/PI()/$O$5^4*EXP((-1/PI())*(2*PI()/$O$5)^4*A14^-4)) -> 4.2084324e+08 | P14: =$B$4*(B14^2)*($D$4^2*(2*PI())^4*A14^-5/4/PI()/$P$5^4*EXP((-1/PI())*(2*PI()/$P$5)^4*A14^-4)) -> 4.9423604e+08 | Q14: =$B$4*(B14^2)*($D$4^2*(2*PI())^4*A14^-5/4/PI()/$Q$5^4*EXP((-1/PI())*(2*PI()/$Q$5)^4*A14^-4)) -> 5.2443982e+08 | R14: =$B$4*(B14^2)*($D$4^2*(2*PI())^4*A14^-5/4/PI()/$R$5^4*EXP((-1/PI())*(2*PI()/$R$5)^4*A14^-4)) -> 5.2078374e+08 | S14: =$B$4*(B14^2)*($D$4^2*(2*PI())^4*A14^-5/4/PI()/$S$5^4*EXP((-1/PI())*(2*PI()/$S$5)^4*A14^-4)) -> 4.9500799e+08
A15: 0.30875 | B15: ='2.VBM_RAO'!M15 -> 627599.4 | D15: =$B$4*(B15^2)*($D$4^2*(2*PI())^4*A15^-5/4/PI()/$D$5^4*EXP((-1/PI())*(2*PI()/$D$5)^4*A15^-4)) -> 8.3621125e-147 | E15: =$B$4*(B15^2)*($D$4^2*(2*PI())^4*A15^-5/4/PI()/$E$5^4*EXP((-1/PI())*(2*PI()/$E$5)^4*A15^-4)) -> 4.6221773e-47 | F15: =$B$4*(B15^2)*($D$4^2*(2*PI())^4*A15^-5/4/PI()/$F$5^4*EXP((-1/PI())*(2*PI()/$F$5)^4*A15^-4)) -> 1.6807264e-15 | G15: =$B$4*(B15^2)*($D$4^2*(2*PI())^4*A15^-5/4/PI()/$G$5^4*EXP((-1/PI())*(2*PI()/$G$5)^4*A15^-4)) -> 0.0036600295 | H15: =$B$4*(B15^2)*($D$4^2*(2*PI())^4*A15^-5/4/PI()/$H$5^4*EXP((-1/PI())*(2*PI()/$H$5)^4*A15^-4)) -> 1269.8043 | I15: =$B$4*(B15^2)*($D$4^2*(2*PI())^4*A15^-5/4/PI()/$I$5^4*EXP((-1/PI())*(2*PI()/$I$5)^4*A15^-4)) -> 688190 | J15: =$B$4*(B15^2)*($D$4^2*(2*PI())^4*A15^-5/4/PI()/$J$5^4*EXP((-1/PI())*(2*PI()/$J$5)^4*A15^-4)) -> 18862279 | K15: =$B$4*(B15^2)*($D$4^2*(2*PI())^4*A15^-5/4/PI()/$K$5^4*EXP((-1/PI())*(2*PI()/$K$5)^4*A15^-4)) -> 1.1536064e+08 | L15: =$B$4*(B15^2)*($D$4^2*(2*PI())^4*A15^-5/4/PI()/$L$5^4*EXP((-1/PI())*(2*PI()/$L$5)^4*A15^-4)) -> 3.1551249e+08 | M15: =$B$4*(B15^2)*($D$4^2*(2*PI())^4*A15^-5/4/PI()/$M$5^4*EXP((-1/PI())*(2*PI()/$M$5)^4*A15^-4)) -> 5.4780796e+08 | N15: =$B$4*(B15^2)*($D$4^2*(2*PI())^4*A15^-5/4/PI()/$N$5^4*EXP((-1/PI())*(2*PI()/$N$5)^4*A15^-4)) -> 7.2821377e+08 | O15: =$B$4*(B15^2)*($D$4^2*(2*PI())^4*A15^-5/4/PI()/$O$5^4*EXP((-1/PI())*(2*PI()/$O$5)^4*A15^-4)) -> 8.2335772e+08 | P15: =$B$4*(B15^2)*($D$4^2*(2*PI())^4*A15^-5/4/PI()/$P$5^4*EXP((-1/PI())*(2*PI()/$P$5)^4*A15^-4)) -> 8.4201606e+08 | Q15: =$B$4*(B15^2)*($D$4^2*(2*PI())^4*A15^-5/4/PI()/$Q$5^4*EXP((-1/PI())*(2*PI()/$Q$5)^4*A15^-4)) -> 8.0835021e+08 | R15: =$B$4*(B15^2)*($D$4^2*(2*PI())^4*A15^-5/4/PI()/$R$5^4*EXP((-1/PI())*(2*PI()/$R$5)^4*A15^-4)) -> 7.4553383e+08 | S15: =$B$4*(B15^2)*($D$4^2*(2*PI())^4*A15^-5/4/PI()/$S$5^4*EXP((-1/PI())*(2*PI()/$S$5)^4*A15^-4)) -> 6.703744e+08
A16: 0.3375 | B16: ='2.VBM_RAO'!M16 -> 782998.61 | D16: =$B$4*(B16^2)*($D$4^2*(2*PI())^4*A16^-5/4/PI()/$D$5^4*EXP((-1/PI())*(2*PI()/$D$5)^4*A16^-4)) -> 1.8238863e-99 | E16: =$B$4*(B16^2)*($D$4^2*(2*PI())^4*A16^-5/4/PI()/$E$5^4*EXP((-1/PI())*(2*PI()/$E$5)^4*A16^-4)) -> 9.7208813e-30 | F16: =$B$4*(B16^2)*($D$4^2*(2*PI())^4*A16^-5/4/PI()/$F$5^4*EXP((-1/PI())*(2*PI()/$F$5)^4*A16^-4)) -> 9.7197667e-08 | G16: =$B$4*(B16^2)*($D$4^2*(2*PI())^4*A16^-5/4/PI()/$G$5^4*EXP((-1/PI())*(2*PI()/$G$5)^4*A16^-4)) -> 34.830931 | H16: =$B$4*(B16^2)*($D$4^2*(2*PI())^4*A16^-5/4/PI()/$H$5^4*EXP((-1/PI())*(2*PI()/$H$5)^4*A16^-4)) -> 222717.71 | I16: =$B$4*(B16^2)*($D$4^2*(2*PI())^4*A16^-5/4/PI()/$I$5^4*EXP((-1/PI())*(2*PI()/$I$5)^4*A16^-4)) -> 15755150 | J16: =$B$4*(B16^2)*($D$4^2*(2*PI())^4*A16^-5/4/PI()/$J$5^4*EXP((-1/PI())*(2*PI()/$J$5)^4*A16^-4)) -> 1.4015036e+08 | K16: =$B$4*(B16^2)*($D$4^2*(2*PI())^4*A16^-5/4/PI()/$K$5^4*EXP((-1/PI())*(2*PI()/$K$5)^4*A16^-4)) -> 4.4189923e+08 | L16: =$B$4*(B16^2)*($D$4^2*(2*PI())^4*A16^-5/4/PI()/$L$5^4*EXP((-1/PI())*(2*PI()/$L$5)^4*A16^-4)) -> 8.0169539e+08 | M16: =$B$4*(B16^2)*($D$4^2*(2*PI())^4*A16^-5/4/PI()/$M$5^4*EXP((-1/PI())*(2*PI()/$M$5)^4*A16^-4)) -> 1.067649e+09 | N16: =$B$4*(B16^2)*($D$4^2*(2*PI())^4*A16^-5/4/PI()/$N$5^4*EXP((-1/PI())*(2*PI()/$N$5)^4*A16^-4)) -> 1.1883894e+09 | O16: =$B$4*(B16^2)*($D$4^2*(2*PI())^4*A16^-5/4/PI()/$O$5^4*EXP((-1/PI())*(2*PI()/$O$5)^4*A16^-4)) -> 1.1888187e+09 | P16: =$B$4*(B16^2)*($D$4^2*(2*PI())^4*A16^-5/4/PI()/$P$5^4*EXP((-1/PI())*(2*PI()/$P$5)^4*A16^-4)) -> 1.1148565e+09 | Q16: =$B$4*(B16^2)*($D$4^2*(2*PI())^4*A16^-5/4/PI()/$Q$5^4*EXP((-1/PI())*(2*PI()/$Q$5)^4*A16^-4)) -> 1.0052315e+09 | R16: =$B$4*(B16^2)*($D$4^2*(2*PI())^4*A16^-5/4/PI()/$R$5^4*EXP((-1/PI())*(2*PI()/$R$5)^4*A16^-4)) -> 8.8518495e+08 | S16: =$B$4*(B16^2)*($D$4^2*(2*PI())^4*A16^-5/4/PI()/$S$5^4*EXP((-1/PI())*(2*PI()/$S$5)^4*A16^-4)) -> 7.6875458e+08
A17: 0.36625 | B17: ='2.VBM_RAO'!M17 -> 915054.6 | D17: =$B$4*(B17^2)*($D$4^2*(2*PI())^4*A17^-5/4/PI()/$D$5^4*EXP((-1/PI())*(2*PI()/$D$5)^4*A17^-4)) -> 1.2123943e-68 | E17: =$B$4*(B17^2)*($D$4^2*(2*PI())^4*A17^-5/4/PI()/$E$5^4*EXP((-1/PI())*(2*PI()/$E$5)^4*A17^-4)) -> 1.7399596e-18 | F17: =$B$4*(B17^2)*($D$4^2*(2*PI())^4*A17^-5/4/PI()/$F$5^4*EXP((-1/PI())*(2*PI()/$F$5)^4*A17^-4)) -> 0.010164202 | G17: =$B$4*(B17^2)*($D$4^2*(2*PI())^4*A17^-5/4/PI()/$G$5^4*EXP((-1/PI())*(2*PI()/$G$5)^4*A17^-4)) -> 12430.477 | H17: =$B$4*(B17^2)*($D$4^2*(2*PI())^4*A17^-5/4/PI()/$H$5^4*EXP((-1/PI())*(2*PI()/$H$5)^4*A17^-4)) -> 5880808.1 | I17: =$B$4*(B17^2)*($D$4^2*(2*PI())^4*A17^-5/4/PI()/$I$5^4*EXP((-1/PI())*(2*PI()/$I$5)^4*A17^-4)) -> 1.1029442e+08 | J17: =$B$4*(B17^2)*($D$4^2*(2*PI())^4*A17^-5/4/PI()/$J$5^4*EXP((-1/PI())*(2*PI()/$J$5)^4*A17^-4)) -> 4.7107695e+08 | K17: =$B$4*(B17^2)*($D$4^2*(2*PI())^4*A17^-5/4/PI()/$K$5^4*EXP((-1/PI())*(2*PI()/$K$5)^4*A17^-4)) -> 9.6432365e+08 | L17: =$B$4*(B17^2)*($D$4^2*(2*PI())^4*A17^-5/4/PI()/$L$5^4*EXP((-1/PI())*(2*PI()/$L$5)^4*A17^-4)) -> 1.3386841e+09 | M17: =$B$4*(B17^2)*($D$4^2*(2*PI())^4*A17^-5/4/PI()/$M$5^4*EXP((-1/PI())*(2*PI()/$M$5)^4*A17^-4)) -> 1.4996626e+09 | N17: =$B$4*(B17^2)*($D$4^2*(2*PI())^4*A17^-5/4/PI()/$N$5^4*EXP((-1/PI())*(2*PI()/$N$5)^4*A17^-4)) -> 1.4868109e+09 | O17: =$B$4*(B17^2)*($D$4^2*(2*PI())^4*A17^-5/4/PI()/$O$5^4*EXP((-1/PI())*(2*PI()/$O$5)^4*A17^-4)) -> 1.3732347e+09 | P17: =$B$4*(B17^2)*($D$4^2*(2*PI())^4*A17^-5/4/PI()/$P$5^4*EXP((-1/PI())*(2*PI()/$P$5)^4*A17^-4)) -> 1.2170685e+09 | Q17: =$B$4*(B17^2)*($D$4^2*(2*PI())^4*A17^-5/4/PI()/$Q$5^4*EXP((-1/PI())*(2*PI()/$Q$5)^4*A17^-4)) -> 1.0534339e+09 | R17: =$B$4*(B17^2)*($D$4^2*(2*PI())^4*A17^-5/4/PI()/$R$5^4*EXP((-1/PI())*(2*PI()/$R$5)^4*A17^-4)) -> 9.0005788e+08 | S17: =$B$4*(B17^2)*($D$4^2*(2*PI())^4*A17^-5/4/PI()/$S$5^4*EXP((-1/PI())*(2*PI()/$S$5)^4*A17^-4)) -> 7.6415517e+08
... A46: 1.2 | B46: ='2.VBM_RAO'!M46 -> 56023.751 | D46: =$B$4*(B46^2)*($D$4^2*(2*PI())^4*A46^-5/4/PI()/$D$5^4*EXP((-1/PI())*(2*PI()/$D$5)^4*A46^-4)) -> 1521436.8 | E46: =$B$4*(B46^2)*($D$4^2*(2*PI())^4*A46^-5/4/PI()/$E$5^4*EXP((-1/PI())*(2*PI()/$E$5)^4*A46^-4)) -> 1530001.1 | F46: =$B$4*(B46^2)*($D$4^2*(2*PI())^4*A46^-5/4/PI()/$F$5^4*EXP((-1/PI())*(2*PI()/$F$5)^4*A46^-4)) -> 946078.53 | G46: =$B$4*(B46^2)*($D$4^2*(2*PI())^4*A46^-5/4/PI()/$G$5^4*EXP((-1/PI())*(2*PI()/$G$5)^4*A46^-4)) -> 550890.31 | H46: =$B$4*(B46^2)*($D$4^2*(2*PI())^4*A46^-5/4/PI()/$H$5^4*EXP((-1/PI())*(2*PI()/$H$5)^4*A46^-4)) -> 329489.82 | I46: =$B$4*(B46^2)*($D$4^2*(2*PI())^4*A46^-5/4/PI()/$I$5^4*EXP((-1/PI())*(2*PI()/$I$5)^4*A46^-4)) -> 205752.59 | J46: =$B$4*(B46^2)*($D$4^2*(2*PI())^4*A46^-5/4/PI()/$J$5^4*EXP((-1/PI())*(2*PI()/$J$5)^4*A46^-4)) -> 134052.4 | K46: =$B$4*(B46^2)*($D$4^2*(2*PI())^4*A46^-5/4/PI()/$K$5^4*EXP((-1/PI())*(2*PI()/$K$5)^4*A46^-4)) -> 90702.71 | L46: =$B$4*(B46^2)*($D$4^2*(2*PI())^4*A46^-5/4/PI()/$L$5^4*EXP((-1/PI())*(2*PI()/$L$5)^4*A46^-4)) -> 63415.225 | M46: =$B$4*(B46^2)*($D$4^2*(2*PI())^4*A46^-5/4/PI()/$M$5^4*EXP((-1/PI())*(2*PI()/$M$5)^4*A46^-4)) -> 45606.808 | N46: =$B$4*(B46^2)*($D$4^2*(2*PI())^4*A46^-5/4/PI()/$N$5^4*EXP((-1/PI())*(2*PI()/$N$5)^4*A46^-4)) -> 33609.522 | O46: =$B$4*(B46^2)*($D$4^2*(2*PI())^4*A46^-5/4/PI()/$O$5^4*EXP((-1/PI())*(2*PI()/$O$5)^4*A46^-4)) -> 25298.986 | P46: =$B$4*(B46^2)*($D$4^2*(2*PI())^4*A46^-5/4/PI()/$P$5^4*EXP((-1/PI())*(2*PI()/$P$5)^4*A46^-4)) -> 19399.864 | Q46: =$B$4*(B46^2)*($D$4^2*(2*PI())^4*A46^-5/4/PI()/$Q$5^4*EXP((-1/PI())*(2*PI()/$Q$5)^4*A46^-4)) -> 15121.261 | R46: =$B$4*(B46^2)*($D$4^2*(2*PI())^4*A46^-5/4/PI()/$R$5^4*EXP((-1/PI())*(2*PI()/$R$5)^4*A46^-4)) -> 11958.193 | S46: =$B$4*(B46^2)*($D$4^2*(2*PI())^4*A46^-5/4/PI()/$S$5^4*EXP((-1/PI())*(2*PI()/$S$5)^4*A46^-4)) -> 9579.6943
A47: 1.22875 | C47: sum | D47: =SUM(D6:D46) -> 21948250 | E47: =SUM(E6:E46) -> 1.2876228e+08 | F47: =SUM(F6:F46) -> 3.9753605e+08 | G47: =SUM(G6:G46) -> 9.4118782e+08 | H47: =SUM(H6:H46) -> 2.2234268e+09 | I47: =SUM(I6:I46) -> 4.2519652e+09 | J47: =SUM(J6:J46) -> 6.3646737e+09 | K47: =SUM(K6:K46) -> 7.9467307e+09 | ... S47: =SUM(S6:S46) -> 5.0087875e+09 | T47: =SUM(D47:S47) -> 8.1053046e+10
A48: w0 | B48: =A51-A50 -> 0.02875 | C48: Hs | D48: 1.5
A49: w | B49: RAO(0) | C49: Tz | D49: 3.5 | E49: 4.5 | F49: 5.5 | G49: 6.5 | H49: 7.5 | I49: 8.5 | J49: 9.5 | K49: 10.5 | L49: 11.5 | M49: 12.5 | N49: 13.5 | O49: 14.5 | P49: 15.5 | Q49: 16.5 | R49: 17.5 | S49: 18.5
A50: =A6 -> 0.05 | B50: =B6 -> 0 | D50: =$B$4*(B50^2)*($D$48^2*(2*PI())^4*A50^-5/4/PI()/$D$5^4*EXP((-1/PI())*(2*PI()/$D$5)^4*A50^-4)) -> 0 | E50: =$B$4*(B50^2)*($D$48^2*(2*PI())^4*A50^-5/4/PI()/$E$5^4*EXP((-1/PI())*(2*PI()/$E$5)^4*A50^-4)) -> 0 | F50: =$B$4*(B50^2)*($D$48^2*(2*PI())^4*A50^-5/4/PI()/$F$5^4*EXP((-1/PI())*(2*PI()/$F$5)^4*A50^-4)) -> 0 | G50: =$B$4*(B50^2)*($D$48^2*(2*PI())^4*A50^-5/4/PI()/$G$5^4*EXP((-1/PI())*(2*PI()/$G$5)^4*A50^-4)) -> 0 | H50: =$B$4*(B50^2)*($D$48^2*(2*PI())^4*A50^-5/4/PI()/$H$5^4*EXP((-1/PI())*(2*PI()/$H$5)^4*A50^-4)) -> 0 | I50: =$B$4*(B50^2)*($D$48^2*(2*PI())^4*A50^-5/4/PI()/$I$5^4*EXP((-1/PI())*(2*PI()/$I$5)^4*A50^-4)) -> 0 | J50: =$B$4*(B50^2)*($D$48^2*(2*PI())^4*A50^-5/4/PI()/$J$5^4*EXP((-1/PI())*(2*PI()/$J$5)^4*A50^-4)) -> 0 | K50: =$B$4*(B50^2)*($D$48^2*(2*PI())^4*A50^-5/4/PI()/$K$5^4*EXP((-1/PI())*(2*PI()/$K$5)^4*A50^-4)) -> 0 | L50: =$B$4*(B50^2)*($D$48^2*(2*PI())^4*A50^-5/4/PI()/$L$5^4*EXP((-1/PI())*(2*PI()/$L$5)^4*A50^-4)) -> 0 | M50: =$B$4*(B50^2)*($D$48^2*(2*PI())^4*A50^-5/4/PI()/$M$5^4*EXP((-1/PI())*(2*PI()/$M$5)^4*A50^-4)) -> 0 | N50: =$B$4*(B50^2)*($D$48^2*(2*PI())^4*A50^-5/4/PI()/$N$5^4*EXP((-1/PI())*(2*PI()/$N$5)^4*A50^-4)) -> 0 | O50: =$B$4*(B50^2)*($D$48^2*(2*PI())^4*A50^-5/4/PI()/$O$5^4*EXP((-1/PI())*(2*PI()/$O$5)^4*A50^-4)) -> 0 | P50: =$B$4*(B50^2)*($D$48^2*(2*PI())^4*A50^-5/4/PI()/$P$5^4*EXP((-1/PI())*(2*PI()/$P$5)^4*A50^-4)) -> 0 | Q50: =$B$4*(B50^2)*($D$48^2*(2*PI())^4*A50^-5/4/PI()/$Q$5^4*EXP((-1/PI())*(2*PI()/$Q$5)^4*A50^-4)) -> 0 | R50: =$B$4*(B50^2)*($D$48^2*(2*PI())^4*A50^-5/4/PI()/$R$5^4*EXP((-1/PI())*(2*PI()/$R$5)^4*A50^-4)) -> 0 | S50: =$B$4*(B50^2)*($D$48^2*(2*PI())^4*A50^-5/4/PI()/$S$5^4*EXP((-1/PI())*(2*PI()/$S$5)^4*A50^-4)) -> 0
A51: =A7 -> 0.07875 | B51: =B7 -> 2667.7977 | D51: =$B$4*(B51^2)*($D$48^2*(2*PI())^4*A51^-5/4/PI()/$D$5^4*EXP((-1/PI())*(2*PI()/$D$5)^4*A51^-4)) -> 0 | E51: =$B$4*(B51^2)*($D$48^2*(2*PI())^4*A51^-5/4/PI()/$E$5^4*EXP((-1/PI())*(2*PI()/$E$5)^4*A51^-4)) -> 0 | F51: =$B$4*(B51^2)*($D$48^2*(2*PI())^4*A51^-5/4/PI()/$F$5^4*EXP((-1/PI())*(2*PI()/$F$5)^4*A51^-4)) -> 0 | G51: =$B$4*(B51^2)*($D$48^2*(2*PI())^4*A51^-5/4/PI()/$G$5^4*EXP((-1/PI())*(2*PI()/$G$5)^4*A51^-4)) -> 0 | H51: =$B$4*(B51^2)*($D$48^2*(2*PI())^4*A51^-5/4/PI()/$H$5^4*EXP((-1/PI())*(2*PI()/$H$5)^4*A51^-4)) -> 0 | I51: =$B$4*(B51^2)*($D$48^2*(2*PI())^4*A51^-5/4/PI()/$I$5^4*EXP((-1/PI())*(2*PI()/$I$5)^4*A51^-4)) -> 0 | J51: =$B$4*(B51^2)*($D$48^2*(2*PI())^4*A51^-5/4/PI()/$J$5^4*EXP((-1/PI())*(2*PI()/$J$5)^4*A51^-4)) -> 0 | K51: =$B$4*(B51^2)*($D$48^2*(2*PI())^4*A51^-5/4/PI()/$K$5^4*EXP((-1/PI())*(2*PI()/$K$5)^4*A51^-4)) -> 0 | L51: =$B$4*(B51^2)*($D$48^2*(2*PI())^4*A51^-5/4/PI()/$L$5^4*EXP((-1/PI())*(2*PI()/$L$5)^4*A51^-4)) -> 0 | M51: =$B$4*(B51^2)*($D$48^2*(2*PI())^4*A51^-5/4/PI()/$M$5^4*EXP((-1/PI())*(2*PI()/$M$5)^4*A51^-4)) -> 2.6625723e-221 | N51: =$B$4*(B51^2)*($D$48^2*(2*PI())^4*A51^-5/4/PI()/$N$5^4*EXP((-1/PI())*(2*PI()/$N$5)^4*A51^-4)) -> 1.2368108e-160 | O51: =$B$4*(B51^2)*($D$48^2*(2*PI())^4*A51^-5/4/PI()/$O$5^4*EXP((-1/PI())*(2*PI()/$O$5)^4*A51^-4)) -> 7.9404882e-119 | P51: =$B$4*(B51^2)*($D$48^2*(2*PI())^4*A51^-5/4/PI()/$P$5^4*EXP((-1/PI())*(2*PI()/$P$5)^4*A51^-4)) -> 2.8674887e-89 | Q51: =$B$4*(B51^2)*($D$48^2*(2*PI())^4*A51^-5/4/PI()/$Q$5^4*EXP((-1/PI())*(2*PI()/$Q$5)^4*A51^-4)) -> 6.666245e-68 | R51: =$B$4*(B51^2)*($D$48^2*(2*PI())^4*A51^-5/4/PI()/$R$5^4*EXP((-1/PI())*(2*PI()/$R$5)^4*A51^-4)) -> 3.7348616e-52 | S51: =$B$4*(B51^2)*($D$48^2*(2*PI())^4*A51^-5/4/PI()/$S$5^4*EXP((-1/PI())*(2*PI()/$S$5)^4*A51^-4)) -> 2.4022607e-40
A52: =A8 -> 0.1075 | B52: =B8 -> 12005.089 | D52: =$B$4*(B52^2)*($D$48^2*(2*PI())^4*A52^-5/4/PI()/$D$5^4*EXP((-1/PI())*(2*PI()/$D$5)^4*A52^-4)) -> 0 | E52: =$B$4*(B52^2)*($D$48^2*(2*PI())^4*A52^-5/4/PI()/$E$5^4*EXP((-1/PI())*(2*PI()/$E$5)^4*A52^-4)) -> 0 | F52: =$B$4*(B52^2)*($D$48^2*(2*PI())^4*A52^-5/4/PI()/$F$5^4*EXP((-1/PI())*(2*PI()/$F$5)^4*A52^-4)) -> 0 | G52: =$B$4*(B52^2)*($D$48^2*(2*PI())^4*A52^-5/4/PI()/$G$5^4*EXP((-1/PI())*(2*PI()/$G$5)^4*A52^-4)) -> 0 | H52: =$B$4*(B52^2)*($D$48^2*(2*PI())^4*A52^-5/4/PI()/$H$5^4*EXP((-1/PI())*(2*PI()/$H$5)^4*A52^-4)) -> 0 | I52: =$B$4*(B52^2)*($D$48^2*(2*PI())^4*A52^-5/4/PI()/$I$5^4*EXP((-1/PI())*(2*PI()/$I$5)^4*A52^-4)) -> 1.3404122e-299 | J52: =$B$4*(B52^2)*($D$48^2*(2*PI())^4*A52^-5/4/PI()/$J$5^4*EXP((-1/PI())*(2*PI()/$J$5)^4*A52^-4)) -> 8.3553064e-189 | K52: =$B$4*(B52^2)*($D$48^2*(2*PI())^4*A52^-5/4/PI()/$K$5^4*EXP((-1/PI())*(2*PI()/$K$5)^4*A52^-4)) -> 1.239273e-123 | L52: =$B$4*(B52^2)*($D$48^2*(2*PI())^4*A52^-5/4/PI()/$L$5^4*EXP((-1/PI())*(2*PI()/$L$5)^4*A52^-4)) -> 2.6377325e-83 | M52: =$B$4*(B52^2)*($D$48^2*(2*PI())^4*A52^-5/4/PI()/$M$5^4*EXP((-1/PI())*(2*PI()/$M$5)^4*A52^-4)) -> 2.7343972e-57 | N52: =$B$4*(B52^2)*($D$48^2*(2*PI())^4*A52^-5/4/PI()/$N$5^4*EXP((-1/PI())*(2*PI()/$N$5)^4*A52^-4)) -> 6.498241e-40 | O52: =$B$4*(B52^2)*($D$48^2*(2*PI())^4*A52^-5/4/PI()/$O$5^4*EXP((-1/PI())*(2*PI()/$O$5)^4*A52^-4)) -> 5.8118311e-28 | P52: =$B$4*(B52^2)*($D$48^2*(2*PI())^4*A52^-5/4/PI()/$P$5^4*EXP((-1/PI())*(2*PI()/$P$5)^4*A52^-4)) -> 1.5629848e-19 | Q52: =$B$4*(B52^2)*($D$48^2*(2*PI())^4*A52^-5/4/PI()/$Q$5^4*EXP((-1/PI())*(2*PI()/$Q$5)^4*A52^-4)) -> 1.861227e-13 | R52: =$B$4*(B52^2)*($D$48^2*(2*PI())^4*A52^-5/4/PI()/$R$5^4*EXP((-1/PI())*(2*PI()/$R$5)^4*A52^-4)) -> 5.3988995e-09 | S52: =$B$4*(B52^2)*($D$48^2*(2*PI())^4*A52^-5/4/PI()/$S$5^4*EXP((-1/PI())*(2*PI()/$S$5)^4*A52^-4)) -> 1.1592734e-05
A53: =A9 -> 0.13625 | B53: =B9 -> 32013.572 | D53: =$B$4*(B53^2)*($D$48^2*(2*PI())^4*A53^-5/4/PI()/$D$5^4*EXP((-1/PI())*(2*PI()/$D$5)^4*A53^-4)) -> 0 | E53: =$B$4*(B53^2)*($D$48^2*(2*PI())^4*A53^-5/4/PI()/$E$5^4*EXP((-1/PI())*(2*PI()/$E$5)^4*A53^-4)) -> 0 | F53: =$B$4*(B53^2)*($D$48^2*(2*PI())^4*A53^-5/4/PI()/$F$5^4*EXP((-1/PI())*(2*PI()/$F$5)^4*A53^-4)) -> 0 | G53: =$B$4*(B53^2)*($D$48^2*(2*PI())^4*A53^-5/4/PI()/$G$5^4*EXP((-1/PI())*(2*PI()/$G$5)^4*A53^-4)) -> 0 | H53: =$B$4*(B53^2)*($D$48^2*(2*PI())^4*A53^-5/4/PI()/$H$5^4*EXP((-1/PI())*(2*PI()/$H$5)^4*A53^-4)) -> 1.4257627e-187 | I53: =$B$4*(B53^2)*($D$48^2*(2*PI())^4*A53^-5/4/PI()/$I$5^4*EXP((-1/PI())*(2*PI()/$I$5)^4*A53^-4)) -> 5.7546704e-110 | J53: =$B$4*(B53^2)*($D$48^2*(2*PI())^4*A53^-5/4/PI()/$J$5^4*EXP((-1/PI())*(2*PI()/$J$5)^4*A53^-4)) -> 3.7689864e-67 | K53: =$B$4*(B53^2)*($D$48^2*(2*PI())^4*A53^-5/4/PI()/$K$5^4*EXP((-1/PI())*(2*PI()/$K$5)^4*A53^-4)) -> 5.302913e-42 | L53: =$B$4*(B53^2)*($D$48^2*(2*PI())^4*A53^-5/4/PI()/$L$5^4*EXP((-1/PI())*(2*PI()/$L$5)^4*A53^-4)) -> 1.8006326e-26 | M53: =$B$4*(B53^2)*($D$48^2*(2*PI())^4*A53^-5/4/PI()/$M$5^4*EXP((-1/PI())*(2*PI()/$M$5)^4*A53^-4)) -> 1.7706724e-16 | N53: =$B$4*(B53^2)*($D$48^2*(2*PI())^4*A53^-5/4/PI()/$N$5^4*EXP((-1/PI())*(2*PI()/$N$5)^4*A53^-4)) -> 7.9373612e-10 | O53: =$B$4*(B53^2)*($D$48^2*(2*PI())^4*A53^-5/4/PI()/$O$5^4*EXP((-1/PI())*(2*PI()/$O$5)^4*A53^-4)) -> 2.8512068e-05 | P53: =$B$4*(B53^2)*($D$48^2*(2*PI())^4*A53^-5/4/PI()/$P$5^4*EXP((-1/PI())*(2*PI()/$P$5)^4*A53^-4)) -> 0.04473801 | Q53: =$B$4*(B53^2)*($D$48^2*(2*PI())^4*A53^-5/4/PI()/$Q$5^4*EXP((-1/PI())*(2*PI()/$Q$5)^4*A53^-4)) -> 8.6822505 | R53: =$B$4*(B53^2)*($D$48^2*(2*PI())^4*A53^-5/4/PI()/$R$5^4*EXP((-1/PI())*(2*PI()/$R$5)^4*A53^-4)) -> 403.00589 | S53: =$B$4*(B53^2)*($D$48^2*(2*PI())^4*A53^-5/4/PI()/$S$5^4*EXP((-1/PI())*(2*PI()/$S$5)^4*A53^-4)) -> 6876.0161
A54: =A10 -> 0.165 | B54: =B10 -> 70029.689 | D54: =$B$4*(B54^2)*($D$48^2*(2*PI())^4*A54^-5/4/PI()/$D$5^4*EXP((-1/PI())*(2*PI()/$D$5)^4*A54^-4)) -> 0 | E54: =$B$4*(B54^2)*($D$48^2*(2*PI())^4*A54^-5/4/PI()/$E$5^4*EXP((-1/PI())*(2*PI()/$E$5)^4*A54^-4)) -> 0 | F54: =$B$4*(B54^2)*($D$48^2*(2*PI())^4*A54^-5/4/PI()/$F$5^4*EXP((-1/PI())*(2*PI()/$F$5)^4*A54^-4)) -> 0 | G54: =$B$4*(B54^2)*($D$48^2*(2*PI())^4*A54^-5/4/PI()/$G$5^4*EXP((-1/PI())*(2*PI()/$G$5)^4*A54^-4)) -> 2.5969632e-152 | H54: =$B$4*(B54^2)*($D$48^2*(2*PI())^4*A54^-5/4/PI()/$H$5^4*EXP((-1/PI())*(2*PI()/$H$5)^4*A54^-4)) -> 1.3720308e-81 | I54: =$B$4*(B54^2)*($D$48^2*(2*PI())^4*A54^-5/4/PI()/$I$5^4*EXP((-1/PI())*(2*PI()/$I$5)^4*A54^-4)) -> 1.2713331e-45 | J54: =$B$4*(B54^2)*($D$48^2*(2*PI())^4*A54^-5/4/PI()/$J$5^4*EXP((-1/PI())*(2*PI()/$J$5)^4*A54^-4)) -> 8.0994709e-26 | K54: =$B$4*(B54^2)*($D$48^2*(2*PI())^4*A54^-5/4/PI()/$K$5^4*EXP((-1/PI())*(2*PI()/$K$5)^4*A54^-4)) -> 3.2228316e-14 | L54: =$B$4*(B54^2)*($D$48^2*(2*PI())^4*A54^-5/4/PI()/$L$5^4*EXP((-1/PI())*(2*PI()/$L$5)^4*A54^-4)) -> 4.4141365e-07 | M54: =$B$4*(B54^2)*($D$48^2*(2*PI())^4*A54^-5/4/PI()/$M$5^4*EXP((-1/PI())*(2*PI()/$M$5)^4*A54^-4)) -> 0.016349331 | N54: =$B$4*(B54^2)*($D$48^2*(2*PI())^4*A54^-5/4/PI()/$N$5^4*EXP((-1/PI())*(2*PI()/$N$5)^4*A54^-4)) -> 17.164383 | O54: =$B$4*(B54^2)*($D$48^2*(2*PI())^4*A54^-5/4/PI()/$O$5^4*EXP((-1/PI())*(2*PI()/$O$5)^4*A54^-4)) -> 1933.0364 | P54: =$B$4*(B54^2)*($D$48^2*(2*PI())^4*A54^-5/4/PI()/$P$5^4*EXP((-1/PI())*(2*PI()/$P$5)^4*A54^-4)) -> 51295.902 | Q54: =$B$4*(B54^2)*($D$48^2*(2*PI())^4*A54^-5/4/PI()/$Q$5^4*EXP((-1/PI())*(2*PI()/$Q$5)^4*A54^-4)) -> 519716.75 | R54: =$B$4*(B54^2)*($D$48^2*(2*PI())^4*A54^-5/4/PI()/$R$5^4*EXP((-1/PI())*(2*PI()/$R$5)^4*A54^-4)) -> 2729014.6 | S54: =$B$4*(B54^2)*($D$48^2*(2*PI())^4*A54^-5/4/PI()/$S$5^4*EXP((-1/PI())*(2*PI()/$S$5)^4*A54^-4)) -> 9061308.7
A55: =A11 -> 0.19375 | B55: =B11 -> 129388.19 | D55: =$B$4*(B55^2)*($D$48^2*(2*PI())^4*A55^-5/4/PI()/$D$5^4*EXP((-1/PI())*(2*PI()/$D$5)^4*A55^-4)) -> 0 | E55: =$B$4*(B55^2)*($D$48^2*(2*PI())^4*A55^-5/4/PI()/$E$5^4*EXP((-1/PI())*(2*PI()/$E$5)^4*A55^-4)) -> 0 | F55: =$B$4*(B55^2)*($D$48^2*(2*PI())^4*A55^-5/4/PI()/$F$5^4*EXP((-1/PI())*(2*PI()/$F$5)^4*A55^-4)) -> 4.424903e-156 | G55: =$B$4*(B55^2)*($D$48^2*(2*PI())^4*A55^-5/4/PI()/$G$5^4*EXP((-1/PI())*(2*PI()/$G$5)^4*A55^-4)) -> 6.1520522e-75 | H55: =$B$4*(B55^2)*($D$48^2*(2*PI())^4*A55^-5/4/PI()/$H$5^4*EXP((-1/PI())*(2*PI()/$H$5)^4*A55^-4)) -> 7.4128783e-38 | I55: =$B$4*(B55^2)*($D$48^2*(2*PI())^4*A55^-5/4/PI()/$I$5^4*EXP((-1/PI())*(2*PI()/$I$5)^4*A55^-4)) -> 4.8392158e-19 | J55: =$B$4*(B55^2)*($D$48^2*(2*PI())^4*A55^-5/4/PI()/$J$5^4*EXP((-1/PI())*(2*PI()/$J$5)^4*A55^-4)) -> 1.0227981e-08 | K55: =$B$4*(B55^2)*($D$48^2*(2*PI())^4*A55^-5/4/PI()/$K$5^4*EXP((-1/PI())*(2*PI()/$K$5)^4*A55^-4)) -> 0.010681298 | L55: =$B$4*(B55^2)*($D$48^2*(2*PI())^4*A55^-5/4/PI()/$L$5^4*EXP((-1/PI())*(2*PI()/$L$5)^4*A55^-4)) -> 50.982741 | M55: =$B$4*(B55^2)*($D$48^2*(2*PI())^4*A55^-5/4/PI()/$M$5^4*EXP((-1/PI())*(2*PI()/$M$5)^4*A55^-4)) -> 11009.841 | N55: =$B$4*(B55^2)*($D$48^2*(2*PI())^4*A55^-5/4/PI()/$N$5^4*EXP((-1/PI())*(2*PI()/$N$5)^4*A55^-4)) -> 369367.62 | O55: =$B$4*(B55^2)*($D$48^2*(2*PI())^4*A55^-5/4/PI()/$O$5^4*EXP((-1/PI())*(2*PI()/$O$5)^4*A55^-4)) -> 3870093.2 | P55: =$B$4*(B55^2)*($D$48^2*(2*PI())^4*A55^-5/4/PI()/$P$5^4*EXP((-1/PI())*(2*PI()/$P$5)^4*A55^-4)) -> 19130051 | Q55: =$B$4*(B55^2)*($D$48^2*(2*PI())^4*A55^-5/4/PI()/$Q$5^4*EXP((-1/PI())*(2*PI()/$Q$5)^4*A55^-4)) -> 57438435 | R55: =$B$4*(B55^2)*($D$48^2*(2*PI())^4*A55^-5/4/PI()/$R$5^4*EXP((-1/PI())*(2*PI()/$R$5)^4*A55^-4)) -> 1.2290826e+08 | S55: =$B$4*(B55^2)*($D$48^2*(2*PI())^4*A55^-5/4/PI()/$S$5^4*EXP((-1/PI())*(2*PI()/$S$5)^4*A55^-4)) -> 2.0794782e+08
A56: =A12 -> 0.2225 | B56: =B12 -> 216758.56 | D56: =$B$4*(B56^2)*($D$48^2*(2*PI())^4*A56^-5/4/PI()/$D$5^4*EXP((-1/PI())*(2*PI()/$D$5)^4*A56^-4)) -> 0 | E56: =$B$4*(B56^2)*($D$48^2*(2*PI())^4*A56^-5/4/PI()/$E$5^4*EXP((-1/PI())*(2*PI()/$E$5)^4*A56^-4)) -> 7.0309631e-203 | F56: =$B$4*(B56^2)*($D$48^2*(2*PI())^4*A56^-5/4/PI()/$F$5^4*EXP((-1/PI())*(2*PI()/$F$5)^4*A56^-4)) -> 6.4449696e-85 | G56: =$B$4*(B56^2)*($D$48^2*(2*PI())^4*A56^-5/4/PI()/$G$5^4*EXP((-1/PI())*(2*PI()/$G$5)^4*A56^-4)) -> 2.1923298e-38 | H56: =$B$4*(B56^2)*($D$48^2*(2*PI())^4*A56^-5/4/PI()/$H$5^4*EXP((-1/PI())*(2*PI()/$H$5)^4*A56^-4)) -> 3.5955844e-17 | I56: =$B$4*(B56^2)*($D$48^2*(2*PI())^4*A56^-5/4/PI()/$I$5^4*EXP((-1/PI())*(2*PI()/$I$5)^4*A56^-4)) -> 1.9113223e-06 | J56: =$B$4*(B56^2)*($D$48^2*(2*PI())^4*A56^-5/4/PI()/$J$5^4*EXP((-1/PI())*(2*PI()/$J$5)^4*A56^-4)) -> 1.3671189 | K56: =$B$4*(B56^2)*($D$48^2*(2*PI())^4*A56^-5/4/PI()/$K$5^4*EXP((-1/PI())*(2*PI()/$K$5)^4*A56^-4)) -> 3330.9762 | L56: =$B$4*(B56^2)*($D$48^2*(2*PI())^4*A56^-5/4/PI()/$L$5^4*EXP((-1/PI())*(2*PI()/$L$5)^4*A56^-4)) -> 372057.05 | M56: =$B$4*(B56^2)*($D$48^2*(2*PI())^4*A56^-5/4/PI()/$M$5^4*EXP((-1/PI())*(2*PI()/$M$5)^4*A56^-4)) -> 7099626.2 | N56: =$B$4*(B56^2)*($D$48^2*(2*PI())^4*A56^-5/4/PI()/$N$5^4*EXP((-1/PI())*(2*PI()/$N$5)^4*A56^-4)) -> 46949778 | O56: =$B$4*(B56^2)*($D$48^2*(2*PI())^4*A56^-5/4/PI()/$O$5^4*EXP((-1/PI())*(2*PI()/$O$5)^4*A56^-4)) -> 1.6050717e+08 | P56: =$B$4*(B56^2)*($D$48^2*(2*PI())^4*A56^-5/4/PI()/$P$5^4*EXP((-1/PI())*(2*PI()/$P$5)^4*A56^-4)) -> 3.5915385e+08 | Q56: =$B$4*(B56^2)*($D$48^2*(2*PI())^4*A56^-5/4/PI()/$Q$5^4*EXP((-1/PI())*(2*PI()/$Q$5)^4*A56^-4)) -> 6.0765921e+08 | R56: =$B$4*(B56^2)*($D$48^2*(2*PI())^4*A56^-5/4/PI()/$R$5^4*EXP((-1/PI())*(2*PI()/$R$5)^4*A56^-4)) -> 8.5147845e+08 | S56: =$B$4*(B56^2)*($D$48^2*(2*PI())^4*A56^-5/4/PI()/$S$5^4*EXP((-1/PI())*(2*PI()/$S$5)^4*A56^-4)) -> 1.0482189e+09
A57: =A13 -> 0.25125 | B57: =B13 -> 331473.86 | D57: =$B$4*(B57^2)*($D$48^2*(2*PI())^4*A57^-5/4/PI()/$D$5^4*EXP((-1/PI())*(2*PI()/$D$5)^4*A57^-4)) -> 0 | E57: =$B$4*(B57^2)*($D$48^2*(2*PI())^4*A57^-5/4/PI()/$E$5^4*EXP((-1/PI())*(2*PI()/$E$5)^4*A57^-4)) -> 3.0340157e-120 | F57: =$B$4*(B57^2)*($D$48^2*(2*PI())^4*A57^-5/4/PI()/$F$5^4*EXP((-1/PI())*(2*PI()/$F$5)^4*A57^-4)) -> 7.9072476e-48 | G57: =$B$4*(B57^2)*($D$48^2*(2*PI())^4*A57^-5/4/PI()/$G$5^4*EXP((-1/PI())*(2*PI()/$G$5)^4*A57^-4)) -> 2.5389475e-19 | H57: =$B$4*(B57^2)*($D$48^2*(2*PI())^4*A57^-5/4/PI()/$H$5^4*EXP((-1/PI())*(2*PI()/$H$5)^4*A57^-4)) -> 2.2736056e-06 | I57: =$B$4*(B57^2)*($D$48^2*(2*PI())^4*A57^-5/4/PI()/$I$5^4*EXP((-1/PI())*(2*PI()/$I$5)^4*A57^-4)) -> 7.4053687 | J57: =$B$4*(B57^2)*($D$48^2*(2*PI())^4*A57^-5/4/PI()/$J$5^4*EXP((-1/PI())*(2*PI()/$J$5)^4*A57^-4)) -> 24879.116 | K57: =$B$4*(B57^2)*($D$48^2*(2*PI())^4*A57^-5/4/PI()/$K$5^4*EXP((-1/PI())*(2*PI()/$K$5)^4*A57^-4)) -> 2581443.3 | L57: =$B$4*(B57^2)*($D$48^2*(2*PI())^4*A57^-5/4/PI()/$L$5^4*EXP((-1/PI())*(2*PI()/$L$5)^4*A57^-4)) -> 40796919 | M57: =$B$4*(B57^2)*($D$48^2*(2*PI())^4*A57^-5/4/PI()/$M$5^4*EXP((-1/PI())*(2*PI()/$M$5)^4*A57^-4)) -> 2.2003273e+08 | N57: =$B$4*(B57^2)*($D$48^2*(2*PI())^4*A57^-5/4/PI()/$N$5^4*EXP((-1/PI())*(2*PI()/$N$5)^4*A57^-4)) -> 6.2457909e+08 | O57: =$B$4*(B57^2)*($D$48^2*(2*PI())^4*A57^-5/4/PI()/$O$5^4*EXP((-1/PI())*(2*PI()/$O$5)^4*A57^-4)) -> 1.1916218e+09 | P57: =$B$4*(B57^2)*($D$48^2*(2*PI())^4*A57^-5/4/PI()/$P$5^4*EXP((-1/PI())*(2*PI()/$P$5)^4*A57^-4)) -> 1.7646818e+09 | Q57: =$B$4*(B57^2)*($D$48^2*(2*PI())^4*A57^-5/4/PI()/$Q$5^4*EXP((-1/PI())*(2*PI()/$Q$5)^4*A57^-4)) -> 2.2147017e+09 | R57: =$B$4*(B57^2)*($D$48^2*(2*PI())^4*A57^-5/4/PI()/$R$5^4*EXP((-1/PI())*(2*PI()/$R$5)^4*A57^-4)) -> 2.4892874e+09 | S57: =$B$4*(B57^2)*($D$48^2*(2*PI())^4*A57^-5/4/PI()/$S$5^4*EXP((-1/PI())*(2*PI()/$S$5)^4*A57^-4)) -> 2.5967839e+09
A58: =A14 -> 0.28 | B58: =B14 -> 472200.19 | D58: =$B$4*(B58^2)*($D$48^2*(2*PI())^4*A58^-5/4/PI()/$D$5^4*EXP((-1/PI())*(2*PI()/$D$5)^4*A58^-4)) -> 1.7906645e-221 | E58: =$B$4*(B58^2)*($D$48^2*(2*PI())^4*A58^-5/4/PI()/$E$5^4*EXP((-1/PI())*(2*PI()/$E$5)^4*A58^-4)) -> 8.3660675e-74 | F58: =$B$4*(B58^2)*($D$48^2*(2*PI())^4*A58^-5/4/PI()/$F$5^4*EXP((-1/PI())*(2*PI()/$F$5)^4*A58^-4)) -> 5.6100763e-27 | G58: =$B$4*(B58^2)*($D$48^2*(2*PI())^4*A58^-5/4/PI()/$G$5^4*EXP((-1/PI())*(2*PI()/$G$5)^4*A58^-4)) -> 1.3441423e-08 | H58: =$B$4*(B58^2)*($D$48^2*(2*PI())^4*A58^-5/4/PI()/$H$5^4*EXP((-1/PI())*(2*PI()/$H$5)^4*A58^-4)) -> 2.7425525 | I58: =$B$4*(B58^2)*($D$48^2*(2*PI())^4*A58^-5/4/PI()/$I$5^4*EXP((-1/PI())*(2*PI()/$I$5)^4*A58^-4)) -> 38380.921 | J58: =$B$4*(B58^2)*($D$48^2*(2*PI())^4*A58^-5/4/PI()/$J$5^4*EXP((-1/PI())*(2*PI()/$J$5)^4*A58^-4)) -> 6343699.9 | K58: =$B$4*(B58^2)*($D$48^2*(2*PI())^4*A58^-5/4/PI()/$K$5^4*EXP((-1/PI())*(2*PI()/$K$5)^4*A58^-4)) -> 1.1174769e+08 | L58: =$B$4*(B58^2)*($D$48^2*(2*PI())^4*A58^-5/4/PI()/$L$5^4*EXP((-1/PI())*(2*PI()/$L$5)^4*A58^-4)) -> 5.8864009e+08 | M58: =$B$4*(B58^2)*($D$48^2*(2*PI())^4*A58^-5/4/PI()/$M$5^4*EXP((-1/PI())*(2*PI()/$M$5)^4*A58^-4)) -> 1.5609625e+09 | N58: =$B$4*(B58^2)*($D$48^2*(2*PI())^4*A58^-5/4/PI()/$N$5^4*EXP((-1/PI())*(2*PI()/$N$5)^4*A58^-4)) -> 2.7550588e+09 | O58: =$B$4*(B58^2)*($D$48^2*(2*PI())^4*A58^-5/4/PI()/$O$5^4*EXP((-1/PI())*(2*PI()/$O$5)^4*A58^-4)) -> 3.7875891e+09 | P58: =$B$4*(B58^2)*($D$48^2*(2*PI())^4*A58^-5/4/PI()/$P$5^4*EXP((-1/PI())*(2*PI()/$P$5)^4*A58^-4)) -> 4.4481244e+09 | Q58: =$B$4*(B58^2)*($D$48^2*(2*PI())^4*A58^-5/4/PI()/$Q$5^4*EXP((-1/PI())*(2*PI()/$Q$5)^4*A58^-4)) -> 4.7199584e+09 | R58: =$B$4*(B58^2)*($D$48^2*(2*PI())^4*A58^-5/4/PI()/$R$5^4*EXP((-1/PI())*(2*PI()/$R$5)^4*A58^-4)) -> 4.6870536e+09 | S58: =$B$4*(B58^2)*($D$48^2*(2*PI())^4*A58^-5/4/PI()/$S$5^4*EXP((-1/PI())*(2*PI()/$S$5)^4*A58^-4)) -> 4.4550719e+09
A59: =A15 -> 0.30875 | B59: =B15 -> 627599.4 | D59: =$B$4*(B59^2)*($D$48^2*(2*PI())^4*A59^-5/4/PI()/$D$5^4*EXP((-1/PI())*(2*PI()/$D$5)^4*A59^-4)) -> 7.5259013e-146 | E59: =$B$4*(B59^2)*($D$48^2*(2*PI())^4*A59^-5/4/PI()/$E$5^4*EXP((-1/PI())*(2*PI()/$E$5)^4*A59^-4)) -> 4.1599596e-46 | F59: =$B$4*(B59^2)*($D$48^2*(2*PI())^4*A59^-5/4/PI()/$F$5^4*EXP((-1/PI())*(2*PI()/$F$5)^4*A59^-4)) -> 1.5126538e-14 | G59: =$B$4*(B59^2)*($D$48^2*(2*PI())^4*A59^-5/4/PI()/$G$5^4*EXP((-1/PI())*(2*PI()/$G$5)^4*A59^-4)) -> 0.032940265 | H59: =$B$4*(B59^2)*($D$48^2*(2*PI())^4*A59^-5/4/PI()/$H$5^4*EXP((-1/PI())*(2*PI()/$H$5)^4*A59^-4)) -> 11428.238 | I59: =$B$4*(B59^2)*($D$48^2*(2*PI())^4*A59^-5/4/PI()/$I$5^4*EXP((-1/PI())*(2*PI()/$I$5)^4*A59^-4)) -> 6193710 | J59: =$B$4*(B59^2)*($D$48^2*(2*PI())^4*A59^-5/4/PI()/$J$5^4*EXP((-1/PI())*(2*PI()/$J$5)^4*A59^-4)) -> 1.6976051e+08 | K59: =$B$4*(B59^2)*($D$48^2*(2*PI())^4*A59^-5/4/PI()/$K$5^4*EXP((-1/PI())*(2*PI()/$K$5)^4*A59^-4)) -> 1.0382457e+09 | L59: =$B$4*(B59^2)*($D$48^2*(2*PI())^4*A59^-5/4/PI()/$L$5^4*EXP((-1/PI())*(2*PI()/$L$5)^4*A59^-4)) -> 2.8396124e+09 | M59: =$B$4*(B59^2)*($D$48^2*(2*PI())^4*A59^-5/4/PI()/$M$5^4*EXP((-1/PI())*(2*PI()/$M$5)^4*A59^-4)) -> 4.9302716e+09 | N59: =$B$4*(B59^2)*($D$48^2*(2*PI())^4*A59^-5/4/PI()/$N$5^4*EXP((-1/PI())*(2*PI()/$N$5)^4*A59^-4)) -> 6.5539239e+09 | O59: =$B$4*(B59^2)*($D$48^2*(2*PI())^4*A59^-5/4/PI()/$O$5^4*EXP((-1/PI())*(2*PI()/$O$5)^4*A59^-4)) -> 7.4102195e+09 | P59: =$B$4*(B59^2)*($D$48^2*(2*PI())^4*A59^-5/4/PI()/$P$5^4*EXP((-1/PI())*(2*PI()/$P$5)^4*A59^-4)) -> 7.5781445e+09 | Q59: =$B$4*(B59^2)*($D$48^2*(2*PI())^4*A59^-5/4/PI()/$Q$5^4*EXP((-1/PI())*(2*PI()/$Q$5)^4*A59^-4)) -> 7.2751519e+09 | R59: =$B$4*(B59^2)*($D$48^2*(2*PI())^4*A59^-5/4/PI()/$R$5^4*EXP((-1/PI())*(2*PI()/$R$5)^4*A59^-4)) -> 6.7098044e+09 | S59: =$B$4*(B59^2)*($D$48^2*(2*PI())^4*A59^-5/4/PI()/$S$5^4*EXP((-1/PI())*(2*PI()/$S$5)^4*A59^-4)) -> 6.0333696e+09
A60: =A16 -> 0.3375 | B60: =B16 -> 782998.61 | D60: =$B$4*(B60^2)*($D$48^2*(2*PI())^4*A60^-5/4/PI()/$D$5^4*EXP((-1/PI())*(2*PI()/$D$5)^4*A60^-4)) -> 1.6414977e-98 | E60: =$B$4*(B60^2)*($D$48^2*(2*PI())^4*A60^-5/4/PI()/$E$5^4*EXP((-1/PI())*(2*PI()/$E$5)^4*A60^-4)) -> 8.7487931e-29 | F60: =$B$4*(B60^2)*($D$48^2*(2*PI())^4*A60^-5/4/PI()/$F$5^4*EXP((-1/PI())*(2*PI()/$F$5)^4*A60^-4)) -> 8.74779e-07 | G60: =$B$4*(B60^2)*($D$48^2*(2*PI())^4*A60^-5/4/PI()/$G$5^4*EXP((-1/PI())*(2*PI()/$G$5)^4*A60^-4)) -> 313.47838 | H60: =$B$4*(B60^2)*($D$48^2*(2*PI())^4*A60^-5/4/PI()/$H$5^4*EXP((-1/PI())*(2*PI()/$H$5)^4*A60^-4)) -> 2004459.4 | I60: =$B$4*(B60^2)*($D$48^2*(2*PI())^4*A60^-5/4/PI()/$I$5^4*EXP((-1/PI())*(2*PI()/$I$5)^4*A60^-4)) -> 1.4179635e+08 | J60: =$B$4*(B60^2)*($D$48^2*(2*PI())^4*A60^-5/4/PI()/$J$5^4*EXP((-1/PI())*(2*PI()/$J$5)^4*A60^-4)) -> 1.2613533e+09 | K60: =$B$4*(B60^2)*($D$48^2*(2*PI())^4*A60^-5/4/PI()/$K$5^4*EXP((-1/PI())*(2*PI()/$K$5)^4*A60^-4)) -> 3.977093e+09 | L60: =$B$4*(B60^2)*($D$48^2*(2*PI())^4*A60^-5/4/PI()/$L$5^4*EXP((-1/PI())*(2*PI()/$L$5)^4*A60^-4)) -> 7.2152585e+09 | M60: =$B$4*(B60^2)*($D$48^2*(2*PI())^4*A60^-5/4/PI()/$M$5^4*EXP((-1/PI())*(2*PI()/$M$5)^4*A60^-4)) -> 9.6088413e+09 | N60: =$B$4*(B60^2)*($D$48^2*(2*PI())^4*A60^-5/4/PI()/$N$5^4*EXP((-1/PI())*(2*PI()/$N$5)^4*A60^-4)) -> 1.0695505e+10 | O60: =$B$4*(B60^2)*($D$48^2*(2*PI())^4*A60^-5/4/PI()/$O$5^4*EXP((-1/PI())*(2*PI()/$O$5)^4*A60^-4)) -> 1.0699368e+10 | P60: =$B$4*(B60^2)*($D$48^2*(2*PI())^4*A60^-5/4/PI()/$P$5^4*EXP((-1/PI())*(2*PI()/$P$5)^4*A60^-4)) -> 1.0033709e+10 | Q60: =$B$4*(B60^2)*($D$48^2*(2*PI())^4*A60^-5/4/PI()/$Q$5^4*EXP((-1/PI())*(2*PI()/$Q$5)^4*A60^-4)) -> 9.0470837e+09 | R60: =$B$4*(B60^2)*($D$48^2*(2*PI())^4*A60^-5/4/PI()/$R$5^4*EXP((-1/PI())*(2*PI()/$R$5)^4*A60^-4)) -> 7.9666645e+09 | S60: =$B$4*(B60^2)*($D$48^2*(2*PI())^4*A60^-5/4/PI()/$S$5^4*EXP((-1/PI())*(2*PI()/$S$5)^4*A60^-4)) -> 6.9187913e+09
A61: =A17 -> 0.36625 | B61: =B17 -> 915054.6 | D61: =$B$4*(B61^2)*($D$48^2*(2*PI())^4*A61^-5/4/PI()/$D$5^4*EXP((-1/PI())*(2*PI()/$D$5)^4*A61^-4)) -> 1.0911548e-67 | E61: =$B$4*(B61^2)*($D$48^2*(2*PI())^4*A61^-5/4/PI()/$E$5^4*EXP((-1/PI())*(2*PI()/$E$5)^4*A61^-4)) -> 1.5659636e-17 | F61: =$B$4*(B61^2)*($D$48^2*(2*PI())^4*A61^-5/4/PI()/$F$5^4*EXP((-1/PI())*(2*PI()/$F$5)^4*A61^-4)) -> 0.091477819 | G61: =$B$4*(B61^2)*($D$48^2*(2*PI())^4*A61^-5/4/PI()/$G$5^4*EXP((-1/PI())*(2*PI()/$G$5)^4*A61^-4)) -> 111874.29 | H61: =$B$4*(B61^2)*($D$48^2*(2*PI())^4*A61^-5/4/PI()/$H$5^4*EXP((-1/PI())*(2*PI()/$H$5)^4*A61^-4)) -> 52927273 | I61: =$B$4*(B61^2)*($D$48^2*(2*PI())^4*A61^-5/4/PI()/$I$5^4*EXP((-1/PI())*(2*PI()/$I$5)^4*A61^-4)) -> 9.9264982e+08 | J61: =$B$4*(B61^2)*($D$48^2*(2*PI())^4*A61^-5/4/PI()/$J$5^4*EXP((-1/PI())*(2*PI()/$J$5)^4*A61^-4)) -> 4.2396925e+09 | K61: =$B$4*(B61^2)*($D$48^2*(2*PI())^4*A61^-5/4/PI()/$K$5^4*EXP((-1/PI())*(2*PI()/$K$5)^4*A61^-4)) -> 8.6789129e+09 | L61: =$B$4*(B61^2)*($D$48^2*(2*PI())^4*A61^-5/4/PI()/$L$5^4*EXP((-1/PI())*(2*PI()/$L$5)^4*A61^-4)) -> 1.2048157e+10 | M61: =$B$4*(B61^2)*($D$48^2*(2*PI())^4*A61^-5/4/PI()/$M$5^4*EXP((-1/PI())*(2*PI()/$M$5)^4*A61^-4)) -> 1.3496964e+10 | N61: =$B$4*(B61^2)*($D$48^2*(2*PI())^4*A61^-5/4/PI()/$N$5^4*EXP((-1/PI())*(2*PI()/$N$5)^4*A61^-4)) -> 1.3381298e+10 | O61: =$B$4*(B61^2)*($D$48^2*(2*PI())^4*A61^-5/4/PI()/$O$5^4*EXP((-1/PI())*(2*PI()/$O$5)^4*A61^-4)) -> 1.2359113e+10 | P61: =$B$4*(B61^2)*($D$48^2*(2*PI())^4*A61^-5/4/PI()/$P$5^4*EXP((-1/PI())*(2*PI()/$P$5)^4*A61^-4)) -> 1.0953616e+10 | Q61: =$B$4*(B61^2)*($D$48^2*(2*PI())^4*A61^-5/4/PI()/$Q$5^4*EXP((-1/PI())*(2*PI()/$Q$5)^4*A61^-4)) -> 9.4809053e+09 | R61: =$B$4*(B61^2)*($D$48^2*(2*PI())^4*A61^-5/4/PI()/$R$5^4*EXP((-1/PI())*(2*PI()/$R$5)^4*A61^-4)) -> 8.1005209e+09 | S61: =$B$4*(B61^2)*($D$48^2*(2*PI())^4*A61^-5/4/PI()/$S$5^4*EXP((-1/PI())*(2*PI()/$S$5)^4*A61^-4)) -> 6.8773965e+09
