Workbook

Sheet Wave spectrum(mo_sample)
A1: Hs | B1: 1
A2: Tz | B2: 3.5
A3: w0 | B3: Wave spetrum | C3: RAO^2 | D3: Respone spectrum | E3: Mo
A4: 0.05 | B4: =$B$1^2*(2*PI())^4*A4^-5/4/PI()/$B$2^4*EXP((-1/PI())*(2*PI()/$B$2)^4*A4^-4) -> 0 | C4: =VBM_RAO!D6^2 -> 2.8561e-06 | D4: =B4*C4 -> 0 | E4: =D4*(A5-A4) -> 0
A5: 0.07875 | B5: =$B$1^2*(2*PI())^4*A5^-5/4/PI()/$B$2^4*EXP((-1/PI())*(2*PI()/$B$2)^4*A5^-4) -> 0 | C5: =VBM_RAO!D7^2 -> 1.74724e-05 | D5: =B5*C5 -> 0 | E5: =D5*(A6-A5) -> 0
A6: 0.1075 | B6: =$B$1^2*(2*PI())^4*A6^-5/4/PI()/$B$2^4*EXP((-1/PI())*(2*PI()/$B$2)^4*A6^-4) -> 0 | C6: =VBM_RAO!D8^2 -> 6.60969e-05 | D6: =B6*C6 -> 0 | E6: =D6*(A7-A6) -> 0
A7: 0.13625 | B7: =$B$1^2*(2*PI())^4*A7^-5/4/PI()/$B$2^4*EXP((-1/PI())*(2*PI()/$B$2)^4*A7^-4) -> 0 | C7: =VBM_RAO!D9^2 -> 0.0001478656 | D7: =B7*C7 -> 0 | E7: =D7*(A8-A7) -> 0
A8: 0.165 | B8: =$B$1^2*(2*PI())^4*A8^-5/4/PI()/$B$2^4*EXP((-1/PI())*(2*PI()/$B$2)^4*A8^-4) -> 0 | C8: =VBM_RAO!D10^2 -> 0.0001846881 | D8: =B8*C8 -> 0 | E8: =D8*(A9-A8) -> 0
A9: 0.19375 | B9: =$B$1^2*(2*PI())^4*A9^-5/4/PI()/$B$2^4*EXP((-1/PI())*(2*PI()/$B$2)^4*A9^-4) -> 0 | C9: =VBM_RAO!D11^2 -> 0.0001026169 | D9: =B9*C9 -> 0 | E9: =D9*(A10-A9) -> 0
A10: 0.2225 | B10: =$B$1^2*(2*PI())^4*A10^-5/4/PI()/$B$2^4*EXP((-1/PI())*(2*PI()/$B$2)^4*A10^-4) -> 0 | C10: =VBM_RAO!D12^2 -> 8.4681e-06 | D10: =B10*C10 -> 0 | E10: =D10*(A11-A10) -> 0
A11: 0.25125 | B11: =$B$1^2*(2*PI())^4*A11^-5/4/PI()/$B$2^4*EXP((-1/PI())*(2*PI()/$B$2)^4*A11^-4) -> 0 | C11: =VBM_RAO!D13^2 -> 1.56816e-05 | D11: =B11*C11 -> 0 | E11: =D11*(A12-A11) -> 0
A12: 0.28 | B12: =$B$1^2*(2*PI())^4*A12^-5/4/PI()/$B$2^4*EXP((-1/PI())*(2*PI()/$B$2)^4*A12^-4) -> 1.2414852e-231 | C12: =VBM_RAO!D14^2 -> 2.16225e-05 | D12: =B12*C12 -> 2.6844013e-236 | E12: =D12*(A13-A12) -> 7.7176538e-238
A13: 0.30875 | B13: =$B$1^2*(2*PI())^4*A13^-5/4/PI()/$B$2^4*EXP((-1/PI())*(2*PI()/$B$2)^4*A13^-4) -> 2.9537457e-156 | C13: =VBM_RAO!D15^2 -> 6.5025e-06 | D13: =B13*C13 -> 1.9206732e-161 | E13: =D13*(A14-A13) -> 5.5219354e-163
A14: 0.3375 | B14: =$B$1^2*(2*PI())^4*A14^-5/4/PI()/$B$2^4*EXP((-1/PI())*(2*PI()/$B$2)^4*A14^-4) -> 4.1390238e-109 | C14: =VBM_RAO!D16^2 -> 1.03041e-05 | D14: =B14*C14 -> 4.2648915e-114 | E14: =D14*(A15-A14) -> 1.2261563e-115
A15: 0.36625 | B15: =$B$1^2*(2*PI())^4*A15^-5/4/PI()/$B$2^4*EXP((-1/PI())*(2*PI()/$B$2)^4*A15^-4) -> 2.0145219e-78 | C15: =VBM_RAO!D17^2 -> 5.1984e-06 | D15: =B15*C15 -> 1.0472291e-83 | E15: =D15*(A16-A15) -> 3.0107836e-85
... A19: 0.48125 | B19: =$B$1^2*(2*PI())^4*A19^-5/4/PI()/$B$2^4*EXP((-1/PI())*(2*PI()/$B$2)^4*A19^-4) -> 5.4757209e-26 | C19: =VBM_RAO!D21^2 -> 2.1904e-06 | D19: =B19*C19 -> 1.1994019e-31 | E19: =D19*(A20-A19) -> 3.4482805e-33
A20: 0.51 | B20: =$B$1^2*(2*PI())^4*A20^-5/4/PI()/$B$2^4*EXP((-1/PI())*(2*PI()/$B$2)^4*A20^-4) -> 1.43439e-20 | C20: =VBM_RAO!D22^2 -> 1.2769e-06 | D20: =B20*C20 -> 1.8315725e-26 | E20: =D20*(A21-A20) -> 5.2657711e-28 | Q20: World wide wave scatter diagram
A21: 0.53875 | B21: =$B$1^2*(2*PI())^4*A21^-5/4/PI()/$B$2^4*EXP((-1/PI())*(2*PI()/$B$2)^4*A21^-4) -> 1.6513096e-16 | C21: =VBM_RAO!D23^2 -> 1.0609e-06 | D21: =B21*C21 -> 1.7518744e-22 | E21: =D21*(A22-A21) -> 5.0366389e-24 | R21: 3.5 | S21: 4.5 | T21: 5.5 | U21: 6.5 | V21: 7.5 | W21: 8.5 | X21: 9.5 | Y21: 10.5 | Z21: 11.5 | AA21: 12.5 | AB21: 13.5 | AC21: 14.5 | AD21: 15.5 | AE21: 16.5 | AF21: 17.5
A22: 0.5675 | B22: =$B$1^2*(2*PI())^4*A22^-5/4/PI()/$B$2^4*EXP((-1/PI())*(2*PI()/$B$2)^4*A22^-4) -> 2.0173856e-13 | C22: =VBM_RAO!D24^2 -> 5.625e-07 | D22: =B22*C22 -> 1.1347794e-19 | E22: =D22*(A23-A22) -> 3.2624909e-21 | Q22: 1 | R22: 311 | S22: 2734 | T22: 6402 | U22: 7132 | V22: 5071 | W22: 2711 | X22: 1202 | Y22: 470 | Z22: 169 | AA22: 57 | AB22: 19 | AC22: 6 | AD22: 2 | AE22: 1 | AF22: 0
A23: 0.59625 | B23: =$B$1^2*(2*PI())^4*A23^-5/4/PI()/$B$2^4*EXP((-1/PI())*(2*PI()/$B$2)^4*A23^-4) -> 4.790285e-11 | C23: =VBM_RAO!D25^2 -> 1.764e-07 | D23: =B23*C23 -> 8.4500628e-18 | E23: =D23*(A24-A23) -> 2.4293931e-19 | Q23: 2 | R23: 20 | S23: 764 | T23: 4453 | U23: 8841 | V23: 9045 | W23: 6020 | X23: 3000 | Y23: 1225 | Z23: 435 | AA23: 140 | AB23: 42 | AC23: 12 | AD23: 3 | AE23: 1 | AF23: 0
A24: 0.625 | B24: =$B$1^2*(2*PI())^4*A24^-5/4/PI()/$B$2^4*EXP((-1/PI())*(2*PI()/$B$2)^4*A24^-4) -> 3.3763161e-09 | C24: =VBM_RAO!D26^2 -> 4.41e-08 | D24: =B24*C24 -> 1.4889554e-16 | E24: =D24*(A25-A24) -> 4.2807468e-18 | Q24: 3 | R24: 0 | S24: 57 | T24: 902 | U24: 3474 | V24: 5549 | W24: 4973 | X24: 3004 | Y24: 1377 | Z24: 518 | AA24: 169 | AB24: 50 | AC24: 14 | AD24: 4 | AE24: 1 | AF24: 0
A25: 0.65375 | B25: =$B$1^2*(2*PI())^4*A25^-5/4/PI()/$B$2^4*EXP((-1/PI())*(2*PI()/$B$2)^4*A25^-4) -> 9.5489329e-08 | C25: =VBM_RAO!D27^2 -> 2.89e-08 | D25: =B25*C25 -> 2.7596416e-15 | E25: =D25*(A26-A25) -> 7.9339696e-17 | Q25: 4 | R25: 0 | S25: 4 | T25: 150 | U25: 1007 | V25: 2401 | W25: 2881 | X25: 2156 | Y25: 1154 | Z25: 485 | AA25: 171 | AB25: 53 | AC25: 15 | AD25: 4 | AE25: 1 | AF25: 0
A26: 0.6825 | B26: =$B$1^2*(2*PI())^4*A26^-5/4/PI()/$B$2^4*EXP((-1/PI())*(2*PI()/$B$2)^4*A26^-4) -> 1.3476346e-06 | C26: =VBM_RAO!D28^2 -> 3.24e-08 | D26: =B26*C26 -> 4.366336e-14 | E26: =D26*(A27-A26) -> 1.2553216e-15 | Q26: 5 | R26: 0 | S26: 0 | T26: 25 | U26: 258 | V26: 859 | W26: 1338 | X26: 1230 | Y26: 776 | Z26: 372 | AA26: 146 | AB26: 49 | AC26: 15 | AD26: 4 | AE26: 1 | AF26: 0
A27: 0.71125 | B27: =$B$1^2*(2*PI())^4*A27^-5/4/PI()/$B$2^4*EXP((-1/PI())*(2*PI()/$B$2)^4*A27^-4) -> 1.1136319e-05 | C27: =VBM_RAO!D29^2 -> 2.89e-08 | D27: =B27*C27 -> 3.2183961e-13 | E27: =D27*(A28-A27) -> 9.2528888e-15 | Q27: 6 | R27: 0 | S27: 0 | T27: 4 | U27: 63 | V27: 277 | W27: 540 | X27: 597 | Y27: 440 | Z27: 240 | AA27: 105 | AB27: 39 | AC27: 13 | AD27: 4 | AE27: 1 | AF27: 0
A28: 0.74 | B28: =$B$1^2*(2*PI())^4*A28^-5/4/PI()/$B$2^4*EXP((-1/PI())*(2*PI()/$B$2)^4*A28^-4) -> 6.0683548e-05 | C28: =VBM_RAO!D30^2 -> 2.56e-08 | D28: =B28*C28 -> 1.5534988e-12 | E28: =D28*(A29-A28) -> 4.4663091e-14 | Q28: 7 | R28: 0 | S28: 0 | T28: 1 | U28: 15 | V28: 84 | W28: 198 | X28: 258 | Y28: 219 | Z28: 136 | AA28: 66 | AB28: 27 | AC28: 10 | AD28: 3 | AE28: 1 | AF28: 0
A29: 0.76875 | B29: =$B$1^2*(2*PI())^4*A29^-5/4/PI()/$B$2^4*EXP((-1/PI())*(2*PI()/$B$2)^4*A29^-4) -> 0.00023843556 | C29: =VBM_RAO!D31^2 -> 2.56e-08 | D29: =B29*C29 -> 6.1039502e-12 | E29: =D29*(A30-A29) -> 1.7548857e-13 | Q29: 8 | R29: 0 | S29: 0 | T29: 0 | U29: 4 | V29: 25 | W29: 69 | X29: 103 | Y29: 99 | Z29: 69 | AA29: 37 | AB29: 17 | AC29: 6 | AD29: 2 | AE29: 1 | AF29: 0
A30: 0.7975 | B30: =$B$1^2*(2*PI())^4*A30^-5/4/PI()/$B$2^4*EXP((-1/PI())*(2*PI()/$B$2)^4*A30^-4) -> 0.00072302131 | C30: =VBM_RAO!D32^2 -> 2.56e-08 | D30: =B30*C30 -> 1.8509345e-11 | E30: =D30*(A31-A30) -> 5.3214368e-13 | Q30: 9 | R30: 0 | S30: 0 | T30: 0 | U30: 1 | V30: 7 | W30: 23 | X30: 39 | Y30: 42 | Z30: 32 | AA30: 19 | AB30: 9 | AC30: 4 | AD30: 1 | AE30: 1 | AF30: 0
A31: 0.82625 | B31: =$B$1^2*(2*PI())^4*A31^-5/4/PI()/$B$2^4*EXP((-1/PI())*(2*PI()/$B$2)^4*A31^-4) -> 0.0017826919 | C31: =VBM_RAO!D33^2 -> 3.6e-09 | D31: =B31*C31 -> 6.4176907e-12 | E31: =D31*(A32-A31) -> 1.8450861e-13 | Q31: 10 | R31: 0 | S31: 0 | T31: 0 | U31: 0 | V31: 2 | W31: 7 | X31: 14 | Y31: 16 | Z31: 14 | AA31: 9 | AB31: 5 | AC31: 2 | AD31: 1 | AE31: 0 | AF31: 0
A32: 0.855 | B32: =$B$1^2*(2*PI())^4*A32^-5/4/PI()/$B$2^4*EXP((-1/PI())*(2*PI()/$B$2)^4*A32^-4) -> 0.003721505 | C32: =VBM_RAO!D34^2 -> 1.69e-08 | D32: =B32*C32 -> 6.2893435e-11 | E32: =D32*(A33-A32) -> 1.8081863e-12 | Q32: 11 | R32: 0 | S32: 0 | T32: 0 | U32: 0 | V32: 1 | W32: 2 | X32: 5 | Y32: 6 | Z32: 6 | AA32: 4 | AB32: 2 | AC32: 1 | AD32: 1 | AE32: 0 | AF32: 0
A33: 0.88375 | B33: =$B$1^2*(2*PI())^4*A33^-5/4/PI()/$B$2^4*EXP((-1/PI())*(2*PI()/$B$2)^4*A33^-4) -> 0.0067892262 | C33: =VBM_RAO!D35^2 -> 4.41e-08 | D33: =B33*C33 -> 2.9940487e-10 | E33: =D33*(A34-A33) -> 8.6078901e-12 | Q33: 12 | R33: 0 | S33: 0 | T33: 0 | U33: 0 | V33: 0 | W33: 1 | X33: 2 | Y33: 2 | Z33: 2 | AA33: 2 | AB33: 1 | AC33: 1 | AD33: 0 | AE33: 0 | AF33: 0
... A35: 0.94125 | B35: =$B$1^2*(2*PI())^4*A35^-5/4/PI()/$B$2^4*EXP((-1/PI())*(2*PI()/$B$2)^4*A35^-4) -> 0.016577156 | C35: =VBM_RAO!D37^2 -> 1.764e-07 | D35: =B35*C35 -> 2.9242103e-09 | E35: =D35*(A36-A35) -> 8.4071046e-11 | Q35: 14 | R35: 0 | S35: 0 | T35: 0 | U35: 0 | V35: 0 | W35: 0 | X35: 0 | Y35: 0 | Z35: 1 | AA35: 0 | AB35: 0 | AC35: 0 | AD35: 0 | AE35: 0 | AF35: 0
A36: 0.97 | B36: =$B$1^2*(2*PI())^4*A36^-5/4/PI()/$B$2^4*EXP((-1/PI())*(2*PI()/$B$2)^4*A36^-4) -> 0.0229926 | C36: =VBM_RAO!D38^2 -> 4.356e-07 | D36: =B36*C36 -> 1.0015577e-08 | E36: =D36*(A37-A36) -> 2.8794783e-10
A37: 0.99875 | B37: =$B$1^2*(2*PI())^4*A37^-5/4/PI()/$B$2^4*EXP((-1/PI())*(2*PI()/$B$2)^4*A37^-4) -> 0.029991112 | C37: =VBM_RAO!D39^2 -> 1.21e-06 | D37: =B37*C37 -> 3.6289245e-08 | E37: =D37*(A38-A37) -> 1.0433158e-09
A38: 1.0275 | B38: =$B$1^2*(2*PI())^4*A38^-5/4/PI()/$B$2^4*EXP((-1/PI())*(2*PI()/$B$2)^4*A38^-4) -> 0.03717183 | C38: =VBM_RAO!D40^2 -> 4.225e-07 | D38: =B38*C38 -> 1.5705098e-08 | E38: =D38*(A39-A38) -> 4.5152158e-10
A39: 1.05625 | B39: =$B$1^2*(2*PI())^4*A39^-5/4/PI()/$B$2^4*EXP((-1/PI())*(2*PI()/$B$2)^4*A39^-4) -> 0.04414801 | C39: =VBM_RAO!D41^2 -> 8.836e-07 | D39: =B39*C39 -> 3.9009182e-08 | E39: =D39*(A40-A39) -> 1.121514e-09
A40: 1.085 | B40: =$B$1^2*(2*PI())^4*A40^-5/4/PI()/$B$2^4*EXP((-1/PI())*(2*PI()/$B$2)^4*A40^-4) -> 0.050591962 | C40: =VBM_RAO!D42^2 -> 4.9e-07 | D40: =B40*C40 -> 2.4790061e-08 | E40: =D40*(A41-A40) -> 7.1271426e-10
A41: 1.11375 | B41: =$B$1^2*(2*PI())^4*A41^-5/4/PI()/$B$2^4*EXP((-1/PI())*(2*PI()/$B$2)^4*A41^-4) -> 0.056259141 | C41: =VBM_RAO!D43^2 -> 3.249e-07 | D41: =B41*C41 -> 1.8278595e-08 | E41: =D41*(A42-A41) -> 5.255096e-10
A42: 1.1425 | B42: =$B$1^2*(2*PI())^4*A42^-5/4/PI()/$B$2^4*EXP((-1/PI())*(2*PI()/$B$2)^4*A42^-4) -> 0.06099407 | C42: =VBM_RAO!D44^2 -> 3.844e-07 | D42: =B42*C42 -> 2.3446121e-08 | E42: =D42*(A43-A42) -> 6.7407597e-10
A43: 1.17125 | B43: =$B$1^2*(2*PI())^4*A43^-5/4/PI()/$B$2^4*EXP((-1/PI())*(2*PI()/$B$2)^4*A43^-4) -> 0.064723475 | C43: =VBM_RAO!D45^2 -> 1.681e-07 | D43: =B43*C43 -> 1.0880016e-08 | E43: =D43*(A44-A43) -> 3.1280046e-10
A44: 1.2 | B44: =$B$1^2*(2*PI())^4*A44^-5/4/PI()/$B$2^4*EXP((-1/PI())*(2*PI()/$B$2)^4*A44^-4) -> 0.067442195 | C44: =VBM_RAO!D46^2 -> 1.681e-07 | D44: =B44*C44 -> 1.1337033e-08 | E44: =D44*(A45-A44) -> 3.259397e-10
...

Sheet VBM_RAO
A1: 9 | B1: Vertical | C1: Bending | D1: Moment(14 | E1: Station)
A3: A. | B3: Non | C3: Dimensional | D3: Amplitude | E3: per | F3: Unit | G3: Wave | H3: Amplitude(/rho*g*L**2*B | I3: /a) | M3: 차원화(=RAO*rho*g*L^2*B)
B4: ****************************************************************************************************
B5: NO | C5: Wo(rad/sec) | D5: 0 | E5: 30 | F5: 60 | G5: 90 | H5: 120 | I5: 150 | J5: 180 | M5: 0 | N5: 30 | O5: 60 | P5: 90 | Q5: 120 | R5: 150 | S5: 180
B6: 1 | C6: 0.2 | D6: 0.00169 | E6: 0.00132 | F6: 0.00057 | G6: 0.00017 | H6: 0.00058 | I6: 0.00133 | J6: 0.0017 | L6: =C6 -> 0.2 | M6: =D6*1.024*9.81*286^2*48.2 -> 66932.15 | N6: =E6*1.024*9.81*286^2*48.2 -> 52278.365 | O6: =F6*1.024*9.81*286^2*48.2 -> 22574.749 | P6: =G6*1.024*9.81*286^2*48.2 -> 6732.8198 | Q6: =H6*1.024*9.81*286^2*48.2 -> 22970.797 | R6: =I6*1.024*9.81*286^2*48.2 -> 52674.414 | S6: =J6*1.024*9.81*286^2*48.2 -> 67328.198
B7: 2 | C7: 0.26542 | D7: 0.00418 | E7: 0.00318 | F7: 0.00112 | G7: 2e-05 | H7: 0.00113 | I7: 0.00314 | J7: 0.0041 | L7: =C7 -> 0.26542 | M7: =D7*1.024*9.81*286^2*48.2 -> 165548.16 | N7: =E7*1.024*9.81*286^2*48.2 -> 125943.33 | O7: =F7*1.024*9.81*286^2*48.2 -> 44357.401 | P7: =G7*1.024*9.81*286^2*48.2 -> 792.09645 | Q7: =H7*1.024*9.81*286^2*48.2 -> 44753.449 | R7: =I7*1.024*9.81*286^2*48.2 -> 124359.14 | S7: =J7*1.024*9.81*286^2*48.2 -> 162379.77
B8: 3 | C8: 0.33083 | D8: 0.00813 | E8: 0.00625 | F8: 0.00215 | G8: 0.00011 | H8: 0.00211 | I8: 0.00598 | J8: 0.00774 | L8: =C8 -> 0.33083 | M8: =D8*1.024*9.81*286^2*48.2 -> 321987.2 | N8: =E8*1.024*9.81*286^2*48.2 -> 247530.14 | O8: =F8*1.024*9.81*286^2*48.2 -> 85150.368 | P8: =G8*1.024*9.81*286^2*48.2 -> 4356.5304 | Q8: =H8*1.024*9.81*286^2*48.2 -> 83566.175 | R8: =I8*1.024*9.81*286^2*48.2 -> 236836.84 | S8: =J8*1.024*9.81*286^2*48.2 -> 306541.32
B9: 4 | C9: 0.39625 | D9: 0.01216 | E9: 0.00966 | F9: 0.00356 | G9: 0.00016 | H9: 0.00364 | I9: 0.01036 | J9: 0.01318 | L9: =C9 -> 0.39625 | M9: =D9*1.024*9.81*286^2*48.2 -> 481594.64 | N9: =E9*1.024*9.81*286^2*48.2 -> 382582.58 | O9: =F9*1.024*9.81*286^2*48.2 -> 140993.17 | P9: =G9*1.024*9.81*286^2*48.2 -> 6336.7716 | Q9: =H9*1.024*9.81*286^2*48.2 -> 144161.55 | R9: =I9*1.024*9.81*286^2*48.2 -> 410305.96 | S9: =J9*1.024*9.81*286^2*48.2 -> 521991.56
B10: 5 | C10: 0.46167 | D10: 0.01359 | E10: 0.01151 | F10: 0.00511 | G10: 0.00011 | H10: 0.00651 | I10: 0.0157 | J10: 0.01821 | L10: =C10 -> 0.46167 | M10: =D10*1.024*9.81*286^2*48.2 -> 538229.53 | N10: =E10*1.024*9.81*286^2*48.2 -> 455851.5 | O10: =F10*1.024*9.81*286^2*48.2 -> 202380.64 | P10: =G10*1.024*9.81*286^2*48.2 -> 4356.5304 | Q10: =H10*1.024*9.81*286^2*48.2 -> 257827.39 | R10: =I10*1.024*9.81*286^2*48.2 -> 621795.71 | S10: =J10*1.024*9.81*286^2*48.2 -> 721203.81
B11: 6 | C11: 0.52708 | D11: 0.01013 | E11: 0.00992 | F11: 0.00673 | G11: 0.00031 | H11: 0.01029 | I11: 0.01751 | J11: 0.01759 | L11: =C11 -> 0.52708 | M11: =D11*1.024*9.81*286^2*48.2 -> 401196.85 | N11: =E11*1.024*9.81*286^2*48.2 -> 392879.84 | O11: =F11*1.024*9.81*286^2*48.2 -> 266540.45 | P11: =G11*1.024*9.81*286^2*48.2 -> 12277.495 | Q11: =H11*1.024*9.81*286^2*48.2 -> 407533.62 | R11: =I11*1.024*9.81*286^2*48.2 -> 693480.44 | S11: =J11*1.024*9.81*286^2*48.2 -> 696648.82
B12: 7 | C12: 0.5925 | D12: 0.00291 | E12: 0.00491 | F12: 0.00855 | G12: 0.00155 | H12: 0.01196 | I12: 0.01452 | J12: 0.01199 | L12: =C12 -> 0.5925 | M12: =D12*1.024*9.81*286^2*48.2 -> 115250.03 | N12: =E12*1.024*9.81*286^2*48.2 -> 194459.68 | O12: =F12*1.024*9.81*286^2*48.2 -> 338621.23 | P12: =G12*1.024*9.81*286^2*48.2 -> 61387.474 | Q12: =H12*1.024*9.81*286^2*48.2 -> 473673.67 | R12: =I12*1.024*9.81*286^2*48.2 -> 575062.02 | S12: =J12*1.024*9.81*286^2*48.2 -> 474861.82
B13: 8 | C13: 0.65792 | D13: 0.00396 | E13: 0.00271 | F13: 0.01056 | G13: 0.00373 | H13: 0.01104 | I13: 0.00848 | J13: 0.00522 | L13: =C13 -> 0.65792 | M13: =D13*1.024*9.81*286^2*48.2 -> 156835.1 | N13: =E13*1.024*9.81*286^2*48.2 -> 107329.07 | O13: =F13*1.024*9.81*286^2*48.2 -> 418226.92 | P13: =G13*1.024*9.81*286^2*48.2 -> 147725.99 | Q13: =H13*1.024*9.81*286^2*48.2 -> 437237.24 | R13: =I13*1.024*9.81*286^2*48.2 -> 335848.89 | S13: =J13*1.024*9.81*286^2*48.2 -> 206737.17
B14: 9 | C14: 0.72333 | D14: 0.00465 | E14: 0.00546 | F14: 0.01217 | G14: 0.00506 | H14: 0.00972 | I14: 0.00476 | J14: 0.00596 | L14: =C14 -> 0.72333 | M14: =D14*1.024*9.81*286^2*48.2 -> 184162.42 | N14: =E14*1.024*9.81*286^2*48.2 -> 216242.33 | O14: =F14*1.024*9.81*286^2*48.2 -> 481990.69 | P14: =G14*1.024*9.81*286^2*48.2 -> 200400.4 | Q14: =H14*1.024*9.81*286^2*48.2 -> 384958.87 | R14: =I14*1.024*9.81*286^2*48.2 -> 188518.95 | S14: =J14*1.024*9.81*286^2*48.2 -> 236044.74
B15: 10 | C15: 0.78875 | D15: 0.00255 | E15: 0.00409 | F15: 0.01206 | G15: 0.00515 | H15: 0.00767 | I15: 0.00513 | J15: 0.00374 | L15: =C15 -> 0.78875 | M15: =D15*1.024*9.81*286^2*48.2 -> 100992.3 | N15: =E15*1.024*9.81*286^2*48.2 -> 161983.72 | O15: =F15*1.024*9.81*286^2*48.2 -> 477634.16 | P15: =G15*1.024*9.81*286^2*48.2 -> 203964.83 | Q15: =H15*1.024*9.81*286^2*48.2 -> 303768.99 | R15: =I15*1.024*9.81*286^2*48.2 -> 203172.74 | S15: =J15*1.024*9.81*286^2*48.2 -> 148122.04
B16: 11 | C16: 0.85417 | D16: 0.00321 | E16: 0.00345 | F16: 0.00981 | G16: 0.00487 | H16: 0.00544 | I16: 0.00259 | J16: 0.00187 | L16: =C16 -> 0.85417 | M16: =D16*1.024*9.81*286^2*48.2 -> 127131.48 | N16: =E16*1.024*9.81*286^2*48.2 -> 136636.64 | O16: =F16*1.024*9.81*286^2*48.2 -> 388523.31 | P16: =G16*1.024*9.81*286^2*48.2 -> 192875.48 | Q16: =H16*1.024*9.81*286^2*48.2 -> 215450.23 | R16: =I16*1.024*9.81*286^2*48.2 -> 102576.49 | S16: =J16*1.024*9.81*286^2*48.2 -> 74061.018
B17: 12 | C17: 0.91958 | D17: 0.00228 | E17: 0.0037 | F17: 0.00578 | G17: 0.00443 | H17: 0.00501 | I17: 0.0026 | J17: 0.0017 | L17: =C17 -> 0.91958 | M17: =D17*1.024*9.81*286^2*48.2 -> 90298.995 | N17: =E17*1.024*9.81*286^2*48.2 -> 146537.84 | O17: =F17*1.024*9.81*286^2*48.2 -> 228915.87 | P17: =G17*1.024*9.81*286^2*48.2 -> 175449.36 | Q17: =H17*1.024*9.81*286^2*48.2 -> 198420.16 | R17: =I17*1.024*9.81*286^2*48.2 -> 102972.54 | S17: =J17*1.024*9.81*286^2*48.2 -> 67328.198
... B54: 49 | C54: 3.34 | D54: 0.00011 | E54: 0.00055 | F54: 0.0003 | G54: 0.00014 | H54: 0.00137 | I54: 0.00158 | J54: 0.00215 | L54: =C54 -> 3.34 | M54: =D54*1.024*9.81*286^2*48.2 -> 4356.5304 | N54: =E54*1.024*9.81*286^2*48.2 -> 21782.652 | O54: =F54*1.024*9.81*286^2*48.2 -> 11881.447 | P54: =G54*1.024*9.81*286^2*48.2 -> 5544.6751 | Q54: =H54*1.024*9.81*286^2*48.2 -> 54258.606 | R54: =I54*1.024*9.81*286^2*48.2 -> 62575.619 | S54: =J54*1.024*9.81*286^2*48.2 -> 85150.368

Sheet Short_VBM_0
B2: VBM_RAO
A3: dw | B3: =B4/2 -> 0.013889718
A4: w0 | B4: =A7-A6 -> 0.027779436 | C4: Hs | D4: 0.5
A5: w | B5: RAO(0) | C5: Tz | D5: 3.5 | E5: 4.5 | F5: 5.5 | G5: 6.5 | H5: 7.5 | I5: 8.5 | J5: 9.5 | K5: 10.5 | L5: 11.5 | M5: 12.5 | N5: 13.5 | O5: 14.5 | P5: 15.5 | Q5: 16.5 | R5: 17.5 | S5: 18.5
A6: 0.04934449 | B6: =VBM_RAO!M6 -> 66932.15 | D6: =$B$4*(B6^2)*($D$4^2*(2*PI())^4*A6^-5/4/PI()/$D$5^4*EXP((-1/PI())*(2*PI()/$D$5)^4*A6^-4)) -> 0 | E6: =$B$4*(B6^2)*($D$4^2*(2*PI())^4*A6^-5/4/PI()/$E$5^4*EXP((-1/PI())*(2*PI()/$E$5)^4*A6^-4)) -> 0 | F6: =$B$4*(B6^2)*($D$4^2*(2*PI())^4*A6^-5/4/PI()/$F$5^4*EXP((-1/PI())*(2*PI()/$F$5)^4*A6^-4)) -> 0 | G6: =$B$4*(B6^2)*($D$4^2*(2*PI())^4*A6^-5/4/PI()/$G$5^4*EXP((-1/PI())*(2*PI()/$G$5)^4*A6^-4)) -> 0 | H6: =$B$4*(B6^2)*($D$4^2*(2*PI())^4*A6^-5/4/PI()/$H$5^4*EXP((-1/PI())*(2*PI()/$H$5)^4*A6^-4)) -> 0 | I6: =$B$4*(B6^2)*($D$4^2*(2*PI())^4*A6^-5/4/PI()/$I$5^4*EXP((-1/PI())*(2*PI()/$I$5)^4*A6^-4)) -> 0 | J6: =$B$4*(B6^2)*($D$4^2*(2*PI())^4*A6^-5/4/PI()/$J$5^4*EXP((-1/PI())*(2*PI()/$J$5)^4*A6^-4)) -> 0 | K6: =$B$4*(B6^2)*($D$4^2*(2*PI())^4*A6^-5/4/PI()/$K$5^4*EXP((-1/PI())*(2*PI()/$K$5)^4*A6^-4)) -> 0 | L6: =$B$4*(B6^2)*($D$4^2*(2*PI())^4*A6^-5/4/PI()/$L$5^4*EXP((-1/PI())*(2*PI()/$L$5)^4*A6^-4)) -> 0 | M6: =$B$4*(B6^2)*($D$4^2*(2*PI())^4*A6^-5/4/PI()/$M$5^4*EXP((-1/PI())*(2*PI()/$M$5)^4*A6^-4)) -> 0 | N6: =$B$4*(B6^2)*($D$4^2*(2*PI())^4*A6^-5/4/PI()/$N$5^4*EXP((-1/PI())*(2*PI()/$N$5)^4*A6^-4)) -> 0 | O6: =$B$4*(B6^2)*($D$4^2*(2*PI())^4*A6^-5/4/PI()/$O$5^4*EXP((-1/PI())*(2*PI()/$O$5)^4*A6^-4)) -> 0 | P6: =$B$4*(B6^2)*($D$4^2*(2*PI())^4*A6^-5/4/PI()/$P$5^4*EXP((-1/PI())*(2*PI()/$P$5)^4*A6^-4)) -> 0 | Q6: =$B$4*(B6^2)*($D$4^2*(2*PI())^4*A6^-5/4/PI()/$Q$5^4*EXP((-1/PI())*(2*PI()/$Q$5)^4*A6^-4)) -> 0 | R6: =$B$4*(B6^2)*($D$4^2*(2*PI())^4*A6^-5/4/PI()/$R$5^4*EXP((-1/PI())*(2*PI()/$R$5)^4*A6^-4)) -> 0 | S6: =$B$4*(B6^2)*($D$4^2*(2*PI())^4*A6^-5/4/PI()/$S$5^4*EXP((-1/PI())*(2*PI()/$S$5)^4*A6^-4)) -> 6.3267069e-300
A7: 0.077123926 | B7: =VBM_RAO!M7 -> 165548.16 | D7: =$B$4*(B7^2)*($D$4^2*(2*PI())^4*A7^-5/4/PI()/$D$5^4*EXP((-1/PI())*(2*PI()/$D$5)^4*A7^-4)) -> 0 | E7: =$B$4*(B7^2)*($D$4^2*(2*PI())^4*A7^-5/4/PI()/$E$5^4*EXP((-1/PI())*(2*PI()/$E$5)^4*A7^-4)) -> 0 | F7: =$B$4*(B7^2)*($D$4^2*(2*PI())^4*A7^-5/4/PI()/$F$5^4*EXP((-1/PI())*(2*PI()/$F$5)^4*A7^-4)) -> 0 | G7: =$B$4*(B7^2)*($D$4^2*(2*PI())^4*A7^-5/4/PI()/$G$5^4*EXP((-1/PI())*(2*PI()/$G$5)^4*A7^-4)) -> 0 | H7: =$B$4*(B7^2)*($D$4^2*(2*PI())^4*A7^-5/4/PI()/$H$5^4*EXP((-1/PI())*(2*PI()/$H$5)^4*A7^-4)) -> 0 | I7: =$B$4*(B7^2)*($D$4^2*(2*PI())^4*A7^-5/4/PI()/$I$5^4*EXP((-1/PI())*(2*PI()/$I$5)^4*A7^-4)) -> 0 | J7: =$B$4*(B7^2)*($D$4^2*(2*PI())^4*A7^-5/4/PI()/$J$5^4*EXP((-1/PI())*(2*PI()/$J$5)^4*A7^-4)) -> 0 | K7: =$B$4*(B7^2)*($D$4^2*(2*PI())^4*A7^-5/4/PI()/$K$5^4*EXP((-1/PI())*(2*PI()/$K$5)^4*A7^-4)) -> 0 | L7: =$B$4*(B7^2)*($D$4^2*(2*PI())^4*A7^-5/4/PI()/$L$5^4*EXP((-1/PI())*(2*PI()/$L$5)^4*A7^-4)) -> 0 | M7: =$B$4*(B7^2)*($D$4^2*(2*PI())^4*A7^-5/4/PI()/$M$5^4*EXP((-1/PI())*(2*PI()/$M$5)^4*A7^-4)) -> 1.3015719e-238 | N7: =$B$4*(B7^2)*($D$4^2*(2*PI())^4*A7^-5/4/PI()/$N$5^4*EXP((-1/PI())*(2*PI()/$N$5)^4*A7^-4)) -> 1.1846588e-172 | O7: =$B$4*(B7^2)*($D$4^2*(2*PI())^4*A7^-5/4/PI()/$O$5^4*EXP((-1/PI())*(2*PI()/$O$5)^4*A7^-4)) -> 3.3954068e-127 | P7: =$B$4*(B7^2)*($D$4^2*(2*PI())^4*A7^-5/4/PI()/$P$5^4*EXP((-1/PI())*(2*PI()/$P$5)^4*A7^-4)) -> 4.6918435e-95 | Q7: =$B$4*(B7^2)*($D$4^2*(2*PI())^4*A7^-5/4/PI()/$Q$5^4*EXP((-1/PI())*(2*PI()/$Q$5)^4*A7^-4)) -> 8.0708055e-72 | R7: =$B$4*(B7^2)*($D$4^2*(2*PI())^4*A7^-5/4/PI()/$R$5^4*EXP((-1/PI())*(2*PI()/$R$5)^4*A7^-4)) -> 1.083815e-54 | S7: =$B$4*(B7^2)*($D$4^2*(2*PI())^4*A7^-5/4/PI()/$S$5^4*EXP((-1/PI())*(2*PI()/$S$5)^4*A7^-4)) -> 7.5771795e-42
A8: 0.10446991 | B8: =VBM_RAO!M8 -> 321987.2 | D8: =$B$4*(B8^2)*($D$4^2*(2*PI())^4*A8^-5/4/PI()/$D$5^4*EXP((-1/PI())*(2*PI()/$D$5)^4*A8^-4)) -> 0 | E8: =$B$4*(B8^2)*($D$4^2*(2*PI())^4*A8^-5/4/PI()/$E$5^4*EXP((-1/PI())*(2*PI()/$E$5)^4*A8^-4)) -> 0 | F8: =$B$4*(B8^2)*($D$4^2*(2*PI())^4*A8^-5/4/PI()/$F$5^4*EXP((-1/PI())*(2*PI()/$F$5)^4*A8^-4)) -> 0 | G8: =$B$4*(B8^2)*($D$4^2*(2*PI())^4*A8^-5/4/PI()/$G$5^4*EXP((-1/PI())*(2*PI()/$G$5)^4*A8^-4)) -> 0 | H8: =$B$4*(B8^2)*($D$4^2*(2*PI())^4*A8^-5/4/PI()/$H$5^4*EXP((-1/PI())*(2*PI()/$H$5)^4*A8^-4)) -> 0 | I8: =$B$4*(B8^2)*($D$4^2*(2*PI())^4*A8^-5/4/PI()/$I$5^4*EXP((-1/PI())*(2*PI()/$I$5)^4*A8^-4)) -> 0 | J8: =$B$4*(B8^2)*($D$4^2*(2*PI())^4*A8^-5/4/PI()/$J$5^4*EXP((-1/PI())*(2*PI()/$J$5)^4*A8^-4)) -> 7.4569021e-211 | K8: =$B$4*(B8^2)*($D$4^2*(2*PI())^4*A8^-5/4/PI()/$K$5^4*EXP((-1/PI())*(2*PI()/$K$5)^4*A8^-4)) -> 9.145639e-138 | L8: =$B$4*(B8^2)*($D$4^2*(2*PI())^4*A8^-5/4/PI()/$L$5^4*EXP((-1/PI())*(2*PI()/$L$5)^4*A8^-4)) -> 1.5657548e-92 | M8: =$B$4*(B8^2)*($D$4^2*(2*PI())^4*A8^-5/4/PI()/$M$5^4*EXP((-1/PI())*(2*PI()/$M$5)^4*A8^-4)) -> 2.3991392e-63 | N8: =$B$4*(B8^2)*($D$4^2*(2*PI())^4*A8^-5/4/PI()/$N$5^4*EXP((-1/PI())*(2*PI()/$N$5)^4*A8^-4)) -> 7.5426048e-44 | O8: =$B$4*(B8^2)*($D$4^2*(2*PI())^4*A8^-5/4/PI()/$O$5^4*EXP((-1/PI())*(2*PI()/$O$5)^4*A8^-4)) -> 1.9596098e-30 | P8: =$B$4*(B8^2)*($D$4^2*(2*PI())^4*A8^-5/4/PI()/$P$5^4*EXP((-1/PI())*(2*PI()/$P$5)^4*A8^-4)) -> 5.7176224e-21 | Q8: =$B$4*(B8^2)*($D$4^2*(2*PI())^4*A8^-5/4/PI()/$Q$5^4*EXP((-1/PI())*(2*PI()/$Q$5)^4*A8^-4)) -> 3.8228866e-14 | R8: =$B$4*(B8^2)*($D$4^2*(2*PI())^4*A8^-5/4/PI()/$R$5^4*EXP((-1/PI())*(2*PI()/$R$5)^4*A8^-4)) -> 3.9625616e-09 | S8: =$B$4*(B8^2)*($D$4^2*(2*PI())^4*A8^-5/4/PI()/$S$5^4*EXP((-1/PI())*(2*PI()/$S$5)^4*A8^-4)) -> 2.2144005e-05
A9: 0.13138243 | B9: =VBM_RAO!M9 -> 481594.64 | D9: =$B$4*(B9^2)*($D$4^2*(2*PI())^4*A9^-5/4/PI()/$D$5^4*EXP((-1/PI())*(2*PI()/$D$5)^4*A9^-4)) -> 0 | E9: =$B$4*(B9^2)*($D$4^2*(2*PI())^4*A9^-5/4/PI()/$E$5^4*EXP((-1/PI())*(2*PI()/$E$5)^4*A9^-4)) -> 0 | F9: =$B$4*(B9^2)*($D$4^2*(2*PI())^4*A9^-5/4/PI()/$F$5^4*EXP((-1/PI())*(2*PI()/$F$5)^4*A9^-4)) -> 0 | G9: =$B$4*(B9^2)*($D$4^2*(2*PI())^4*A9^-5/4/PI()/$G$5^4*EXP((-1/PI())*(2*PI()/$G$5)^4*A9^-4)) -> 0 | H9: =$B$4*(B9^2)*($D$4^2*(2*PI())^4*A9^-5/4/PI()/$H$5^4*EXP((-1/PI())*(2*PI()/$H$5)^4*A9^-4)) -> 4.6659483e-217 | I9: =$B$4*(B9^2)*($D$4^2*(2*PI())^4*A9^-5/4/PI()/$I$5^4*EXP((-1/PI())*(2*PI()/$I$5)^4*A9^-4)) -> 2.9167162e-127 | J9: =$B$4*(B9^2)*($D$4^2*(2*PI())^4*A9^-5/4/PI()/$J$5^4*EXP((-1/PI())*(2*PI()/$J$5)^4*A9^-4)) -> 1.0421764e-77 | K9: =$B$4*(B9^2)*($D$4^2*(2*PI())^4*A9^-5/4/PI()/$K$5^4*EXP((-1/PI())*(2*PI()/$K$5)^4*A9^-4)) -> 1.3570725e-48 | L9: =$B$4*(B9^2)*($D$4^2*(2*PI())^4*A9^-5/4/PI()/$L$5^4*EXP((-1/PI())*(2*PI()/$L$5)^4*A9^-4)) -> 1.321217e-30 | M9: =$B$4*(B9^2)*($D$4^2*(2*PI())^4*A9^-5/4/PI()/$M$5^4*EXP((-1/PI())*(2*PI()/$M$5)^4*A9^-4)) -> 5.0303574e-19 | N9: =$B$4*(B9^2)*($D$4^2*(2*PI())^4*A9^-5/4/PI()/$N$5^4*EXP((-1/PI())*(2*PI()/$N$5)^4*A9^-4)) -> 2.6058627e-11 | O9: =$B$4*(B9^2)*($D$4^2*(2*PI())^4*A9^-5/4/PI()/$O$5^4*EXP((-1/PI())*(2*PI()/$O$5)^4*A9^-4)) -> 5.0615401e-06 | P9: =$B$4*(B9^2)*($D$4^2*(2*PI())^4*A9^-5/4/PI()/$P$5^4*EXP((-1/PI())*(2*PI()/$P$5)^4*A9^-4)) -> 0.026219996 | Q9: =$B$4*(B9^2)*($D$4^2*(2*PI())^4*A9^-5/4/PI()/$Q$5^4*EXP((-1/PI())*(2*PI()/$Q$5)^4*A9^-4)) -> 12.077516 | R9: =$B$4*(B9^2)*($D$4^2*(2*PI())^4*A9^-5/4/PI()/$R$5^4*EXP((-1/PI())*(2*PI()/$R$5)^4*A9^-4)) -> 1061.0362 | S9: =$B$4*(B9^2)*($D$4^2*(2*PI())^4*A9^-5/4/PI()/$S$5^4*EXP((-1/PI())*(2*PI()/$S$5)^4*A9^-4)) -> 29231.873
A10: 0.1578615 | B10: =VBM_RAO!M10 -> 538229.53 | D10: =$B$4*(B10^2)*($D$4^2*(2*PI())^4*A10^-5/4/PI()/$D$5^4*EXP((-1/PI())*(2*PI()/$D$5)^4*A10^-4)) -> 0 | E10: =$B$4*(B10^2)*($D$4^2*(2*PI())^4*A10^-5/4/PI()/$E$5^4*EXP((-1/PI())*(2*PI()/$E$5)^4*A10^-4)) -> 0 | F10: =$B$4*(B10^2)*($D$4^2*(2*PI())^4*A10^-5/4/PI()/$F$5^4*EXP((-1/PI())*(2*PI()/$F$5)^4*A10^-4)) -> 0 | G10: =$B$4*(B10^2)*($D$4^2*(2*PI())^4*A10^-5/4/PI()/$G$5^4*EXP((-1/PI())*(2*PI()/$G$5)^4*A10^-4)) -> 6.296958e-183 | H10: =$B$4*(B10^2)*($D$4^2*(2*PI())^4*A10^-5/4/PI()/$H$5^4*EXP((-1/PI())*(2*PI()/$H$5)^4*A10^-4)) -> 1.8057673e-98 | I10: =$B$4*(B10^2)*($D$4^2*(2*PI())^4*A10^-5/4/PI()/$I$5^4*EXP((-1/PI())*(2*PI()/$I$5)^4*A10^-4)) -> 1.6829276e-55 | J10: =$B$4*(B10^2)*($D$4^2*(2*PI())^4*A10^-5/4/PI()/$J$5^4*EXP((-1/PI())*(2*PI()/$J$5)^4*A10^-4)) -> 7.9474451e-32 | K10: =$B$4*(B10^2)*($D$4^2*(2*PI())^4*A10^-5/4/PI()/$K$5^4*EXP((-1/PI())*(2*PI()/$K$5)^4*A10^-4)) -> 6.0045744e-18 | L10: =$B$4*(B10^2)*($D$4^2*(2*PI())^4*A10^-5/4/PI()/$L$5^4*EXP((-1/PI())*(2*PI()/$L$5)^4*A10^-4)) -> 2.122136e-09 | M10: =$B$4*(B10^2)*($D$4^2*(2*PI())^4*A10^-5/4/PI()/$M$5^4*EXP((-1/PI())*(2*PI()/$M$5)^4*A10^-4)) -> 0.0006420958 | N10: =$B$4*(B10^2)*($D$4^2*(2*PI())^4*A10^-5/4/PI()/$N$5^4*EXP((-1/PI())*(2*PI()/$N$5)^4*A10^-4)) -> 2.7495376 | O10: =$B$4*(B10^2)*($D$4^2*(2*PI())^4*A10^-5/4/PI()/$O$5^4*EXP((-1/PI())*(2*PI()/$O$5)^4*A10^-4)) -> 816.44972 | P10: =$B$4*(B10^2)*($D$4^2*(2*PI())^4*A10^-5/4/PI()/$P$5^4*EXP((-1/PI())*(2*PI()/$P$5)^4*A10^-4)) -> 43026.828 | Q10: =$B$4*(B10^2)*($D$4^2*(2*PI())^4*A10^-5/4/PI()/$Q$5^4*EXP((-1/PI())*(2*PI()/$Q$5)^4*A10^-4)) -> 716250.56 | R10: =$B$4*(B10^2)*($D$4^2*(2*PI())^4*A10^-5/4/PI()/$R$5^4*EXP((-1/PI())*(2*PI()/$R$5)^4*A10^-4)) -> 5425857.6 | S10: =$B$4*(B10^2)*($D$4^2*(2*PI())^4*A10^-5/4/PI()/$S$5^4*EXP((-1/PI())*(2*PI()/$S$5)^4*A10^-4)) -> 23724474
A11: 0.18390711 | B11: =VBM_RAO!M11 -> 401196.85 | D11: =$B$4*(B11^2)*($D$4^2*(2*PI())^4*A11^-5/4/PI()/$D$5^4*EXP((-1/PI())*(2*PI()/$D$5)^4*A11^-4)) -> 0 | E11: =$B$4*(B11^2)*($D$4^2*(2*PI())^4*A11^-5/4/PI()/$E$5^4*EXP((-1/PI())*(2*PI()/$E$5)^4*A11^-4)) -> 0 | F11: =$B$4*(B11^2)*($D$4^2*(2*PI())^4*A11^-5/4/PI()/$F$5^4*EXP((-1/PI())*(2*PI()/$F$5)^4*A11^-4)) -> 1.0647934e-194 | G11: =$B$4*(B11^2)*($D$4^2*(2*PI())^4*A11^-5/4/PI()/$G$5^4*EXP((-1/PI())*(2*PI()/$G$5)^4*A11^-4)) -> 1.1327701e-94 | H11: =$B$4*(B11^2)*($D$4^2*(2*PI())^4*A11^-5/4/PI()/$H$5^4*EXP((-1/PI())*(2*PI()/$H$5)^4*A11^-4)) -> 6.1879399e-49 | I11: =$B$4*(B11^2)*($D$4^2*(2*PI())^4*A11^-5/4/PI()/$I$5^4*EXP((-1/PI())*(2*PI()/$I$5)^4*A11^-4)) -> 1.0465484e-25 | J11: =$B$4*(B11^2)*($D$4^2*(2*PI())^4*A11^-5/4/PI()/$J$5^4*EXP((-1/PI())*(2*PI()/$J$5)^4*A11^-4)) -> 6.0795539e-13 | K11: =$B$4*(B11^2)*($D$4^2*(2*PI())^4*A11^-5/4/PI()/$K$5^4*EXP((-1/PI())*(2*PI()/$K$5)^4*A11^-4)) -> 1.7327846e-05 | L11: =$B$4*(B11^2)*($D$4^2*(2*PI())^4*A11^-5/4/PI()/$L$5^4*EXP((-1/PI())*(2*PI()/$L$5)^4*A11^-4)) -> 0.64161701 | M11: =$B$4*(B11^2)*($D$4^2*(2*PI())^4*A11^-5/4/PI()/$M$5^4*EXP((-1/PI())*(2*PI()/$M$5)^4*A11^-4)) -> 520.64616 | N11: =$B$4*(B11^2)*($D$4^2*(2*PI())^4*A11^-5/4/PI()/$N$5^4*EXP((-1/PI())*(2*PI()/$N$5)^4*A11^-4)) -> 42365.878 | O11: =$B$4*(B11^2)*($D$4^2*(2*PI())^4*A11^-5/4/PI()/$O$5^4*EXP((-1/PI())*(2*PI()/$O$5)^4*A11^-4)) -> 817817.27 | P11: =$B$4*(B11^2)*($D$4^2*(2*PI())^4*A11^-5/4/PI()/$P$5^4*EXP((-1/PI())*(2*PI()/$P$5)^4*A11^-4)) -> 6229437.8 | Q11: =$B$4*(B11^2)*($D$4^2*(2*PI())^4*A11^-5/4/PI()/$Q$5^4*EXP((-1/PI())*(2*PI()/$Q$5)^4*A11^-4)) -> 25576808 | R11: =$B$4*(B11^2)*($D$4^2*(2*PI())^4*A11^-5/4/PI()/$R$5^4*EXP((-1/PI())*(2*PI()/$R$5)^4*A11^-4)) -> 68950946 | S11: =$B$4*(B11^2)*($D$4^2*(2*PI())^4*A11^-5/4/PI()/$S$5^4*EXP((-1/PI())*(2*PI()/$S$5)^4*A11^-4)) -> 1.3875774e+08
A12: 0.20951927 | B12: =VBM_RAO!M12 -> 115250.03 | D12: =$B$4*(B12^2)*($D$4^2*(2*PI())^4*A12^-5/4/PI()/$D$5^4*EXP((-1/PI())*(2*PI()/$D$5)^4*A12^-4)) -> 0 | E12: =$B$4*(B12^2)*($D$4^2*(2*PI())^4*A12^-5/4/PI()/$E$5^4*EXP((-1/PI())*(2*PI()/$E$5)^4*A12^-4)) -> 1.5414679e-262 | F12: =$B$4*(B12^2)*($D$4^2*(2*PI())^4*A12^-5/4/PI()/$F$5^4*EXP((-1/PI())*(2*PI()/$F$5)^4*A12^-4)) -> 2.0364485e-112 | G12: =$B$4*(B12^2)*($D$4^2*(2*PI())^4*A12^-5/4/PI()/$G$5^4*EXP((-1/PI())*(2*PI()/$G$5)^4*A12^-4)) -> 3.6938725e-53 | H12: =$B$4*(B12^2)*($D$4^2*(2*PI())^4*A12^-5/4/PI()/$H$5^4*EXP((-1/PI())*(2*PI()/$H$5)^4*A12^-4)) -> 4.1347501e-26 | I12: =$B$4*(B12^2)*($D$4^2*(2*PI())^4*A12^-5/4/PI()/$I$5^4*EXP((-1/PI())*(2*PI()/$I$5)^4*A12^-4)) -> 2.0724851e-12 | J12: =$B$4*(B12^2)*($D$4^2*(2*PI())^4*A12^-5/4/PI()/$J$5^4*EXP((-1/PI())*(2*PI()/$J$5)^4*A12^-4)) -> 6.5286147e-05 | K12: =$B$4*(B12^2)*($D$4^2*(2*PI())^4*A12^-5/4/PI()/$K$5^4*EXP((-1/PI())*(2*PI()/$K$5)^4*A12^-4)) -> 1.4771372 | L12: =$B$4*(B12^2)*($D$4^2*(2*PI())^4*A12^-5/4/PI()/$L$5^4*EXP((-1/PI())*(2*PI()/$L$5)^4*A12^-4)) -> 656.3022 | M12: =$B$4*(B12^2)*($D$4^2*(2*PI())^4*A12^-5/4/PI()/$M$5^4*EXP((-1/PI())*(2*PI()/$M$5)^4*A12^-4)) -> 30563.014 | N12: =$B$4*(B12^2)*($D$4^2*(2*PI())^4*A12^-5/4/PI()/$N$5^4*EXP((-1/PI())*(2*PI()/$N$5)^4*A12^-4)) -> 367224.54 | O12: =$B$4*(B12^2)*($D$4^2*(2*PI())^4*A12^-5/4/PI()/$O$5^4*EXP((-1/PI())*(2*PI()/$O$5)^4*A12^-4)) -> 1895163.7 | P12: =$B$4*(B12^2)*($D$4^2*(2*PI())^4*A12^-5/4/PI()/$P$5^4*EXP((-1/PI())*(2*PI()/$P$5)^4*A12^-4)) -> 5675463.2 | Q12: =$B$4*(B12^2)*($D$4^2*(2*PI())^4*A12^-5/4/PI()/$Q$5^4*EXP((-1/PI())*(2*PI()/$Q$5)^4*A12^-4)) -> 11857131 | R12: =$B$4*(B12^2)*($D$4^2*(2*PI())^4*A12^-5/4/PI()/$R$5^4*EXP((-1/PI())*(2*PI()/$R$5)^4*A12^-4)) -> 19413414 | S12: =$B$4*(B12^2)*($D$4^2*(2*PI())^4*A12^-5/4/PI()/$S$5^4*EXP((-1/PI())*(2*PI()/$S$5)^4*A12^-4)) -> 26863276
A13: 0.23469797 | B13: =VBM_RAO!M13 -> 156835.1 | D13: =$B$4*(B13^2)*($D$4^2*(2*PI())^4*A13^-5/4/PI()/$D$5^4*EXP((-1/PI())*(2*PI()/$D$5)^4*A13^-4)) -> 0 | E13: =$B$4*(B13^2)*($D$4^2*(2*PI())^4*A13^-5/4/PI()/$E$5^4*EXP((-1/PI())*(2*PI()/$E$5)^4*A13^-4)) -> 4.9329935e-163 | F13: =$B$4*(B13^2)*($D$4^2*(2*PI())^4*A13^-5/4/PI()/$F$5^4*EXP((-1/PI())*(2*PI()/$F$5)^4*A13^-4)) -> 8.1532466e-68 | G13: =$B$4*(B13^2)*($D$4^2*(2*PI())^4*A13^-5/4/PI()/$G$5^4*EXP((-1/PI())*(2*PI()/$G$5)^4*A13^-4)) -> 2.7669986e-30 | H13: =$B$4*(B13^2)*($D$4^2*(2*PI())^4*A13^-5/4/PI()/$H$5^4*EXP((-1/PI())*(2*PI()/$H$5)^4*A13^-4)) -> 3.3943221e-13 | I13: =$B$4*(B13^2)*($D$4^2*(2*PI())^4*A13^-5/4/PI()/$I$5^4*EXP((-1/PI())*(2*PI()/$I$5)^4*A13^-4)) -> 0.00014211628 | J13: =$B$4*(B13^2)*($D$4^2*(2*PI())^4*A13^-5/4/PI()/$J$5^4*EXP((-1/PI())*(2*PI()/$J$5)^4*A13^-4)) -> 6.9905656 | K13: =$B$4*(B13^2)*($D$4^2*(2*PI())^4*A13^-5/4/PI()/$K$5^4*EXP((-1/PI())*(2*PI()/$K$5)^4*A13^-4)) -> 3521.9643 | L13: =$B$4*(B13^2)*($D$4^2*(2*PI())^4*A13^-5/4/PI()/$L$5^4*EXP((-1/PI())*(2*PI()/$L$5)^4*A13^-4)) -> 148159.4 | M13: =$B$4*(B13^2)*($D$4^2*(2*PI())^4*A13^-5/4/PI()/$M$5^4*EXP((-1/PI())*(2*PI()/$M$5)^4*A13^-4)) -> 1504260 | N13: =$B$4*(B13^2)*($D$4^2*(2*PI())^4*A13^-5/4/PI()/$N$5^4*EXP((-1/PI())*(2*PI()/$N$5)^4*A13^-4)) -> 6520888.7 | O13: =$B$4*(B13^2)*($D$4^2*(2*PI())^4*A13^-5/4/PI()/$O$5^4*EXP((-1/PI())*(2*PI()/$O$5)^4*A13^-4)) -> 16659986 | P13: =$B$4*(B13^2)*($D$4^2*(2*PI())^4*A13^-5/4/PI()/$P$5^4*EXP((-1/PI())*(2*PI()/$P$5)^4*A13^-4)) -> 30335158 | Q13: =$B$4*(B13^2)*($D$4^2*(2*PI())^4*A13^-5/4/PI()/$Q$5^4*EXP((-1/PI())*(2*PI()/$Q$5)^4*A13^-4)) -> 44212327 | R13: =$B$4*(B13^2)*($D$4^2*(2*PI())^4*A13^-5/4/PI()/$R$5^4*EXP((-1/PI())*(2*PI()/$R$5)^4*A13^-4)) -> 55493392 | S13: =$B$4*(B13^2)*($D$4^2*(2*PI())^4*A13^-5/4/PI()/$S$5^4*EXP((-1/PI())*(2*PI()/$S$5)^4*A13^-4)) -> 62893650
A14: 0.25944322 | B14: =VBM_RAO!M14 -> 184162.42 | D14: =$B$4*(B14^2)*($D$4^2*(2*PI())^4*A14^-5/4/PI()/$D$5^4*EXP((-1/PI())*(2*PI()/$D$5)^4*A14^-4)) -> 0 | E14: =$B$4*(B14^2)*($D$4^2*(2*PI())^4*A14^-5/4/PI()/$E$5^4*EXP((-1/PI())*(2*PI()/$E$5)^4*A14^-4)) -> 6.5384042e-106 | F14: =$B$4*(B14^2)*($D$4^2*(2*PI())^4*A14^-5/4/PI()/$F$5^4*EXP((-1/PI())*(2*PI()/$F$5)^4*A14^-4)) -> 2.9252792e-42 | G14: =$B$4*(B14^2)*($D$4^2*(2*PI())^4*A14^-5/4/PI()/$G$5^4*EXP((-1/PI())*(2*PI()/$G$5)^4*A14^-4)) -> 3.1907657e-17 | H14: =$B$4*(B14^2)*($D$4^2*(2*PI())^4*A14^-5/4/PI()/$H$5^4*EXP((-1/PI())*(2*PI()/$H$5)^4*A14^-4)) -> 7.341585e-06 | I14: =$B$4*(B14^2)*($D$4^2*(2*PI())^4*A14^-5/4/PI()/$I$5^4*EXP((-1/PI())*(2*PI()/$I$5)^4*A14^-4)) -> 3.6973106 | J14: =$B$4*(B14^2)*($D$4^2*(2*PI())^4*A14^-5/4/PI()/$J$5^4*EXP((-1/PI())*(2*PI()/$J$5)^4*A14^-4)) -> 4427.0855 | K14: =$B$4*(B14^2)*($D$4^2*(2*PI())^4*A14^-5/4/PI()/$K$5^4*EXP((-1/PI())*(2*PI()/$K$5)^4*A14^-4)) -> 250235.4 | L14: =$B$4*(B14^2)*($D$4^2*(2*PI())^4*A14^-5/4/PI()/$L$5^4*EXP((-1/PI())*(2*PI()/$L$5)^4*A14^-4)) -> 2714387.8 | M14: =$B$4*(B14^2)*($D$4^2*(2*PI())^4*A14^-5/4/PI()/$M$5^4*EXP((-1/PI())*(2*PI()/$M$5)^4*A14^-4)) -> 11479486 | N14: =$B$4*(B14^2)*($D$4^2*(2*PI())^4*A14^-5/4/PI()/$N$5^4*EXP((-1/PI())*(2*PI()/$N$5)^4*A14^-4)) -> 27690866 | O14: =$B$4*(B14^2)*($D$4^2*(2*PI())^4*A14^-5/4/PI()/$O$5^4*EXP((-1/PI())*(2*PI()/$O$5)^4*A14^-4)) -> 47221343 | P14: =$B$4*(B14^2)*($D$4^2*(2*PI())^4*A14^-5/4/PI()/$P$5^4*EXP((-1/PI())*(2*PI()/$P$5)^4*A14^-4)) -> 64590449 | Q14: =$B$4*(B14^2)*($D$4^2*(2*PI())^4*A14^-5/4/PI()/$Q$5^4*EXP((-1/PI())*(2*PI()/$Q$5)^4*A14^-4)) -> 76533329 | R14: =$B$4*(B14^2)*($D$4^2*(2*PI())^4*A14^-5/4/PI()/$R$5^4*EXP((-1/PI())*(2*PI()/$R$5)^4*A14^-4)) -> 82448491 | S14: =$B$4*(B14^2)*($D$4^2*(2*PI())^4*A14^-5/4/PI()/$S$5^4*EXP((-1/PI())*(2*PI()/$S$5)^4*A14^-4)) -> 83311133
A15: 0.28375501 | B15: =VBM_RAO!M15 -> 100992.3 | D15: =$B$4*(B15^2)*($D$4^2*(2*PI())^4*A15^-5/4/PI()/$D$5^4*EXP((-1/PI())*(2*PI()/$D$5)^4*A15^-4)) -> 1.0876325e-211 | E15: =$B$4*(B15^2)*($D$4^2*(2*PI())^4*A15^-5/4/PI()/$E$5^4*EXP((-1/PI())*(2*PI()/$E$5)^4*A15^-4)) -> 1.0484033e-71 | F15: =$B$4*(B15^2)*($D$4^2*(2*PI())^4*A15^-5/4/PI()/$F$5^4*EXP((-1/PI())*(2*PI()/$F$5)^4*A15^-4)) -> 2.5060359e-27 | G15: =$B$4*(B15^2)*($D$4^2*(2*PI())^4*A15^-5/4/PI()/$G$5^4*EXP((-1/PI())*(2*PI()/$G$5)^4*A15^-4)) -> 6.4515543e-10 | H15: =$B$4*(B15^2)*($D$4^2*(2*PI())^4*A15^-5/4/PI()/$H$5^4*EXP((-1/PI())*(2*PI()/$H$5)^4*A15^-4)) -> 0.047344566 | I15: =$B$4*(B15^2)*($D$4^2*(2*PI())^4*A15^-5/4/PI()/$I$5^4*EXP((-1/PI())*(2*PI()/$I$5)^4*A15^-4)) -> 393.37545 | J15: =$B$4*(B15^2)*($D$4^2*(2*PI())^4*A15^-5/4/PI()/$J$5^4*EXP((-1/PI())*(2*PI()/$J$5)^4*A15^-4)) -> 48741.705 | K15: =$B$4*(B15^2)*($D$4^2*(2*PI())^4*A15^-5/4/PI()/$K$5^4*EXP((-1/PI())*(2*PI()/$K$5)^4*A15^-4)) -> 724641.34 | L15: =$B$4*(B15^2)*($D$4^2*(2*PI())^4*A15^-5/4/PI()/$L$5^4*EXP((-1/PI())*(2*PI()/$L$5)^4*A15^-4)) -> 3436277.1 | M15: =$B$4*(B15^2)*($D$4^2*(2*PI())^4*A15^-5/4/PI()/$M$5^4*EXP((-1/PI())*(2*PI()/$M$5)^4*A15^-4)) -> 8514047.4 | N15: =$B$4*(B15^2)*($D$4^2*(2*PI())^4*A15^-5/4/PI()/$N$5^4*EXP((-1/PI())*(2*PI()/$N$5)^4*A15^-4)) -> 14359297 | O15: =$B$4*(B15^2)*($D$4^2*(2*PI())^4*A15^-5/4/PI()/$O$5^4*EXP((-1/PI())*(2*PI()/$O$5)^4*A15^-4)) -> 19131562 | P15: =$B$4*(B15^2)*($D$4^2*(2*PI())^4*A15^-5/4/PI()/$P$5^4*EXP((-1/PI())*(2*PI()/$P$5)^4*A15^-4)) -> 21975048 | Q15: =$B$4*(B15^2)*($D$4^2*(2*PI())^4*A15^-5/4/PI()/$Q$5^4*EXP((-1/PI())*(2*PI()/$Q$5)^4*A15^-4)) -> 22946603 | R15: =$B$4*(B15^2)*($D$4^2*(2*PI())^4*A15^-5/4/PI()/$R$5^4*EXP((-1/PI())*(2*PI()/$R$5)^4*A15^-4)) -> 22518198 | S15: =$B$4*(B15^2)*($D$4^2*(2*PI())^4*A15^-5/4/PI()/$S$5^4*EXP((-1/PI())*(2*PI()/$S$5)^4*A15^-4)) -> 21214024
A16: 0.30763334 | B16: =VBM_RAO!M16 -> 127131.48 | D16: =$B$4*(B16^2)*($D$4^2*(2*PI())^4*A16^-5/4/PI()/$D$5^4*EXP((-1/PI())*(2*PI()/$D$5)^4*A16^-4)) -> 1.6666621e-150 | E16: =$B$4*(B16^2)*($D$4^2*(2*PI())^4*A16^-5/4/PI()/$E$5^4*EXP((-1/PI())*(2*PI()/$E$5)^4*A16^-4)) -> 2.6721062e-49 | F16: =$B$4*(B16^2)*($D$4^2*(2*PI())^4*A16^-5/4/PI()/$F$5^4*EXP((-1/PI())*(2*PI()/$F$5)^4*A16^-4)) -> 2.8401076e-17 | G16: =$B$4*(B16^2)*($D$4^2*(2*PI())^4*A16^-5/4/PI()/$G$5^4*EXP((-1/PI())*(2*PI()/$G$5)^4*A16^-4)) -> 9.4553225e-05 | H16: =$B$4*(B16^2)*($D$4^2*(2*PI())^4*A16^-5/4/PI()/$H$5^4*EXP((-1/PI())*(2*PI()/$H$5)^4*A16^-4)) -> 39.850852 | I16: =$B$4*(B16^2)*($D$4^2*(2*PI())^4*A16^-5/4/PI()/$I$5^4*EXP((-1/PI())*(2*PI()/$I$5)^4*A16^-4)) -> 23850.394 | J16: =$B$4*(B16^2)*($D$4^2*(2*PI())^4*A16^-5/4/PI()/$J$5^4*EXP((-1/PI())*(2*PI()/$J$5)^4*A16^-4)) -> 690546.96 | K16: =$B$4*(B16^2)*($D$4^2*(2*PI())^4*A16^-5/4/PI()/$K$5^4*EXP((-1/PI())*(2*PI()/$K$5)^4*A16^-4)) -> 4361904.2 | L16: =$B$4*(B16^2)*($D$4^2*(2*PI())^4*A16^-5/4/PI()/$L$5^4*EXP((-1/PI())*(2*PI()/$L$5)^4*A16^-4)) -> 12170856 | M16: =$B$4*(B16^2)*($D$4^2*(2*PI())^4*A16^-5/4/PI()/$M$5^4*EXP((-1/PI())*(2*PI()/$M$5)^4*A16^-4)) -> 21406491 | N16: =$B$4*(B16^2)*($D$4^2*(2*PI())^4*A16^-5/4/PI()/$N$5^4*EXP((-1/PI())*(2*PI()/$N$5)^4*A16^-4)) -> 28703352 | O16: =$B$4*(B16^2)*($D$4^2*(2*PI())^4*A16^-5/4/PI()/$O$5^4*EXP((-1/PI())*(2*PI()/$O$5)^4*A16^-4)) -> 32647735 | P16: =$B$4*(B16^2)*($D$4^2*(2*PI())^4*A16^-5/4/PI()/$P$5^4*EXP((-1/PI())*(2*PI()/$P$5)^4*A16^-4)) -> 33528819 | Q16: =$B$4*(B16^2)*($D$4^2*(2*PI())^4*A16^-5/4/PI()/$Q$5^4*EXP((-1/PI())*(2*PI()/$Q$5)^4*A16^-4)) -> 32286746 | R16: =$B$4*(B16^2)*($D$4^2*(2*PI())^4*A16^-5/4/PI()/$R$5^4*EXP((-1/PI())*(2*PI()/$R$5)^4*A16^-4)) -> 29844989 | S16: =$B$4*(B16^2)*($D$4^2*(2*PI())^4*A16^-5/4/PI()/$S$5^4*EXP((-1/PI())*(2*PI()/$S$5)^4*A16^-4)) -> 26881719
A17: 0.33107822 | B17: =VBM_RAO!M17 -> 90298.995 | D17: =$B$4*(B17^2)*($D$4^2*(2*PI())^4*A17^-5/4/PI()/$D$5^4*EXP((-1/PI())*(2*PI()/$D$5)^4*A17^-4)) -> 3.7409517e-110 | E17: =$B$4*(B17^2)*($D$4^2*(2*PI())^4*A17^-5/4/PI()/$E$5^4*EXP((-1/PI())*(2*PI()/$E$5)^4*A17^-4)) -> 8.0138308e-35 | F17: =$B$4*(B17^2)*($D$4^2*(2*PI())^4*A17^-5/4/PI()/$F$5^4*EXP((-1/PI())*(2*PI()/$F$5)^4*A17^-4)) -> 4.8846738e-11 | G17: =$B$4*(B17^2)*($D$4^2*(2*PI())^4*A17^-5/4/PI()/$G$5^4*EXP((-1/PI())*(2*PI()/$G$5)^4*A17^-4)) -> 0.089039409 | H17: =$B$4*(B17^2)*($D$4^2*(2*PI())^4*A17^-5/4/PI()/$H$5^4*EXP((-1/PI())*(2*PI()/$H$5)^4*A17^-4)) -> 1200.0723 | I17: =$B$4*(B17^2)*($D$4^2*(2*PI())^4*A17^-5/4/PI()/$I$5^4*EXP((-1/PI())*(2*PI()/$I$5)^4*A17^-4)) -> 124159.66 | J17: =$B$4*(B17^2)*($D$4^2*(2*PI())^4*A17^-5/4/PI()/$J$5^4*EXP((-1/PI())*(2*PI()/$J$5)^4*A17^-4)) -> 1362693.9 | K17: =$B$4*(B17^2)*($D$4^2*(2*PI())^4*A17^-5/4/PI()/$K$5^4*EXP((-1/PI())*(2*PI()/$K$5)^4*A17^-4)) -> 4862383.7 | L17: =$B$4*(B17^2)*($D$4^2*(2*PI())^4*A17^-5/4/PI()/$L$5^4*EXP((-1/PI())*(2*PI()/$L$5)^4*A17^-4)) -> 9524014.9 | M17: =$B$4*(B17^2)*($D$4^2*(2*PI())^4*A17^-5/4/PI()/$M$5^4*EXP((-1/PI())*(2*PI()/$M$5)^4*A17^-4)) -> 13327430 | N17: =$B$4*(B17^2)*($D$4^2*(2*PI())^4*A17^-5/4/PI()/$N$5^4*EXP((-1/PI())*(2*PI()/$N$5)^4*A17^-4)) -> 15334577 | O17: =$B$4*(B17^2)*($D$4^2*(2*PI())^4*A17^-5/4/PI()/$O$5^4*EXP((-1/PI())*(2*PI()/$O$5)^4*A17^-4)) -> 15694821 | P17: =$B$4*(B17^2)*($D$4^2*(2*PI())^4*A17^-5/4/PI()/$P$5^4*EXP((-1/PI())*(2*PI()/$P$5)^4*A17^-4)) -> 14958402 | Q17: =$B$4*(B17^2)*($D$4^2*(2*PI())^4*A17^-5/4/PI()/$Q$5^4*EXP((-1/PI())*(2*PI()/$Q$5)^4*A17^-4)) -> 13646357 | R17: =$B$4*(B17^2)*($D$4^2*(2*PI())^4*A17^-5/4/PI()/$R$5^4*EXP((-1/PI())*(2*PI()/$R$5)^4*A17^-4)) -> 12120971 | S17: =$B$4*(B17^2)*($D$4^2*(2*PI())^4*A17^-5/4/PI()/$S$5^4*EXP((-1/PI())*(2*PI()/$S$5)^4*A17^-4)) -> 10595213
... A46: 0.82242642 | B46: =VBM_RAO!M46 -> 16237.977 | D46: =$B$4*(B46^2)*($D$4^2*(2*PI())^4*A46^-5/4/PI()/$D$5^4*EXP((-1/PI())*(2*PI()/$D$5)^4*A46^-4)) -> 2925.4066 | E46: =$B$4*(B46^2)*($D$4^2*(2*PI())^4*A46^-5/4/PI()/$E$5^4*EXP((-1/PI())*(2*PI()/$E$5)^4*A46^-4)) -> 104578.45 | F46: =$B$4*(B46^2)*($D$4^2*(2*PI())^4*A46^-5/4/PI()/$F$5^4*EXP((-1/PI())*(2*PI()/$F$5)^4*A46^-4)) -> 201672.81 | G46: =$B$4*(B46^2)*($D$4^2*(2*PI())^4*A46^-5/4/PI()/$G$5^4*EXP((-1/PI())*(2*PI()/$G$5)^4*A46^-4)) -> 184193.98 | H46: =$B$4*(B46^2)*($D$4^2*(2*PI())^4*A46^-5/4/PI()/$H$5^4*EXP((-1/PI())*(2*PI()/$H$5)^4*A46^-4)) -> 135414.83 | I46: =$B$4*(B46^2)*($D$4^2*(2*PI())^4*A46^-5/4/PI()/$I$5^4*EXP((-1/PI())*(2*PI()/$I$5)^4*A46^-4)) -> 93941.736 | J46: =$B$4*(B46^2)*($D$4^2*(2*PI())^4*A46^-5/4/PI()/$J$5^4*EXP((-1/PI())*(2*PI()/$J$5)^4*A46^-4)) -> 64869.135 | K46: =$B$4*(B46^2)*($D$4^2*(2*PI())^4*A46^-5/4/PI()/$K$5^4*EXP((-1/PI())*(2*PI()/$K$5)^4*A46^-4)) -> 45420.307 | L46: =$B$4*(B46^2)*($D$4^2*(2*PI())^4*A46^-5/4/PI()/$L$5^4*EXP((-1/PI())*(2*PI()/$L$5)^4*A46^-4)) -> 32436.509 | M46: =$B$4*(B46^2)*($D$4^2*(2*PI())^4*A46^-5/4/PI()/$M$5^4*EXP((-1/PI())*(2*PI()/$M$5)^4*A46^-4)) -> 23649.494 | N46: =$B$4*(B46^2)*($D$4^2*(2*PI())^4*A46^-5/4/PI()/$N$5^4*EXP((-1/PI())*(2*PI()/$N$5)^4*A46^-4)) -> 17588.874 | O46: =$B$4*(B46^2)*($D$4^2*(2*PI())^4*A46^-5/4/PI()/$O$5^4*EXP((-1/PI())*(2*PI()/$O$5)^4*A46^-4)) -> 13323.738 | P46: =$B$4*(B46^2)*($D$4^2*(2*PI())^4*A46^-5/4/PI()/$P$5^4*EXP((-1/PI())*(2*PI()/$P$5)^4*A46^-4)) -> 10262.798 | Q46: =$B$4*(B46^2)*($D$4^2*(2*PI())^4*A46^-5/4/PI()/$Q$5^4*EXP((-1/PI())*(2*PI()/$Q$5)^4*A46^-4)) -> 8025.3152 | R46: =$B$4*(B46^2)*($D$4^2*(2*PI())^4*A46^-5/4/PI()/$R$5^4*EXP((-1/PI())*(2*PI()/$R$5)^4*A46^-4)) -> 6361.7728 | S46: =$B$4*(B46^2)*($D$4^2*(2*PI())^4*A46^-5/4/PI()/$S$5^4*EXP((-1/PI())*(2*PI()/$S$5)^4*A46^-4)) -> 5105.5698
C47: sum | D47: =SUM(D6:D46) -> 15103.112 | E47: =SUM(E6:E46) -> 1644768.2 | F47: =SUM(F6:F46) -> 5423628.6 | G47: =SUM(G6:G46) -> 6726987.3 | H47: =SUM(H6:H46) -> 8322234.4 | I47: =SUM(I6:I46) -> 15040386 | J47: =SUM(J6:J46) -> 29154780 | K47: =SUM(K6:K46) -> 49939385 | ... S47: =SUM(S6:S46) -> 4.1732282e+08 | T47: =SUM(D47:S47) -> 1.8309456e+09
A48: w0 | B48: =A51-A50 -> 0.027779436 | C48: Hs | D48: 1.5
A49: w | B49: RAO(0) | C49: Tz | D49: 3.5 | E49: 4.5 | F49: 5.5 | G49: 6.5 | H49: 7.5 | I49: 8.5 | J49: 9.5 | K49: 10.5 | L49: 11.5 | M49: 12.5 | N49: 13.5 | O49: 14.5 | P49: 15.5 | Q49: 16.5 | R49: 17.5 | S49: 18.5
A50: =A6 -> 0.04934449 | B50: =B6 -> 66932.15 | D50: =$B$4*(B50^2)*($D$48^2*(2*PI())^4*A50^-5/4/PI()/$D$5^4*EXP((-1/PI())*(2*PI()/$D$5)^4*A50^-4)) -> 0 | E50: =$B$4*(B50^2)*($D$48^2*(2*PI())^4*A50^-5/4/PI()/$E$5^4*EXP((-1/PI())*(2*PI()/$E$5)^4*A50^-4)) -> 0 | F50: =$B$4*(B50^2)*($D$48^2*(2*PI())^4*A50^-5/4/PI()/$F$5^4*EXP((-1/PI())*(2*PI()/$F$5)^4*A50^-4)) -> 0 | G50: =$B$4*(B50^2)*($D$48^2*(2*PI())^4*A50^-5/4/PI()/$G$5^4*EXP((-1/PI())*(2*PI()/$G$5)^4*A50^-4)) -> 0 | H50: =$B$4*(B50^2)*($D$48^2*(2*PI())^4*A50^-5/4/PI()/$H$5^4*EXP((-1/PI())*(2*PI()/$H$5)^4*A50^-4)) -> 0 | I50: =$B$4*(B50^2)*($D$48^2*(2*PI())^4*A50^-5/4/PI()/$I$5^4*EXP((-1/PI())*(2*PI()/$I$5)^4*A50^-4)) -> 0 | J50: =$B$4*(B50^2)*($D$48^2*(2*PI())^4*A50^-5/4/PI()/$J$5^4*EXP((-1/PI())*(2*PI()/$J$5)^4*A50^-4)) -> 0 | K50: =$B$4*(B50^2)*($D$48^2*(2*PI())^4*A50^-5/4/PI()/$K$5^4*EXP((-1/PI())*(2*PI()/$K$5)^4*A50^-4)) -> 0 | L50: =$B$4*(B50^2)*($D$48^2*(2*PI())^4*A50^-5/4/PI()/$L$5^4*EXP((-1/PI())*(2*PI()/$L$5)^4*A50^-4)) -> 0 | M50: =$B$4*(B50^2)*($D$48^2*(2*PI())^4*A50^-5/4/PI()/$M$5^4*EXP((-1/PI())*(2*PI()/$M$5)^4*A50^-4)) -> 0 | N50: =$B$4*(B50^2)*($D$48^2*(2*PI())^4*A50^-5/4/PI()/$N$5^4*EXP((-1/PI())*(2*PI()/$N$5)^4*A50^-4)) -> 0 | O50: =$B$4*(B50^2)*($D$48^2*(2*PI())^4*A50^-5/4/PI()/$O$5^4*EXP((-1/PI())*(2*PI()/$O$5)^4*A50^-4)) -> 0 | P50: =$B$4*(B50^2)*($D$48^2*(2*PI())^4*A50^-5/4/PI()/$P$5^4*EXP((-1/PI())*(2*PI()/$P$5)^4*A50^-4)) -> 0 | Q50: =$B$4*(B50^2)*($D$48^2*(2*PI())^4*A50^-5/4/PI()/$Q$5^4*EXP((-1/PI())*(2*PI()/$Q$5)^4*A50^-4)) -> 0 | R50: =$B$4*(B50^2)*($D$48^2*(2*PI())^4*A50^-5/4/PI()/$R$5^4*EXP((-1/PI())*(2*PI()/$R$5)^4*A50^-4)) -> 0 | S50: =$B$4*(B50^2)*($D$48^2*(2*PI())^4*A50^-5/4/PI()/$S$5^4*EXP((-1/PI())*(2*PI()/$S$5)^4*A50^-4)) -> 5.6940362e-299
A51: =A7 -> 0.077123926 | B51: =B7 -> 165548.16 | D51: =$B$4*(B51^2)*($D$48^2*(2*PI())^4*A51^-5/4/PI()/$D$5^4*EXP((-1/PI())*(2*PI()/$D$5)^4*A51^-4)) -> 0 | E51: =$B$4*(B51^2)*($D$48^2*(2*PI())^4*A51^-5/4/PI()/$E$5^4*EXP((-1/PI())*(2*PI()/$E$5)^4*A51^-4)) -> 0 | F51: =$B$4*(B51^2)*($D$48^2*(2*PI())^4*A51^-5/4/PI()/$F$5^4*EXP((-1/PI())*(2*PI()/$F$5)^4*A51^-4)) -> 0 | G51: =$B$4*(B51^2)*($D$48^2*(2*PI())^4*A51^-5/4/PI()/$G$5^4*EXP((-1/PI())*(2*PI()/$G$5)^4*A51^-4)) -> 0 | H51: =$B$4*(B51^2)*($D$48^2*(2*PI())^4*A51^-5/4/PI()/$H$5^4*EXP((-1/PI())*(2*PI()/$H$5)^4*A51^-4)) -> 0 | I51: =$B$4*(B51^2)*($D$48^2*(2*PI())^4*A51^-5/4/PI()/$I$5^4*EXP((-1/PI())*(2*PI()/$I$5)^4*A51^-4)) -> 0 | J51: =$B$4*(B51^2)*($D$48^2*(2*PI())^4*A51^-5/4/PI()/$J$5^4*EXP((-1/PI())*(2*PI()/$J$5)^4*A51^-4)) -> 0 | K51: =$B$4*(B51^2)*($D$48^2*(2*PI())^4*A51^-5/4/PI()/$K$5^4*EXP((-1/PI())*(2*PI()/$K$5)^4*A51^-4)) -> 0 | L51: =$B$4*(B51^2)*($D$48^2*(2*PI())^4*A51^-5/4/PI()/$L$5^4*EXP((-1/PI())*(2*PI()/$L$5)^4*A51^-4)) -> 0 | M51: =$B$4*(B51^2)*($D$48^2*(2*PI())^4*A51^-5/4/PI()/$M$5^4*EXP((-1/PI())*(2*PI()/$M$5)^4*A51^-4)) -> 1.1714147e-237 | N51: =$B$4*(B51^2)*($D$48^2*(2*PI())^4*A51^-5/4/PI()/$N$5^4*EXP((-1/PI())*(2*PI()/$N$5)^4*A51^-4)) -> 1.0661929e-171 | O51: =$B$4*(B51^2)*($D$48^2*(2*PI())^4*A51^-5/4/PI()/$O$5^4*EXP((-1/PI())*(2*PI()/$O$5)^4*A51^-4)) -> 3.0558661e-126 | P51: =$B$4*(B51^2)*($D$48^2*(2*PI())^4*A51^-5/4/PI()/$P$5^4*EXP((-1/PI())*(2*PI()/$P$5)^4*A51^-4)) -> 4.2226591e-94 | Q51: =$B$4*(B51^2)*($D$48^2*(2*PI())^4*A51^-5/4/PI()/$Q$5^4*EXP((-1/PI())*(2*PI()/$Q$5)^4*A51^-4)) -> 7.263725e-71 | R51: =$B$4*(B51^2)*($D$48^2*(2*PI())^4*A51^-5/4/PI()/$R$5^4*EXP((-1/PI())*(2*PI()/$R$5)^4*A51^-4)) -> 9.7543351e-54 | S51: =$B$4*(B51^2)*($D$48^2*(2*PI())^4*A51^-5/4/PI()/$S$5^4*EXP((-1/PI())*(2*PI()/$S$5)^4*A51^-4)) -> 6.8194615e-41
A52: =A8 -> 0.10446991 | B52: =B8 -> 321987.2 | D52: =$B$4*(B52^2)*($D$48^2*(2*PI())^4*A52^-5/4/PI()/$D$5^4*EXP((-1/PI())*(2*PI()/$D$5)^4*A52^-4)) -> 0 | E52: =$B$4*(B52^2)*($D$48^2*(2*PI())^4*A52^-5/4/PI()/$E$5^4*EXP((-1/PI())*(2*PI()/$E$5)^4*A52^-4)) -> 0 | F52: =$B$4*(B52^2)*($D$48^2*(2*PI())^4*A52^-5/4/PI()/$F$5^4*EXP((-1/PI())*(2*PI()/$F$5)^4*A52^-4)) -> 0 | G52: =$B$4*(B52^2)*($D$48^2*(2*PI())^4*A52^-5/4/PI()/$G$5^4*EXP((-1/PI())*(2*PI()/$G$5)^4*A52^-4)) -> 0 | H52: =$B$4*(B52^2)*($D$48^2*(2*PI())^4*A52^-5/4/PI()/$H$5^4*EXP((-1/PI())*(2*PI()/$H$5)^4*A52^-4)) -> 0 | I52: =$B$4*(B52^2)*($D$48^2*(2*PI())^4*A52^-5/4/PI()/$I$5^4*EXP((-1/PI())*(2*PI()/$I$5)^4*A52^-4)) -> 0 | J52: =$B$4*(B52^2)*($D$48^2*(2*PI())^4*A52^-5/4/PI()/$J$5^4*EXP((-1/PI())*(2*PI()/$J$5)^4*A52^-4)) -> 6.7112118e-210 | K52: =$B$4*(B52^2)*($D$48^2*(2*PI())^4*A52^-5/4/PI()/$K$5^4*EXP((-1/PI())*(2*PI()/$K$5)^4*A52^-4)) -> 8.2310751e-137 | L52: =$B$4*(B52^2)*($D$48^2*(2*PI())^4*A52^-5/4/PI()/$L$5^4*EXP((-1/PI())*(2*PI()/$L$5)^4*A52^-4)) -> 1.4091793e-91 | M52: =$B$4*(B52^2)*($D$48^2*(2*PI())^4*A52^-5/4/PI()/$M$5^4*EXP((-1/PI())*(2*PI()/$M$5)^4*A52^-4)) -> 2.1592253e-62 | N52: =$B$4*(B52^2)*($D$48^2*(2*PI())^4*A52^-5/4/PI()/$N$5^4*EXP((-1/PI())*(2*PI()/$N$5)^4*A52^-4)) -> 6.7883443e-43 | O52: =$B$4*(B52^2)*($D$48^2*(2*PI())^4*A52^-5/4/PI()/$O$5^4*EXP((-1/PI())*(2*PI()/$O$5)^4*A52^-4)) -> 1.7636488e-29 | P52: =$B$4*(B52^2)*($D$48^2*(2*PI())^4*A52^-5/4/PI()/$P$5^4*EXP((-1/PI())*(2*PI()/$P$5)^4*A52^-4)) -> 5.1458602e-20 | Q52: =$B$4*(B52^2)*($D$48^2*(2*PI())^4*A52^-5/4/PI()/$Q$5^4*EXP((-1/PI())*(2*PI()/$Q$5)^4*A52^-4)) -> 3.440598e-13 | R52: =$B$4*(B52^2)*($D$48^2*(2*PI())^4*A52^-5/4/PI()/$R$5^4*EXP((-1/PI())*(2*PI()/$R$5)^4*A52^-4)) -> 3.5663054e-08 | S52: =$B$4*(B52^2)*($D$48^2*(2*PI())^4*A52^-5/4/PI()/$S$5^4*EXP((-1/PI())*(2*PI()/$S$5)^4*A52^-4)) -> 0.00019929604
A53: =A9 -> 0.13138243 | B53: =B9 -> 481594.64 | D53: =$B$4*(B53^2)*($D$48^2*(2*PI())^4*A53^-5/4/PI()/$D$5^4*EXP((-1/PI())*(2*PI()/$D$5)^4*A53^-4)) -> 0 | E53: =$B$4*(B53^2)*($D$48^2*(2*PI())^4*A53^-5/4/PI()/$E$5^4*EXP((-1/PI())*(2*PI()/$E$5)^4*A53^-4)) -> 0 | F53: =$B$4*(B53^2)*($D$48^2*(2*PI())^4*A53^-5/4/PI()/$F$5^4*EXP((-1/PI())*(2*PI()/$F$5)^4*A53^-4)) -> 0 | G53: =$B$4*(B53^2)*($D$48^2*(2*PI())^4*A53^-5/4/PI()/$G$5^4*EXP((-1/PI())*(2*PI()/$G$5)^4*A53^-4)) -> 0 | H53: =$B$4*(B53^2)*($D$48^2*(2*PI())^4*A53^-5/4/PI()/$H$5^4*EXP((-1/PI())*(2*PI()/$H$5)^4*A53^-4)) -> 4.1993535e-216 | I53: =$B$4*(B53^2)*($D$48^2*(2*PI())^4*A53^-5/4/PI()/$I$5^4*EXP((-1/PI())*(2*PI()/$I$5)^4*A53^-4)) -> 2.6250446e-126 | J53: =$B$4*(B53^2)*($D$48^2*(2*PI())^4*A53^-5/4/PI()/$J$5^4*EXP((-1/PI())*(2*PI()/$J$5)^4*A53^-4)) -> 9.3795877e-77 | K53: =$B$4*(B53^2)*($D$48^2*(2*PI())^4*A53^-5/4/PI()/$K$5^4*EXP((-1/PI())*(2*PI()/$K$5)^4*A53^-4)) -> 1.2213653e-47 | L53: =$B$4*(B53^2)*($D$48^2*(2*PI())^4*A53^-5/4/PI()/$L$5^4*EXP((-1/PI())*(2*PI()/$L$5)^4*A53^-4)) -> 1.1890953e-29 | M53: =$B$4*(B53^2)*($D$48^2*(2*PI())^4*A53^-5/4/PI()/$M$5^4*EXP((-1/PI())*(2*PI()/$M$5)^4*A53^-4)) -> 4.5273217e-18 | N53: =$B$4*(B53^2)*($D$48^2*(2*PI())^4*A53^-5/4/PI()/$N$5^4*EXP((-1/PI())*(2*PI()/$N$5)^4*A53^-4)) -> 2.3452764e-10 | O53: =$B$4*(B53^2)*($D$48^2*(2*PI())^4*A53^-5/4/PI()/$O$5^4*EXP((-1/PI())*(2*PI()/$O$5)^4*A53^-4)) -> 4.5553861e-05 | P53: =$B$4*(B53^2)*($D$48^2*(2*PI())^4*A53^-5/4/PI()/$P$5^4*EXP((-1/PI())*(2*PI()/$P$5)^4*A53^-4)) -> 0.23597997 | Q53: =$B$4*(B53^2)*($D$48^2*(2*PI())^4*A53^-5/4/PI()/$Q$5^4*EXP((-1/PI())*(2*PI()/$Q$5)^4*A53^-4)) -> 108.69765 | R53: =$B$4*(B53^2)*($D$48^2*(2*PI())^4*A53^-5/4/PI()/$R$5^4*EXP((-1/PI())*(2*PI()/$R$5)^4*A53^-4)) -> 9549.3261 | S53: =$B$4*(B53^2)*($D$48^2*(2*PI())^4*A53^-5/4/PI()/$S$5^4*EXP((-1/PI())*(2*PI()/$S$5)^4*A53^-4)) -> 263086.86
A54: =A10 -> 0.1578615 | B54: =B10 -> 538229.53 | D54: =$B$4*(B54^2)*($D$48^2*(2*PI())^4*A54^-5/4/PI()/$D$5^4*EXP((-1/PI())*(2*PI()/$D$5)^4*A54^-4)) -> 0 | E54: =$B$4*(B54^2)*($D$48^2*(2*PI())^4*A54^-5/4/PI()/$E$5^4*EXP((-1/PI())*(2*PI()/$E$5)^4*A54^-4)) -> 0 | F54: =$B$4*(B54^2)*($D$48^2*(2*PI())^4*A54^-5/4/PI()/$F$5^4*EXP((-1/PI())*(2*PI()/$F$5)^4*A54^-4)) -> 0 | G54: =$B$4*(B54^2)*($D$48^2*(2*PI())^4*A54^-5/4/PI()/$G$5^4*EXP((-1/PI())*(2*PI()/$G$5)^4*A54^-4)) -> 5.6672622e-182 | H54: =$B$4*(B54^2)*($D$48^2*(2*PI())^4*A54^-5/4/PI()/$H$5^4*EXP((-1/PI())*(2*PI()/$H$5)^4*A54^-4)) -> 1.6251905e-97 | I54: =$B$4*(B54^2)*($D$48^2*(2*PI())^4*A54^-5/4/PI()/$I$5^4*EXP((-1/PI())*(2*PI()/$I$5)^4*A54^-4)) -> 1.5146348e-54 | J54: =$B$4*(B54^2)*($D$48^2*(2*PI())^4*A54^-5/4/PI()/$J$5^4*EXP((-1/PI())*(2*PI()/$J$5)^4*A54^-4)) -> 7.1527006e-31 | K54: =$B$4*(B54^2)*($D$48^2*(2*PI())^4*A54^-5/4/PI()/$K$5^4*EXP((-1/PI())*(2*PI()/$K$5)^4*A54^-4)) -> 5.404117e-17 | L54: =$B$4*(B54^2)*($D$48^2*(2*PI())^4*A54^-5/4/PI()/$L$5^4*EXP((-1/PI())*(2*PI()/$L$5)^4*A54^-4)) -> 1.9099224e-08 | M54: =$B$4*(B54^2)*($D$48^2*(2*PI())^4*A54^-5/4/PI()/$M$5^4*EXP((-1/PI())*(2*PI()/$M$5)^4*A54^-4)) -> 0.0057788622 | N54: =$B$4*(B54^2)*($D$48^2*(2*PI())^4*A54^-5/4/PI()/$N$5^4*EXP((-1/PI())*(2*PI()/$N$5)^4*A54^-4)) -> 24.745838 | O54: =$B$4*(B54^2)*($D$48^2*(2*PI())^4*A54^-5/4/PI()/$O$5^4*EXP((-1/PI())*(2*PI()/$O$5)^4*A54^-4)) -> 7348.0475 | P54: =$B$4*(B54^2)*($D$48^2*(2*PI())^4*A54^-5/4/PI()/$P$5^4*EXP((-1/PI())*(2*PI()/$P$5)^4*A54^-4)) -> 387241.45 | Q54: =$B$4*(B54^2)*($D$48^2*(2*PI())^4*A54^-5/4/PI()/$Q$5^4*EXP((-1/PI())*(2*PI()/$Q$5)^4*A54^-4)) -> 6446255.1 | R54: =$B$4*(B54^2)*($D$48^2*(2*PI())^4*A54^-5/4/PI()/$R$5^4*EXP((-1/PI())*(2*PI()/$R$5)^4*A54^-4)) -> 48832718 | S54: =$B$4*(B54^2)*($D$48^2*(2*PI())^4*A54^-5/4/PI()/$S$5^4*EXP((-1/PI())*(2*PI()/$S$5)^4*A54^-4)) -> 2.1352026e+08
A55: =A11 -> 0.18390711 | B55: =B11 -> 401196.85 | D55: =$B$4*(B55^2)*($D$48^2*(2*PI())^4*A55^-5/4/PI()/$D$5^4*EXP((-1/PI())*(2*PI()/$D$5)^4*A55^-4)) -> 0 | E55: =$B$4*(B55^2)*($D$48^2*(2*PI())^4*A55^-5/4/PI()/$E$5^4*EXP((-1/PI())*(2*PI()/$E$5)^4*A55^-4)) -> 0 | F55: =$B$4*(B55^2)*($D$48^2*(2*PI())^4*A55^-5/4/PI()/$F$5^4*EXP((-1/PI())*(2*PI()/$F$5)^4*A55^-4)) -> 9.5831409e-194 | G55: =$B$4*(B55^2)*($D$48^2*(2*PI())^4*A55^-5/4/PI()/$G$5^4*EXP((-1/PI())*(2*PI()/$G$5)^4*A55^-4)) -> 1.0194931e-93 | H55: =$B$4*(B55^2)*($D$48^2*(2*PI())^4*A55^-5/4/PI()/$H$5^4*EXP((-1/PI())*(2*PI()/$H$5)^4*A55^-4)) -> 5.5691459e-48 | I55: =$B$4*(B55^2)*($D$48^2*(2*PI())^4*A55^-5/4/PI()/$I$5^4*EXP((-1/PI())*(2*PI()/$I$5)^4*A55^-4)) -> 9.4189357e-25 | J55: =$B$4*(B55^2)*($D$48^2*(2*PI())^4*A55^-5/4/PI()/$J$5^4*EXP((-1/PI())*(2*PI()/$J$5)^4*A55^-4)) -> 5.4715985e-12 | K55: =$B$4*(B55^2)*($D$48^2*(2*PI())^4*A55^-5/4/PI()/$K$5^4*EXP((-1/PI())*(2*PI()/$K$5)^4*A55^-4)) -> 0.00015595061 | L55: =$B$4*(B55^2)*($D$48^2*(2*PI())^4*A55^-5/4/PI()/$L$5^4*EXP((-1/PI())*(2*PI()/$L$5)^4*A55^-4)) -> 5.7745531 | M55: =$B$4*(B55^2)*($D$48^2*(2*PI())^4*A55^-5/4/PI()/$M$5^4*EXP((-1/PI())*(2*PI()/$M$5)^4*A55^-4)) -> 4685.8155 | N55: =$B$4*(B55^2)*($D$48^2*(2*PI())^4*A55^-5/4/PI()/$N$5^4*EXP((-1/PI())*(2*PI()/$N$5)^4*A55^-4)) -> 381292.91 | O55: =$B$4*(B55^2)*($D$48^2*(2*PI())^4*A55^-5/4/PI()/$O$5^4*EXP((-1/PI())*(2*PI()/$O$5)^4*A55^-4)) -> 7360355.4 | P55: =$B$4*(B55^2)*($D$48^2*(2*PI())^4*A55^-5/4/PI()/$P$5^4*EXP((-1/PI())*(2*PI()/$P$5)^4*A55^-4)) -> 56064940 | Q55: =$B$4*(B55^2)*($D$48^2*(2*PI())^4*A55^-5/4/PI()/$Q$5^4*EXP((-1/PI())*(2*PI()/$Q$5)^4*A55^-4)) -> 2.3019127e+08 | R55: =$B$4*(B55^2)*($D$48^2*(2*PI())^4*A55^-5/4/PI()/$R$5^4*EXP((-1/PI())*(2*PI()/$R$5)^4*A55^-4)) -> 6.2055851e+08 | S55: =$B$4*(B55^2)*($D$48^2*(2*PI())^4*A55^-5/4/PI()/$S$5^4*EXP((-1/PI())*(2*PI()/$S$5)^4*A55^-4)) -> 1.2488196e+09
A56: =A12 -> 0.20951927 | B56: =B12 -> 115250.03 | D56: =$B$4*(B56^2)*($D$48^2*(2*PI())^4*A56^-5/4/PI()/$D$5^4*EXP((-1/PI())*(2*PI()/$D$5)^4*A56^-4)) -> 0 | E56: =$B$4*(B56^2)*($D$48^2*(2*PI())^4*A56^-5/4/PI()/$E$5^4*EXP((-1/PI())*(2*PI()/$E$5)^4*A56^-4)) -> 1.3873211e-261 | F56: =$B$4*(B56^2)*($D$48^2*(2*PI())^4*A56^-5/4/PI()/$F$5^4*EXP((-1/PI())*(2*PI()/$F$5)^4*A56^-4)) -> 1.8328037e-111 | G56: =$B$4*(B56^2)*($D$48^2*(2*PI())^4*A56^-5/4/PI()/$G$5^4*EXP((-1/PI())*(2*PI()/$G$5)^4*A56^-4)) -> 3.3244852e-52 | H56: =$B$4*(B56^2)*($D$48^2*(2*PI())^4*A56^-5/4/PI()/$H$5^4*EXP((-1/PI())*(2*PI()/$H$5)^4*A56^-4)) -> 3.7212751e-25 | I56: =$B$4*(B56^2)*($D$48^2*(2*PI())^4*A56^-5/4/PI()/$I$5^4*EXP((-1/PI())*(2*PI()/$I$5)^4*A56^-4)) -> 1.8652366e-11 | J56: =$B$4*(B56^2)*($D$48^2*(2*PI())^4*A56^-5/4/PI()/$J$5^4*EXP((-1/PI())*(2*PI()/$J$5)^4*A56^-4)) -> 0.00058757532 | K56: =$B$4*(B56^2)*($D$48^2*(2*PI())^4*A56^-5/4/PI()/$K$5^4*EXP((-1/PI())*(2*PI()/$K$5)^4*A56^-4)) -> 13.294235 | L56: =$B$4*(B56^2)*($D$48^2*(2*PI())^4*A56^-5/4/PI()/$L$5^4*EXP((-1/PI())*(2*PI()/$L$5)^4*A56^-4)) -> 5906.7198 | M56: =$B$4*(B56^2)*($D$48^2*(2*PI())^4*A56^-5/4/PI()/$M$5^4*EXP((-1/PI())*(2*PI()/$M$5)^4*A56^-4)) -> 275067.12 | N56: =$B$4*(B56^2)*($D$48^2*(2*PI())^4*A56^-5/4/PI()/$N$5^4*EXP((-1/PI())*(2*PI()/$N$5)^4*A56^-4)) -> 3305020.9 | O56: =$B$4*(B56^2)*($D$48^2*(2*PI())^4*A56^-5/4/PI()/$O$5^4*EXP((-1/PI())*(2*PI()/$O$5)^4*A56^-4)) -> 17056473 | P56: =$B$4*(B56^2)*($D$48^2*(2*PI())^4*A56^-5/4/PI()/$P$5^4*EXP((-1/PI())*(2*PI()/$P$5)^4*A56^-4)) -> 51079169 | Q56: =$B$4*(B56^2)*($D$48^2*(2*PI())^4*A56^-5/4/PI()/$Q$5^4*EXP((-1/PI())*(2*PI()/$Q$5)^4*A56^-4)) -> 1.0671418e+08 | R56: =$B$4*(B56^2)*($D$48^2*(2*PI())^4*A56^-5/4/PI()/$R$5^4*EXP((-1/PI())*(2*PI()/$R$5)^4*A56^-4)) -> 1.7472073e+08 | S56: =$B$4*(B56^2)*($D$48^2*(2*PI())^4*A56^-5/4/PI()/$S$5^4*EXP((-1/PI())*(2*PI()/$S$5)^4*A56^-4)) -> 2.4176949e+08
A57: =A13 -> 0.23469797 | B57: =B13 -> 156835.1 | D57: =$B$4*(B57^2)*($D$48^2*(2*PI())^4*A57^-5/4/PI()/$D$5^4*EXP((-1/PI())*(2*PI()/$D$5)^4*A57^-4)) -> 0 | E57: =$B$4*(B57^2)*($D$48^2*(2*PI())^4*A57^-5/4/PI()/$E$5^4*EXP((-1/PI())*(2*PI()/$E$5)^4*A57^-4)) -> 4.4396942e-162 | F57: =$B$4*(B57^2)*($D$48^2*(2*PI())^4*A57^-5/4/PI()/$F$5^4*EXP((-1/PI())*(2*PI()/$F$5)^4*A57^-4)) -> 7.337922e-67 | G57: =$B$4*(B57^2)*($D$48^2*(2*PI())^4*A57^-5/4/PI()/$G$5^4*EXP((-1/PI())*(2*PI()/$G$5)^4*A57^-4)) -> 2.4902987e-29 | H57: =$B$4*(B57^2)*($D$48^2*(2*PI())^4*A57^-5/4/PI()/$H$5^4*EXP((-1/PI())*(2*PI()/$H$5)^4*A57^-4)) -> 3.0548899e-12 | I57: =$B$4*(B57^2)*($D$48^2*(2*PI())^4*A57^-5/4/PI()/$I$5^4*EXP((-1/PI())*(2*PI()/$I$5)^4*A57^-4)) -> 0.0012790465 | J57: =$B$4*(B57^2)*($D$48^2*(2*PI())^4*A57^-5/4/PI()/$J$5^4*EXP((-1/PI())*(2*PI()/$J$5)^4*A57^-4)) -> 62.91509 | K57: =$B$4*(B57^2)*($D$48^2*(2*PI())^4*A57^-5/4/PI()/$K$5^4*EXP((-1/PI())*(2*PI()/$K$5)^4*A57^-4)) -> 31697.678 | L57: =$B$4*(B57^2)*($D$48^2*(2*PI())^4*A57^-5/4/PI()/$L$5^4*EXP((-1/PI())*(2*PI()/$L$5)^4*A57^-4)) -> 1333434.6 | M57: =$B$4*(B57^2)*($D$48^2*(2*PI())^4*A57^-5/4/PI()/$M$5^4*EXP((-1/PI())*(2*PI()/$M$5)^4*A57^-4)) -> 13538340 | N57: =$B$4*(B57^2)*($D$48^2*(2*PI())^4*A57^-5/4/PI()/$N$5^4*EXP((-1/PI())*(2*PI()/$N$5)^4*A57^-4)) -> 58687998 | O57: =$B$4*(B57^2)*($D$48^2*(2*PI())^4*A57^-5/4/PI()/$O$5^4*EXP((-1/PI())*(2*PI()/$O$5)^4*A57^-4)) -> 1.4993988e+08 | P57: =$B$4*(B57^2)*($D$48^2*(2*PI())^4*A57^-5/4/PI()/$P$5^4*EXP((-1/PI())*(2*PI()/$P$5)^4*A57^-4)) -> 2.7301642e+08 | Q57: =$B$4*(B57^2)*($D$48^2*(2*PI())^4*A57^-5/4/PI()/$Q$5^4*EXP((-1/PI())*(2*PI()/$Q$5)^4*A57^-4)) -> 3.9791095e+08 | R57: =$B$4*(B57^2)*($D$48^2*(2*PI())^4*A57^-5/4/PI()/$R$5^4*EXP((-1/PI())*(2*PI()/$R$5)^4*A57^-4)) -> 4.9944053e+08 | S57: =$B$4*(B57^2)*($D$48^2*(2*PI())^4*A57^-5/4/PI()/$S$5^4*EXP((-1/PI())*(2*PI()/$S$5)^4*A57^-4)) -> 5.6604285e+08
A58: =A14 -> 0.25944322 | B58: =B14 -> 184162.42 | D58: =$B$4*(B58^2)*($D$48^2*(2*PI())^4*A58^-5/4/PI()/$D$5^4*EXP((-1/PI())*(2*PI()/$D$5)^4*A58^-4)) -> 0 | E58: =$B$4*(B58^2)*($D$48^2*(2*PI())^4*A58^-5/4/PI()/$E$5^4*EXP((-1/PI())*(2*PI()/$E$5)^4*A58^-4)) -> 5.8845638e-105 | F58: =$B$4*(B58^2)*($D$48^2*(2*PI())^4*A58^-5/4/PI()/$F$5^4*EXP((-1/PI())*(2*PI()/$F$5)^4*A58^-4)) -> 2.6327513e-41 | G58: =$B$4*(B58^2)*($D$48^2*(2*PI())^4*A58^-5/4/PI()/$G$5^4*EXP((-1/PI())*(2*PI()/$G$5)^4*A58^-4)) -> 2.8716891e-16 | H58: =$B$4*(B58^2)*($D$48^2*(2*PI())^4*A58^-5/4/PI()/$H$5^4*EXP((-1/PI())*(2*PI()/$H$5)^4*A58^-4)) -> 6.6074265e-05 | I58: =$B$4*(B58^2)*($D$48^2*(2*PI())^4*A58^-5/4/PI()/$I$5^4*EXP((-1/PI())*(2*PI()/$I$5)^4*A58^-4)) -> 33.275795 | J58: =$B$4*(B58^2)*($D$48^2*(2*PI())^4*A58^-5/4/PI()/$J$5^4*EXP((-1/PI())*(2*PI()/$J$5)^4*A58^-4)) -> 39843.77 | K58: =$B$4*(B58^2)*($D$48^2*(2*PI())^4*A58^-5/4/PI()/$K$5^4*EXP((-1/PI())*(2*PI()/$K$5)^4*A58^-4)) -> 2252118.6 | L58: =$B$4*(B58^2)*($D$48^2*(2*PI())^4*A58^-5/4/PI()/$L$5^4*EXP((-1/PI())*(2*PI()/$L$5)^4*A58^-4)) -> 24429490 | M58: =$B$4*(B58^2)*($D$48^2*(2*PI())^4*A58^-5/4/PI()/$M$5^4*EXP((-1/PI())*(2*PI()/$M$5)^4*A58^-4)) -> 1.0331538e+08 | N58: =$B$4*(B58^2)*($D$48^2*(2*PI())^4*A58^-5/4/PI()/$N$5^4*EXP((-1/PI())*(2*PI()/$N$5)^4*A58^-4)) -> 2.492178e+08 | O58: =$B$4*(B58^2)*($D$48^2*(2*PI())^4*A58^-5/4/PI()/$O$5^4*EXP((-1/PI())*(2*PI()/$O$5)^4*A58^-4)) -> 4.2499208e+08 | P58: =$B$4*(B58^2)*($D$48^2*(2*PI())^4*A58^-5/4/PI()/$P$5^4*EXP((-1/PI())*(2*PI()/$P$5)^4*A58^-4)) -> 5.8131404e+08 | Q58: =$B$4*(B58^2)*($D$48^2*(2*PI())^4*A58^-5/4/PI()/$Q$5^4*EXP((-1/PI())*(2*PI()/$Q$5)^4*A58^-4)) -> 6.8879996e+08 | R58: =$B$4*(B58^2)*($D$48^2*(2*PI())^4*A58^-5/4/PI()/$R$5^4*EXP((-1/PI())*(2*PI()/$R$5)^4*A58^-4)) -> 7.4203642e+08 | S58: =$B$4*(B58^2)*($D$48^2*(2*PI())^4*A58^-5/4/PI()/$S$5^4*EXP((-1/PI())*(2*PI()/$S$5)^4*A58^-4)) -> 7.498002e+08
